2020-12-25 16:15:26,861:INFO:C:\Users\TARUNVYDA\CloneProjects\FundooNotes\fundoo\notes\utils.py changed, reloading.
2020-12-25 16:15:26,861:DEBUG:Using selector: SelectSelector
2020-12-25 16:16:32,096:INFO:C:\Users\TARUNVYDA\CloneProjects\FundooNotes\fundoo\notes\utils.py changed, reloading.
2020-12-25 16:16:32,096:DEBUG:Using selector: SelectSelector
2020-12-25 16:17:35,420:INFO:C:\Users\TARUNVYDA\CloneProjects\FundooNotes\fundoo\labels\views.py changed, reloading.
2020-12-25 16:17:35,420:DEBUG:Using selector: SelectSelector
2020-12-25 16:18:18,064:INFO:C:\Users\TARUNVYDA\CloneProjects\FundooNotes\fundoo\labels\views.py changed, reloading.
2020-12-25 16:18:18,064:DEBUG:Using selector: SelectSelector
2020-12-25 16:18:36,297:DEBUG:{'token': 'eyJ0eXAiOiJKV1QiLCJhbGciOiJIUzI1NiJ9.eyJpZCI6M30.O09y2tVCvQ7wE-CkRe3uFQJchj3KQj1F8alZ1ChGcGg'}
2020-12-25 16:18:38,636:DEBUG:{'status': True, 'message': {'user': 1, 'label_name': 'new labels'}}
2020-12-25 16:20:08,345:INFO:C:\Users\TARUNVYDA\CloneProjects\FundooNotes\fundoo\notes\utils.py changed, reloading.
2020-12-25 16:20:08,345:DEBUG:Using selector: SelectSelector
2020-12-25 16:20:34,190:DEBUG:{'token': 'eyJ0eXAiOiJKV1QiLCJhbGciOiJIUzI1NiJ9.eyJpZCI6M30.O09y2tVCvQ7wE-CkRe3uFQJchj3KQj1F8alZ1ChGcGg'}
2020-12-25 16:20:37,260:DEBUG:{'status': True, 'message': {'user': 1, 'label_name': 'new labels'}}200
2020-12-25 16:21:28,292:INFO:C:\Users\TARUNVYDA\CloneProjects\FundooNotes\fundoo\notes\utils.py changed, reloading.
2020-12-25 16:21:28,292:DEBUG:Using selector: SelectSelector
2020-12-25 16:21:40,353:DEBUG:{'token': 'eyJ0eXAiOiJKV1QiLCJhbGciOiJIUzI1NiJ9.eyJpZCI6M30.O09y2tVCvQ7wE-CkRe3uFQJchj3KQj1F8alZ1ChGcGg'}
2020-12-25 16:21:42,513:DEBUG:{'status': True, 'message': {'user': 1, 'label_name': 'new labels'}}, status_code = 200
2020-12-25 16:23:17,721:INFO:C:\Users\TARUNVYDA\CloneProjects\FundooNotes\fundoo\labels\views.py changed, reloading.
2020-12-25 16:23:17,721:DEBUG:Using selector: SelectSelector
2020-12-25 16:23:26,575:DEBUG:{'token': 'eyJ0eXAiOiJKV1QiLCJhbGciOiJIUzI1NiJ9.eyJpZCI6M30.O09y2tVCvQ7wE-CkRe3uFQJchj3KQj1F8alZ1ChGcGg'}
2020-12-25 16:23:29,120:DEBUG:{'status': True, 'message': {'user': 1, 'label_name': 'new labels'}}, status_code = 200
2020-12-25 16:23:29,120:DEBUG:{'status': False, 'message': 'some other issue please try after some time'}, status_code = 400
2020-12-25 16:23:32,992:DEBUG:{'status': True, 'message': {'user': 1, 'label_name': 'new labels'}}, status_code = 200
2020-12-25 16:23:32,992:DEBUG:{'status': False, 'message': 'some other issue please try after some time'}, status_code = 400
2020-12-25 16:23:36,015:DEBUG:{'token': 'eyJ0eXAiOiJKV1QiLCJhbGciOiJIUzI1NiJ9.eyJpZCI6M30.O09y2tVCvQ7wE-CkRe3uFQJchj3KQj1F8alZ1ChGcGg'}
2020-12-25 16:23:38,109:DEBUG:{'status': True, 'message': {'user': 1, 'label_name': 'new labels'}}, status_code = 200
2020-12-25 16:23:38,109:DEBUG:{'status': False, 'message': 'some other issue please try after some time'}, status_code = 400
2020-12-25 16:24:23,490:DEBUG:{'token': 'eyJ0eXAiOiJKV1QiLCJhbGciOiJIUzI1NiJ9.eyJpZCI6M30.O09y2tVCvQ7wE-CkRe3uFQJchj3KQj1F8alZ1ChGcGg'}
2020-12-25 16:24:27,534:DEBUG:{'status': True, 'message': {'user': 1, 'label_name': 'new labels'}}, status_code = 200
2020-12-25 16:24:27,534:DEBUG:{'status': False, 'message': 'some other issue please try after some time'}, status_code = 400
2020-12-25 16:24:31,962:DEBUG:{'status': True, 'message': {'user': 1, 'label_name': 'new labels'}}, status_code = 200
2020-12-25 16:24:31,962:DEBUG:{'status': False, 'message': 'some other issue please try after some time'}, status_code = 400
2020-12-25 16:24:54,884:INFO:C:\Users\TARUNVYDA\CloneProjects\FundooNotes\fundoo\notes\utils.py changed, reloading.
2020-12-25 16:24:54,885:DEBUG:Using selector: SelectSelector
2020-12-25 16:25:01,857:DEBUG:{'token': 'eyJ0eXAiOiJKV1QiLCJhbGciOiJIUzI1NiJ9.eyJpZCI6M30.O09y2tVCvQ7wE-CkRe3uFQJchj3KQj1F8alZ1ChGcGg'}
2020-12-25 16:25:04,709:DEBUG:{'status': True, 'message': {'user': 1, 'label_name': 'new labels'}}, status_code = 200
2020-12-25 16:25:19,764:DEBUG:Using selector: SelectSelector
2020-12-25 16:34:27,528:DEBUG:{'token': 'eyJ0eXAiOiJKV1QiLCJhbGciOiJIUzI1NiJ9.eyJpZCI6M30.O09y2tVCvQ7wE-CkRe3uFQJchj3KQj1F8alZ1ChGcGg'}
2020-12-25 16:34:51,530:DEBUG:{'status': True, 'message': {'id': 1, 'title': 'my put note11', 'description': 'this is my testing note for put', 'created_time': '2020-12-21T07:12:08.603603Z', 'updated_time': '2020-12-22T05:45:47.772013Z', 'is_archived': False, 'is_deleted': False, 'color': '#00F0FF', 'image': None, 'trash': False, 'is_pinned': False, 'user': 1, 'label': [1], 'collaborate': [3]}}, status_code = 200
2020-12-25 16:35:07,870:DEBUG:Using selector: SelectSelector
2020-12-26 10:11:13,292:DEBUG:{'token': 'eyJ0eXAiOiJKV1QiLCJhbGciOiJIUzI1NiJ9.eyJpZCI6M30.O09y2tVCvQ7wE-CkRe3uFQJchj3KQj1F8alZ1ChGcGg'}
2020-12-26 10:11:16,746:DEBUG:{'status': True, 'message': {'id': 1, 'title': 'my put note11', 'description': 'this is my testing note for put', 'created_time': '2020-12-21T07:12:08.603603Z', 'updated_time': '2020-12-22T05:45:47.772013Z', 'is_archived': False, 'is_deleted': False, 'color': '#00F0FF', 'image': None, 'trash': False, 'is_pinned': False, 'user': 1, 'label': [1], 'collaborate': [3]}}, status_code = 200
2020-12-26 10:11:23,343:DEBUG:Using selector: SelectSelector
2020-12-26 10:13:05,400:DEBUG:{'token': 'eyJ0eXAiOiJKV1QiLCJhbGciOiJIUzI1NiJ9.eyJpZCI6M30.O09y2tVCvQ7wE-CkRe3uFQJchj3KQj1F8alZ1ChGcGg'}
2020-12-26 10:13:08,028:DEBUG:{'status': True, 'message': {'id': 1, 'title': 'my put note11', 'description': 'this is my testing note for put', 'created_time': '2020-12-21T07:12:08.603603Z', 'updated_time': '2020-12-22T05:45:47.772013Z', 'is_archived': False, 'is_deleted': False, 'color': '#00F0FF', 'image': None, 'trash': False, 'is_pinned': False, 'user': 1, 'label': [1], 'collaborate': [3]}}, status_code = 200
2020-12-26 10:13:13,253:DEBUG:Using selector: SelectSelector
2020-12-26 10:13:41,004:DEBUG:{'token': 'eyJ0eXAiOiJKV1QiLCJhbGciOiJIUzI1NiJ9.eyJpZCI6M30.O09y2tVCvQ7wE-CkRe3uFQJchj3KQj1F8alZ1ChGcGg'}
2020-12-26 10:20:11,295:INFO:C:\Users\TARUNVYDA\CloneProjects\FundooNotes\fundoo\fundooapp\decorator.py changed, reloading.
2020-12-26 10:20:11,295:DEBUG:Using selector: SelectSelector
2020-12-26 10:21:04,424:INFO:C:\Users\TARUNVYDA\CloneProjects\FundooNotes\fundoo\fundooapp\decorator.py changed, reloading.
2020-12-26 10:21:04,424:DEBUG:Using selector: SelectSelector
2020-12-26 10:21:21,596:INFO:C:\Users\TARUNVYDA\CloneProjects\FundooNotes\fundoo\fundooapp\decorator.py changed, reloading.
2020-12-26 10:21:21,596:DEBUG:Using selector: SelectSelector
2020-12-26 10:21:27,026:ERROR:Internal Server Error: /note/1
Traceback (most recent call last):
  File "C:\Users\TARUNVYDA\PycharmProjects\FundooNotes\venv\lib\site-packages\django\core\handlers\exception.py", line 47, in inner
    response = get_response(request)
  File "C:\Users\TARUNVYDA\PycharmProjects\FundooNotes\venv\lib\site-packages\django\core\handlers\base.py", line 179, in _get_response
    response = wrapped_callback(request, *callback_args, **callback_kwargs)
  File "C:\Users\TARUNVYDA\PycharmProjects\FundooNotes\venv\lib\site-packages\django\views\decorators\csrf.py", line 54, in wrapped_view
    return view_func(*args, **kwargs)
  File "C:\Users\TARUNVYDA\PycharmProjects\FundooNotes\venv\lib\site-packages\django\views\generic\base.py", line 70, in view
    return self.dispatch(request, *args, **kwargs)
  File "C:\Users\TARUNVYDA\PycharmProjects\FundooNotes\venv\lib\site-packages\django\utils\decorators.py", line 43, in _wrapper
    return bound_method(*args, **kwargs)
  File "C:\Users\TARUNVYDA\CloneProjects\FundooNotes\fundoo\fundooapp\decorator.py", line 13, in wrapper
    actual_token = Redis.get_token('token').decode()
AttributeError: 'NoneType' object has no attribute 'decode'
2020-12-26 10:21:29,978:ERROR:Internal Server Error: /note/1
Traceback (most recent call last):
  File "C:\Users\TARUNVYDA\PycharmProjects\FundooNotes\venv\lib\site-packages\django\core\handlers\exception.py", line 47, in inner
    response = get_response(request)
  File "C:\Users\TARUNVYDA\PycharmProjects\FundooNotes\venv\lib\site-packages\django\core\handlers\base.py", line 179, in _get_response
    response = wrapped_callback(request, *callback_args, **callback_kwargs)
  File "C:\Users\TARUNVYDA\PycharmProjects\FundooNotes\venv\lib\site-packages\django\views\decorators\csrf.py", line 54, in wrapped_view
    return view_func(*args, **kwargs)
  File "C:\Users\TARUNVYDA\PycharmProjects\FundooNotes\venv\lib\site-packages\django\views\generic\base.py", line 70, in view
    return self.dispatch(request, *args, **kwargs)
  File "C:\Users\TARUNVYDA\PycharmProjects\FundooNotes\venv\lib\site-packages\django\utils\decorators.py", line 43, in _wrapper
    return bound_method(*args, **kwargs)
  File "C:\Users\TARUNVYDA\CloneProjects\FundooNotes\fundoo\fundooapp\decorator.py", line 13, in wrapper
    actual_token = Redis.get_token('token').decode()
AttributeError: 'NoneType' object has no attribute 'decode'
2020-12-26 10:21:42,922:INFO:C:\Users\TARUNVYDA\CloneProjects\FundooNotes\fundoo\fundooapp\decorator.py changed, reloading.
2020-12-26 10:21:42,922:DEBUG:Using selector: SelectSelector
2020-12-26 10:24:00,186:DEBUG:{'token': 'eyJ0eXAiOiJKV1QiLCJhbGciOiJIUzI1NiJ9.eyJpZCI6M30.O09y2tVCvQ7wE-CkRe3uFQJchj3KQj1F8alZ1ChGcGg'}
2020-12-26 10:24:35,602:INFO:C:\Users\TARUNVYDA\CloneProjects\FundooNotes\fundoo\fundooapp\decorator.py changed, reloading.
2020-12-26 10:24:35,602:DEBUG:Using selector: SelectSelector
2020-12-26 10:24:57,070:DEBUG:{'status': True, 'message': {'id': 1, 'title': 'my put note11', 'description': 'this is my testing note for put', 'created_time': '2020-12-21T07:12:08.603603Z', 'updated_time': '2020-12-22T05:45:47.772013Z', 'is_archived': False, 'is_deleted': False, 'color': '#00F0FF', 'image': None, 'trash': False, 'is_pinned': False, 'user': 1, 'label': [1], 'collaborate': [3]}}, status_code = 200
2020-12-26 10:25:29,155:DEBUG:Using selector: SelectSelector
2020-12-26 10:52:47,193:DEBUG:{'token': 'eyJ0eXAiOiJKV1QiLCJhbGciOiJIUzI1NiJ9.eyJpZCI6M30.O09y2tVCvQ7wE-CkRe3uFQJchj3KQj1F8alZ1ChGcGg'}
2020-12-26 10:53:15,488:DEBUG:{'status': True, 'message': 'Note Added Successfully'}, status_code = 201
2020-12-26 10:53:26,909:DEBUG:Using selector: SelectSelector
2020-12-26 10:54:32,314:DEBUG:Using selector: SelectSelector
2020-12-26 12:31:13,456:DEBUG:Using selector: SelectSelector
2020-12-26 19:46:17,542:WARNING:Not Found: /favicon.ico
2020-12-26 19:46:52,437:DEBUG:Using selector: SelectSelector
2020-12-26 19:57:22,031:INFO:C:\Users\TARUNVYDA\CloneProjects\FundooNotes\fundoo\fundooapp\decorator.py changed, reloading.
2020-12-26 19:57:22,056:DEBUG:Using selector: SelectSelector
2020-12-26 19:57:36,590:DEBUG:{'token': 'eyJ0eXAiOiJKV1QiLCJhbGciOiJIUzI1NiJ9.eyJpZCI6M30.O09y2tVCvQ7wE-CkRe3uFQJchj3KQj1F8alZ1ChGcGg'}
2020-12-26 19:57:40,234:DEBUG:{'status': True, 'message': {'id': 1, 'title': 'my put note11', 'description': 'this is my testing note for put', 'created_time': '2020-12-21T07:12:08.603603Z', 'updated_time': '2020-12-22T05:45:47.772013Z', 'is_archived': False, 'is_deleted': False, 'color': '#00F0FF', 'image': None, 'trash': False, 'is_pinned': False, 'user': 1, 'label': [1], 'collaborate': [3]}}, status_code = 200
2020-12-26 19:58:31,872:INFO:C:\Users\TARUNVYDA\CloneProjects\FundooNotes\fundoo\notes\utils.py changed, reloading.
2020-12-26 19:58:31,872:DEBUG:Using selector: SelectSelector
2020-12-26 19:58:41,910:DEBUG:{'token': 'eyJ0eXAiOiJKV1QiLCJhbGciOiJIUzI1NiJ9.eyJpZCI6M30.O09y2tVCvQ7wE-CkRe3uFQJchj3KQj1F8alZ1ChGcGg'}
2020-12-26 19:58:44,038:DEBUG:{'status': True, 'message': {'id': 1, 'title': 'my put note11', 'description': 'this is my testing note for put', 'created_time': '2020-12-21T07:12:08.603603Z', 'updated_time': '2020-12-22T05:45:47.772013Z', 'is_archived': False, 'is_deleted': False, 'color': '#00F0FF', 'image': None, 'trash': False, 'is_pinned': False, 'user': 1, 'label': [1], 'collaborate': [3]}}, status_code = 200
2020-12-26 19:58:58,181:DEBUG:Using selector: SelectSelector
2020-12-26 20:00:42,493:DEBUG:{'token': 'eyJ0eXAiOiJKV1QiLCJhbGciOiJIUzI1NiJ9.eyJpZCI6M30.O09y2tVCvQ7wE-CkRe3uFQJchj3KQj1F8alZ1ChGcGg'}
2020-12-26 20:00:56,496:DEBUG:Using selector: SelectSelector
2020-12-26 20:02:01,647:DEBUG:{'token': 'eyJ0eXAiOiJKV1QiLCJhbGciOiJIUzI1NiJ9.eyJpZCI6M30.O09y2tVCvQ7wE-CkRe3uFQJchj3KQj1F8alZ1ChGcGg'}
2020-12-26 20:03:17,633:DEBUG:{'token': 'eyJ0eXAiOiJKV1QiLCJhbGciOiJIUzI1NiJ9.eyJpZCI6M30.O09y2tVCvQ7wE-CkRe3uFQJchj3KQj1F8alZ1ChGcGg'}
2020-12-26 20:43:29,899:ERROR:Internal Server Error: /login/
Traceback (most recent call last):
  File "C:\Users\TARUNVYDA\PycharmProjects\FundooNotes\venv\lib\site-packages\django\core\handlers\exception.py", line 47, in inner
    response = get_response(request)
  File "C:\Users\TARUNVYDA\PycharmProjects\FundooNotes\venv\lib\site-packages\django\core\handlers\base.py", line 179, in _get_response
    response = wrapped_callback(request, *callback_args, **callback_kwargs)
  File "C:\Users\TARUNVYDA\PycharmProjects\FundooNotes\venv\lib\site-packages\django\views\decorators\csrf.py", line 54, in wrapped_view
    return view_func(*args, **kwargs)
  File "C:\Users\TARUNVYDA\PycharmProjects\FundooNotes\venv\lib\site-packages\django\views\generic\base.py", line 70, in view
    return self.dispatch(request, *args, **kwargs)
  File "C:\Users\TARUNVYDA\PycharmProjects\FundooNotes\venv\lib\site-packages\rest_framework\views.py", line 509, in dispatch
    response = self.handle_exception(exc)
  File "C:\Users\TARUNVYDA\PycharmProjects\FundooNotes\venv\lib\site-packages\rest_framework\views.py", line 469, in handle_exception
    self.raise_uncaught_exception(exc)
  File "C:\Users\TARUNVYDA\PycharmProjects\FundooNotes\venv\lib\site-packages\rest_framework\views.py", line 480, in raise_uncaught_exception
    raise exc
  File "C:\Users\TARUNVYDA\PycharmProjects\FundooNotes\venv\lib\site-packages\rest_framework\views.py", line 506, in dispatch
    response = handler(request, *args, **kwargs)
  File "C:\Users\TARUNVYDA\CloneProjects\FundooNotes\fundoo\fundooapp\views.py", line 41, in post
    Redis.set_token('USER_'+user.id+'_AUTHTOKEN', token)
TypeError: can only concatenate str (not "int") to str
2020-12-26 20:43:33,998:ERROR:Internal Server Error: /login/
Traceback (most recent call last):
  File "C:\Users\TARUNVYDA\PycharmProjects\FundooNotes\venv\lib\site-packages\django\core\handlers\exception.py", line 47, in inner
    response = get_response(request)
  File "C:\Users\TARUNVYDA\PycharmProjects\FundooNotes\venv\lib\site-packages\django\core\handlers\base.py", line 179, in _get_response
    response = wrapped_callback(request, *callback_args, **callback_kwargs)
  File "C:\Users\TARUNVYDA\PycharmProjects\FundooNotes\venv\lib\site-packages\django\views\decorators\csrf.py", line 54, in wrapped_view
    return view_func(*args, **kwargs)
  File "C:\Users\TARUNVYDA\PycharmProjects\FundooNotes\venv\lib\site-packages\django\views\generic\base.py", line 70, in view
    return self.dispatch(request, *args, **kwargs)
  File "C:\Users\TARUNVYDA\PycharmProjects\FundooNotes\venv\lib\site-packages\rest_framework\views.py", line 509, in dispatch
    response = self.handle_exception(exc)
  File "C:\Users\TARUNVYDA\PycharmProjects\FundooNotes\venv\lib\site-packages\rest_framework\views.py", line 469, in handle_exception
    self.raise_uncaught_exception(exc)
  File "C:\Users\TARUNVYDA\PycharmProjects\FundooNotes\venv\lib\site-packages\rest_framework\views.py", line 480, in raise_uncaught_exception
    raise exc
  File "C:\Users\TARUNVYDA\PycharmProjects\FundooNotes\venv\lib\site-packages\rest_framework\views.py", line 506, in dispatch
    response = handler(request, *args, **kwargs)
  File "C:\Users\TARUNVYDA\CloneProjects\FundooNotes\fundoo\fundooapp\views.py", line 41, in post
    Redis.set_token('USER_'+user.id+'_AUTHTOKEN', token)
TypeError: can only concatenate str (not "int") to str
2020-12-26 21:00:22,340:DEBUG:Using selector: SelectSelector
2020-12-26 21:18:27,692:DEBUG:{'token': 'eyJ0eXAiOiJKV1QiLCJhbGciOiJIUzI1NiJ9.eyJpZCI6M30.O09y2tVCvQ7wE-CkRe3uFQJchj3KQj1F8alZ1ChGcGg'}
2020-12-26 21:18:59,197:INFO:C:\Users\TARUNVYDA\CloneProjects\FundooNotes\fundoo\fundooapp\decorator.py changed, reloading.
2020-12-26 21:18:59,197:DEBUG:Using selector: SelectSelector
2020-12-26 21:19:04,619:DEBUG:{'status': True, 'message': {'id': 1, 'title': 'my put note11', 'description': 'this is my testing note for put', 'created_time': '2020-12-21T07:12:08.603603Z', 'updated_time': '2020-12-22T05:45:47.772013Z', 'is_archived': False, 'is_deleted': False, 'color': '#00F0FF', 'image': None, 'trash': False, 'is_pinned': False, 'user': 1, 'label': [1], 'collaborate': [3]}}, status_code = 200
2020-12-26 21:19:12,812:DEBUG:Using selector: SelectSelector
2020-12-26 23:19:36,776:DEBUG:{'token': 'eyJ0eXAiOiJKV1QiLCJhbGciOiJIUzI1NiJ9.eyJpZCI6M30.O09y2tVCvQ7wE-CkRe3uFQJchj3KQj1F8alZ1ChGcGg'}
2020-12-26 23:19:38,938:DEBUG:{'status': True, 'message': {'id': 1, 'title': 'my put note11', 'description': 'this is my testing note for put', 'created_time': '2020-12-21T07:12:08.603603Z', 'updated_time': '2020-12-22T05:45:47.772013Z', 'is_archived': False, 'is_deleted': False, 'color': '#00F0FF', 'image': None, 'trash': False, 'is_pinned': False, 'user': 1, 'label': [1], 'collaborate': [3]}}, status_code = 200
2020-12-26 23:19:43,367:DEBUG:Using selector: SelectSelector
2020-12-26 23:22:16,085:DEBUG:{'token': 'eyJ0eXAiOiJKV1QiLCJhbGciOiJIUzI1NiJ9.eyJpZCI6M30.O09y2tVCvQ7wE-CkRe3uFQJchj3KQj1F8alZ1ChGcGg'}
2020-12-26 23:22:18,960:DEBUG:{'status': True, 'message': {'id': 1, 'title': 'my put note11', 'description': 'this is my testing note for put', 'created_time': '2020-12-21T07:12:08.603603Z', 'updated_time': '2020-12-22T05:45:47.772013Z', 'is_archived': False, 'is_deleted': False, 'color': '#00F0FF', 'image': None, 'trash': False, 'is_pinned': False, 'user': 1, 'label': [1], 'collaborate': [3]}}, status_code = 200
2020-12-26 23:22:24,241:DEBUG:Using selector: SelectSelector
2020-12-26 23:25:05,196:DEBUG:{'token': 'eyJ0eXAiOiJKV1QiLCJhbGciOiJIUzI1NiJ9.eyJpZCI6M30.O09y2tVCvQ7wE-CkRe3uFQJchj3KQj1F8alZ1ChGcGg'}
2020-12-26 23:25:07,940:DEBUG:{'status': True, 'message': {'id': 1, 'title': 'my put note11', 'description': 'this is my testing note for put', 'created_time': '2020-12-21T07:12:08.603603Z', 'updated_time': '2020-12-22T05:45:47.772013Z', 'is_archived': False, 'is_deleted': False, 'color': '#00F0FF', 'image': None, 'trash': False, 'is_pinned': False, 'user': 1, 'label': [1], 'collaborate': [3]}}, status_code = 200
2020-12-26 23:25:13,215:DEBUG:Using selector: SelectSelector
2020-12-26 23:27:16,574:DEBUG:{'token': 'eyJ0eXAiOiJKV1QiLCJhbGciOiJIUzI1NiJ9.eyJpZCI6MX0.-xXA0iKB4mVNvWLYFtt2xNiYkFpObF54J9lj2RwduAI'}
2020-12-26 23:27:21,692:DEBUG:{'token': 'eyJ0eXAiOiJKV1QiLCJhbGciOiJIUzI1NiJ9.eyJpZCI6M30.O09y2tVCvQ7wE-CkRe3uFQJchj3KQj1F8alZ1ChGcGg'}
2020-12-26 23:27:38,376:DEBUG:{'status': True, 'message': {'id': 1, 'title': 'my put note11', 'description': 'this is my testing note for put', 'created_time': '2020-12-21T07:12:08.603603Z', 'updated_time': '2020-12-22T05:45:47.772013Z', 'is_archived': False, 'is_deleted': False, 'color': '#00F0FF', 'image': None, 'trash': False, 'is_pinned': False, 'user': 1, 'label': [1], 'collaborate': [3]}}, status_code = 200
2020-12-26 23:27:56,861:DEBUG:{'status': True, 'message': {'id': 1, 'title': 'my put note11', 'description': 'this is my testing note for put', 'created_time': '2020-12-21T07:12:08.603603Z', 'updated_time': '2020-12-22T05:45:47.772013Z', 'is_archived': False, 'is_deleted': False, 'color': '#00F0FF', 'image': None, 'trash': False, 'is_pinned': False, 'user': 1, 'label': [1], 'collaborate': [3]}}, status_code = 200
2020-12-26 23:28:16,667:DEBUG:{'status': True, 'message': {'id': 1, 'title': 'my put note11', 'description': 'this is my testing note for put', 'created_time': '2020-12-21T07:12:08.603603Z', 'updated_time': '2020-12-22T05:45:47.772013Z', 'is_archived': False, 'is_deleted': False, 'color': '#00F0FF', 'image': None, 'trash': False, 'is_pinned': False, 'user': 1, 'label': [1], 'collaborate': [3]}}, status_code = 200
2020-12-26 23:28:44,805:DEBUG:Using selector: SelectSelector
2020-12-26 23:30:49,138:DEBUG:{'token': 'eyJ0eXAiOiJKV1QiLCJhbGciOiJIUzI1NiJ9.eyJpZCI6MX0.-xXA0iKB4mVNvWLYFtt2xNiYkFpObF54J9lj2RwduAI'}
2020-12-26 23:30:58,171:DEBUG:{'status': True, 'message': {'id': 1, 'title': 'my put note11', 'description': 'this is my testing note for put', 'created_time': '2020-12-21T07:12:08.603603Z', 'updated_time': '2020-12-22T05:45:47.772013Z', 'is_archived': False, 'is_deleted': False, 'color': '#00F0FF', 'image': None, 'trash': False, 'is_pinned': False, 'user': 1, 'label': [1], 'collaborate': [3]}}, status_code = 200
2020-12-26 23:31:01,176:DEBUG:Using selector: SelectSelector
2020-12-26 23:36:57,586:ERROR:Internal Server Error: /login/
Traceback (most recent call last):
  File "C:\Users\TARUNVYDA\PycharmProjects\FundooNotes\venv\lib\site-packages\django\core\handlers\exception.py", line 47, in inner
    response = get_response(request)
  File "C:\Users\TARUNVYDA\PycharmProjects\FundooNotes\venv\lib\site-packages\django\core\handlers\base.py", line 179, in _get_response
    response = wrapped_callback(request, *callback_args, **callback_kwargs)
  File "C:\Users\TARUNVYDA\PycharmProjects\FundooNotes\venv\lib\site-packages\django\views\decorators\csrf.py", line 54, in wrapped_view
    return view_func(*args, **kwargs)
  File "C:\Users\TARUNVYDA\PycharmProjects\FundooNotes\venv\lib\site-packages\django\views\generic\base.py", line 70, in view
    return self.dispatch(request, *args, **kwargs)
  File "C:\Users\TARUNVYDA\PycharmProjects\FundooNotes\venv\lib\site-packages\rest_framework\views.py", line 509, in dispatch
    response = self.handle_exception(exc)
  File "C:\Users\TARUNVYDA\PycharmProjects\FundooNotes\venv\lib\site-packages\rest_framework\views.py", line 469, in handle_exception
    self.raise_uncaught_exception(exc)
  File "C:\Users\TARUNVYDA\PycharmProjects\FundooNotes\venv\lib\site-packages\rest_framework\views.py", line 480, in raise_uncaught_exception
    raise exc
  File "C:\Users\TARUNVYDA\PycharmProjects\FundooNotes\venv\lib\site-packages\rest_framework\views.py", line 506, in dispatch
    response = handler(request, *args, **kwargs)
  File "C:\Users\TARUNVYDA\CloneProjects\FundooNotes\fundoo\fundooapp\views.py", line 41, in post
    Cache.set_cache(user.id, token)
TypeError: set_cache() missing 1 required positional argument: 'value'
2020-12-26 23:37:13,374:INFO:C:\Users\TARUNVYDA\CloneProjects\FundooNotes\fundoo\fundooapp\views.py changed, reloading.
2020-12-26 23:37:13,374:DEBUG:Using selector: SelectSelector
2020-12-26 23:37:19,072:ERROR:Internal Server Error: /login/
Traceback (most recent call last):
  File "C:\Users\TARUNVYDA\PycharmProjects\FundooNotes\venv\lib\site-packages\django\core\handlers\exception.py", line 47, in inner
    response = get_response(request)
  File "C:\Users\TARUNVYDA\PycharmProjects\FundooNotes\venv\lib\site-packages\django\core\handlers\base.py", line 179, in _get_response
    response = wrapped_callback(request, *callback_args, **callback_kwargs)
  File "C:\Users\TARUNVYDA\PycharmProjects\FundooNotes\venv\lib\site-packages\django\views\decorators\csrf.py", line 54, in wrapped_view
    return view_func(*args, **kwargs)
  File "C:\Users\TARUNVYDA\PycharmProjects\FundooNotes\venv\lib\site-packages\django\views\generic\base.py", line 70, in view
    return self.dispatch(request, *args, **kwargs)
  File "C:\Users\TARUNVYDA\PycharmProjects\FundooNotes\venv\lib\site-packages\rest_framework\views.py", line 509, in dispatch
    response = self.handle_exception(exc)
  File "C:\Users\TARUNVYDA\PycharmProjects\FundooNotes\venv\lib\site-packages\rest_framework\views.py", line 469, in handle_exception
    self.raise_uncaught_exception(exc)
  File "C:\Users\TARUNVYDA\PycharmProjects\FundooNotes\venv\lib\site-packages\rest_framework\views.py", line 480, in raise_uncaught_exception
    raise exc
  File "C:\Users\TARUNVYDA\PycharmProjects\FundooNotes\venv\lib\site-packages\rest_framework\views.py", line 506, in dispatch
    response = handler(request, *args, **kwargs)
  File "C:\Users\TARUNVYDA\CloneProjects\FundooNotes\fundoo\fundooapp\views.py", line 41, in post
    Cache.set_cache(self, user.id, token)
  File "C:\Users\TARUNVYDA\CloneProjects\FundooNotes\fundoo\services\cache.py", line 10, in set_cache
    self.r.set(key, value)
AttributeError: 'LoginAPIView' object has no attribute 'r'
2020-12-26 23:38:54,086:ERROR:Internal Server Error: /login/
Traceback (most recent call last):
  File "C:\Users\TARUNVYDA\PycharmProjects\FundooNotes\venv\lib\site-packages\django\core\handlers\exception.py", line 47, in inner
    response = get_response(request)
  File "C:\Users\TARUNVYDA\PycharmProjects\FundooNotes\venv\lib\site-packages\django\core\handlers\base.py", line 179, in _get_response
    response = wrapped_callback(request, *callback_args, **callback_kwargs)
  File "C:\Users\TARUNVYDA\PycharmProjects\FundooNotes\venv\lib\site-packages\django\views\decorators\csrf.py", line 54, in wrapped_view
    return view_func(*args, **kwargs)
  File "C:\Users\TARUNVYDA\PycharmProjects\FundooNotes\venv\lib\site-packages\django\views\generic\base.py", line 70, in view
    return self.dispatch(request, *args, **kwargs)
  File "C:\Users\TARUNVYDA\PycharmProjects\FundooNotes\venv\lib\site-packages\rest_framework\views.py", line 509, in dispatch
    response = self.handle_exception(exc)
  File "C:\Users\TARUNVYDA\PycharmProjects\FundooNotes\venv\lib\site-packages\rest_framework\views.py", line 469, in handle_exception
    self.raise_uncaught_exception(exc)
  File "C:\Users\TARUNVYDA\PycharmProjects\FundooNotes\venv\lib\site-packages\rest_framework\views.py", line 480, in raise_uncaught_exception
    raise exc
  File "C:\Users\TARUNVYDA\PycharmProjects\FundooNotes\venv\lib\site-packages\rest_framework\views.py", line 506, in dispatch
    response = handler(request, *args, **kwargs)
  File "C:\Users\TARUNVYDA\CloneProjects\FundooNotes\fundoo\fundooapp\views.py", line 41, in post
    Cache.set_cache(self, user.id, token)
  File "C:\Users\TARUNVYDA\CloneProjects\FundooNotes\fundoo\services\cache.py", line 10, in set_cache
    self.r.set(key, value)
AttributeError: 'LoginAPIView' object has no attribute 'r'
2020-12-26 23:39:23,861:INFO:C:\Users\TARUNVYDA\CloneProjects\FundooNotes\fundoo\fundooapp\views.py changed, reloading.
2020-12-26 23:39:23,861:DEBUG:Using selector: SelectSelector
2020-12-26 23:39:29,029:ERROR:Internal Server Error: /login/
Traceback (most recent call last):
  File "C:\Users\TARUNVYDA\PycharmProjects\FundooNotes\venv\lib\site-packages\django\core\handlers\exception.py", line 47, in inner
    response = get_response(request)
  File "C:\Users\TARUNVYDA\PycharmProjects\FundooNotes\venv\lib\site-packages\django\core\handlers\base.py", line 179, in _get_response
    response = wrapped_callback(request, *callback_args, **callback_kwargs)
  File "C:\Users\TARUNVYDA\PycharmProjects\FundooNotes\venv\lib\site-packages\django\views\decorators\csrf.py", line 54, in wrapped_view
    return view_func(*args, **kwargs)
  File "C:\Users\TARUNVYDA\PycharmProjects\FundooNotes\venv\lib\site-packages\django\views\generic\base.py", line 70, in view
    return self.dispatch(request, *args, **kwargs)
  File "C:\Users\TARUNVYDA\PycharmProjects\FundooNotes\venv\lib\site-packages\rest_framework\views.py", line 509, in dispatch
    response = self.handle_exception(exc)
  File "C:\Users\TARUNVYDA\PycharmProjects\FundooNotes\venv\lib\site-packages\rest_framework\views.py", line 469, in handle_exception
    self.raise_uncaught_exception(exc)
  File "C:\Users\TARUNVYDA\PycharmProjects\FundooNotes\venv\lib\site-packages\rest_framework\views.py", line 480, in raise_uncaught_exception
    raise exc
  File "C:\Users\TARUNVYDA\PycharmProjects\FundooNotes\venv\lib\site-packages\rest_framework\views.py", line 506, in dispatch
    response = handler(request, *args, **kwargs)
  File "C:\Users\TARUNVYDA\CloneProjects\FundooNotes\fundoo\fundooapp\views.py", line 41, in post
    Cache.set_cache(user.id, token)
TypeError: set_cache() missing 1 required positional argument: 'value'
2020-12-26 23:39:58,244:INFO:C:\Users\TARUNVYDA\CloneProjects\FundooNotes\fundoo\services\cache.py changed, reloading.
2020-12-26 23:39:58,260:DEBUG:Using selector: SelectSelector
2020-12-26 23:40:03,428:ERROR:Internal Server Error: /login/
Traceback (most recent call last):
  File "C:\Users\TARUNVYDA\PycharmProjects\FundooNotes\venv\lib\site-packages\django\core\handlers\exception.py", line 47, in inner
    response = get_response(request)
  File "C:\Users\TARUNVYDA\PycharmProjects\FundooNotes\venv\lib\site-packages\django\core\handlers\base.py", line 179, in _get_response
    response = wrapped_callback(request, *callback_args, **callback_kwargs)
  File "C:\Users\TARUNVYDA\PycharmProjects\FundooNotes\venv\lib\site-packages\django\views\decorators\csrf.py", line 54, in wrapped_view
    return view_func(*args, **kwargs)
  File "C:\Users\TARUNVYDA\PycharmProjects\FundooNotes\venv\lib\site-packages\django\views\generic\base.py", line 70, in view
    return self.dispatch(request, *args, **kwargs)
  File "C:\Users\TARUNVYDA\PycharmProjects\FundooNotes\venv\lib\site-packages\rest_framework\views.py", line 509, in dispatch
    response = self.handle_exception(exc)
  File "C:\Users\TARUNVYDA\PycharmProjects\FundooNotes\venv\lib\site-packages\rest_framework\views.py", line 469, in handle_exception
    self.raise_uncaught_exception(exc)
  File "C:\Users\TARUNVYDA\PycharmProjects\FundooNotes\venv\lib\site-packages\rest_framework\views.py", line 480, in raise_uncaught_exception
    raise exc
  File "C:\Users\TARUNVYDA\PycharmProjects\FundooNotes\venv\lib\site-packages\rest_framework\views.py", line 506, in dispatch
    response = handler(request, *args, **kwargs)
  File "C:\Users\TARUNVYDA\CloneProjects\FundooNotes\fundoo\fundooapp\views.py", line 41, in post
    Cache.set_cache(user.id, token)
  File "C:\Users\TARUNVYDA\CloneProjects\FundooNotes\fundoo\services\cache.py", line 10, in set_cache
    self.r.set(key, value)
NameError: name 'self' is not defined
2020-12-26 23:40:17,235:DEBUG:Using selector: SelectSelector
2020-12-26 23:44:49,687:DEBUG:{'token': 'eyJ0eXAiOiJKV1QiLCJhbGciOiJIUzI1NiJ9.eyJpZCI6MX0.-xXA0iKB4mVNvWLYFtt2xNiYkFpObF54J9lj2RwduAI'}
2020-12-26 23:45:10,157:DEBUG:{'token': 'eyJ0eXAiOiJKV1QiLCJhbGciOiJIUzI1NiJ9.eyJpZCI6MX0.-xXA0iKB4mVNvWLYFtt2xNiYkFpObF54J9lj2RwduAI'}
2020-12-26 23:45:14,094:DEBUG:{'token': 'eyJ0eXAiOiJKV1QiLCJhbGciOiJIUzI1NiJ9.eyJpZCI6M30.O09y2tVCvQ7wE-CkRe3uFQJchj3KQj1F8alZ1ChGcGg'}
2020-12-26 23:45:57,678:INFO:C:\Users\TARUNVYDA\CloneProjects\FundooNotes\fundoo\services\cache.py changed, reloading.
2020-12-26 23:45:57,678:DEBUG:Using selector: SelectSelector
2020-12-26 23:46:03,477:DEBUG:{'status': True, 'message': {'id': 1, 'title': 'my put note11', 'description': 'this is my testing note for put', 'created_time': '2020-12-21T07:12:08.603603Z', 'updated_time': '2020-12-22T05:45:47.772013Z', 'is_archived': False, 'is_deleted': False, 'color': '#00F0FF', 'image': None, 'trash': False, 'is_pinned': False, 'user': 1, 'label': [1], 'collaborate': [3]}}, status_code = 200
2020-12-26 23:47:00,539:DEBUG:{'token': 'eyJ0eXAiOiJKV1QiLCJhbGciOiJIUzI1NiJ9.eyJpZCI6M30.O09y2tVCvQ7wE-CkRe3uFQJchj3KQj1F8alZ1ChGcGg'}
2020-12-26 23:47:03,299:DEBUG:{'token': 'eyJ0eXAiOiJKV1QiLCJhbGciOiJIUzI1NiJ9.eyJpZCI6MX0.-xXA0iKB4mVNvWLYFtt2xNiYkFpObF54J9lj2RwduAI'}
2020-12-26 23:47:05,915:DEBUG:{'status': True, 'message': {'id': 1, 'title': 'my put note11', 'description': 'this is my testing note for put', 'created_time': '2020-12-21T07:12:08.603603Z', 'updated_time': '2020-12-22T05:45:47.772013Z', 'is_archived': False, 'is_deleted': False, 'color': '#00F0FF', 'image': None, 'trash': False, 'is_pinned': False, 'user': 1, 'label': [1], 'collaborate': [3]}}, status_code = 200
2020-12-26 23:47:21,121:DEBUG:{'status': True, 'message': {'id': 1, 'title': 'my put note11', 'description': 'this is my testing note for put', 'created_time': '2020-12-21T07:12:08.603603Z', 'updated_time': '2020-12-22T05:45:47.772013Z', 'is_archived': False, 'is_deleted': False, 'color': '#00F0FF', 'image': None, 'trash': False, 'is_pinned': False, 'user': 1, 'label': [1], 'collaborate': [3]}}, status_code = 200
2020-12-26 23:47:24,711:DEBUG:Using selector: SelectSelector
2020-12-26 23:50:54,942:DEBUG:Using selector: SelectSelector
2020-12-26 23:51:58,254:DEBUG:{'token': 'eyJ0eXAiOiJKV1QiLCJhbGciOiJIUzI1NiJ9.eyJpZCI6MX0.-xXA0iKB4mVNvWLYFtt2xNiYkFpObF54J9lj2RwduAI'}
2020-12-26 23:52:00,741:DEBUG:{'status': True, 'message': {'id': 1, 'title': 'my put note11', 'description': 'this is my testing note for put', 'created_time': '2020-12-21T07:12:08.603603Z', 'updated_time': '2020-12-22T05:45:47.772013Z', 'is_archived': False, 'is_deleted': False, 'color': '#00F0FF', 'image': None, 'trash': False, 'is_pinned': False, 'user': 1, 'label': [1], 'collaborate': [3]}}, status_code = 200
2020-12-26 23:52:03,456:DEBUG:{'status': True, 'message': {'id': 1, 'title': 'my put note11', 'description': 'this is my testing note for put', 'created_time': '2020-12-21T07:12:08.603603Z', 'updated_time': '2020-12-22T05:45:47.772013Z', 'is_archived': False, 'is_deleted': False, 'color': '#00F0FF', 'image': None, 'trash': False, 'is_pinned': False, 'user': 1, 'label': [1], 'collaborate': [3]}}, status_code = 200
2020-12-26 23:52:13,397:DEBUG:Using selector: SelectSelector
2020-12-26 23:57:32,835:DEBUG:{'token': 'eyJ0eXAiOiJKV1QiLCJhbGciOiJIUzI1NiJ9.eyJpZCI6MX0.-xXA0iKB4mVNvWLYFtt2xNiYkFpObF54J9lj2RwduAI'}
2020-12-26 23:57:36,512:DEBUG:{'status': True, 'message': {'id': 1, 'title': 'my put note11', 'description': 'this is my testing note for put', 'created_time': '2020-12-21T07:12:08.603603Z', 'updated_time': '2020-12-22T05:45:47.772013Z', 'is_archived': False, 'is_deleted': False, 'color': '#00F0FF', 'image': None, 'trash': False, 'is_pinned': False, 'user': 1, 'label': [1], 'collaborate': [3]}}, status_code = 200
2020-12-26 23:57:40,260:DEBUG:Using selector: SelectSelector
2020-12-26 23:58:37,427:DEBUG:{'token': 'eyJ0eXAiOiJKV1QiLCJhbGciOiJIUzI1NiJ9.eyJpZCI6MX0.-xXA0iKB4mVNvWLYFtt2xNiYkFpObF54J9lj2RwduAI'}
2020-12-26 23:58:39,582:DEBUG:{'status': True, 'message': {'id': 1, 'title': 'my put note11', 'description': 'this is my testing note for put', 'created_time': '2020-12-21T07:12:08.603603Z', 'updated_time': '2020-12-22T05:45:47.772013Z', 'is_archived': False, 'is_deleted': False, 'color': '#00F0FF', 'image': None, 'trash': False, 'is_pinned': False, 'user': 1, 'label': [1], 'collaborate': [3]}}, status_code = 200
2020-12-26 23:58:43,677:DEBUG:Using selector: SelectSelector
2020-12-27 00:17:43,537:INFO:C:\Users\TARUNVYDA\CloneProjects\FundooNotes\fundoo\fundooapp\decorator.py changed, reloading.
2020-12-27 00:17:43,537:DEBUG:Using selector: SelectSelector
2020-12-27 00:19:10,473:INFO:C:\Users\TARUNVYDA\CloneProjects\FundooNotes\fundoo\fundooapp\decorator.py changed, reloading.
2020-12-27 00:19:10,473:DEBUG:Using selector: SelectSelector
2020-12-27 00:19:16,088:DEBUG:{'message': "logged in user's token is not provided", 'status': False}
2020-12-27 00:19:54,108:INFO:C:\Users\TARUNVYDA\CloneProjects\FundooNotes\fundoo\fundooapp\decorator.py changed, reloading.
2020-12-27 00:19:54,123:DEBUG:Using selector: SelectSelector
2020-12-27 00:19:59,238:DEBUG:{'message': "logged in user's token is not provided", 'status': False}400
2020-12-27 00:20:23,870:INFO:C:\Users\TARUNVYDA\CloneProjects\FundooNotes\fundoo\fundooapp\decorator.py changed, reloading.
2020-12-27 00:20:23,870:DEBUG:Using selector: SelectSelector
2020-12-27 00:20:32,778:INFO:C:\Users\TARUNVYDA\CloneProjects\FundooNotes\fundoo\fundooapp\decorator.py changed, reloading.
2020-12-27 00:20:32,778:DEBUG:Using selector: SelectSelector
2020-12-27 00:20:37,587:DEBUG:{'message': "logged in user's token is not provided", 'status': False} status_code = 400
2020-12-27 00:21:53,338:INFO:C:\Users\TARUNVYDA\CloneProjects\FundooNotes\fundoo\fundooapp\decorator.py changed, reloading.
2020-12-27 00:21:53,338:DEBUG:Using selector: SelectSelector
2020-12-27 00:22:04,873:DEBUG:{'token': 'eyJ0eXAiOiJKV1QiLCJhbGciOiJIUzI1NiJ9.eyJpZCI6MX0.-xXA0iKB4mVNvWLYFtt2xNiYkFpObF54J9lj2RwduAI'}
2020-12-27 00:22:09,265:DEBUG:{'message': 'token verification successful', 'status': True} status_code = 200
2020-12-27 00:22:09,328:DEBUG:{'status': True, 'message': {'id': 1, 'title': 'my put note11', 'description': 'this is my testing note for put', 'created_time': '2020-12-21T07:12:08.603603Z', 'updated_time': '2020-12-22T05:45:47.772013Z', 'is_archived': False, 'is_deleted': False, 'color': '#00F0FF', 'image': None, 'trash': False, 'is_pinned': False, 'user': 1, 'label': [1], 'collaborate': [3]}}, status_code = 200
2020-12-27 00:22:45,381:DEBUG:Using selector: SelectSelector
2020-12-27 00:24:50,761:DEBUG:{'message': "logged in user's token is not provided", 'status': False} status_code = 400
2020-12-27 00:25:00,289:WARNING:Unauthorized: /login/
2020-12-27 00:28:55,395:INFO:C:\Users\TARUNVYDA\CloneProjects\FundooNotes\fundoo\fundooapp\serializers.py changed, reloading.
2020-12-27 00:28:55,395:DEBUG:Using selector: SelectSelector
2020-12-27 00:30:59,043:INFO:C:\Users\TARUNVYDA\CloneProjects\FundooNotes\fundoo\fundooapp\serializers.py changed, reloading.
2020-12-27 00:30:59,043:DEBUG:Using selector: SelectSelector
2020-12-27 00:32:04,725:ERROR:Internal Server Error: /login/
Traceback (most recent call last):
  File "C:\Users\TARUNVYDA\PycharmProjects\FundooNotes\venv\lib\site-packages\rest_framework\fields.py", line 457, in get_attribute
    return get_attribute(instance, self.source_attrs)
  File "C:\Users\TARUNVYDA\PycharmProjects\FundooNotes\venv\lib\site-packages\rest_framework\fields.py", line 97, in get_attribute
    instance = getattr(instance, attr)
AttributeError: 'Response' object has no attribute 'email'

During handling of the above exception, another exception occurred:

Traceback (most recent call last):
  File "C:\Users\TARUNVYDA\PycharmProjects\FundooNotes\venv\lib\site-packages\django\core\handlers\exception.py", line 47, in inner
    response = get_response(request)
  File "C:\Users\TARUNVYDA\PycharmProjects\FundooNotes\venv\lib\site-packages\django\core\handlers\base.py", line 179, in _get_response
    response = wrapped_callback(request, *callback_args, **callback_kwargs)
  File "C:\Users\TARUNVYDA\PycharmProjects\FundooNotes\venv\lib\site-packages\django\views\decorators\csrf.py", line 54, in wrapped_view
    return view_func(*args, **kwargs)
  File "C:\Users\TARUNVYDA\PycharmProjects\FundooNotes\venv\lib\site-packages\django\views\generic\base.py", line 70, in view
    return self.dispatch(request, *args, **kwargs)
  File "C:\Users\TARUNVYDA\PycharmProjects\FundooNotes\venv\lib\site-packages\rest_framework\views.py", line 509, in dispatch
    response = self.handle_exception(exc)
  File "C:\Users\TARUNVYDA\PycharmProjects\FundooNotes\venv\lib\site-packages\rest_framework\views.py", line 469, in handle_exception
    self.raise_uncaught_exception(exc)
  File "C:\Users\TARUNVYDA\PycharmProjects\FundooNotes\venv\lib\site-packages\rest_framework\views.py", line 480, in raise_uncaught_exception
    raise exc
  File "C:\Users\TARUNVYDA\PycharmProjects\FundooNotes\venv\lib\site-packages\rest_framework\views.py", line 506, in dispatch
    response = handler(request, *args, **kwargs)
  File "C:\Users\TARUNVYDA\CloneProjects\FundooNotes\fundoo\fundooapp\views.py", line 40, in post
    user = Account.objects.get(email=serializer.data['email'])
  File "C:\Users\TARUNVYDA\PycharmProjects\FundooNotes\venv\lib\site-packages\rest_framework\serializers.py", line 548, in data
    ret = super().data
  File "C:\Users\TARUNVYDA\PycharmProjects\FundooNotes\venv\lib\site-packages\rest_framework\serializers.py", line 248, in data
    self._data = self.to_representation(self.validated_data)
  File "C:\Users\TARUNVYDA\PycharmProjects\FundooNotes\venv\lib\site-packages\rest_framework\serializers.py", line 502, in to_representation
    attribute = field.get_attribute(instance)
  File "C:\Users\TARUNVYDA\PycharmProjects\FundooNotes\venv\lib\site-packages\rest_framework\fields.py", line 490, in get_attribute
    raise type(exc)(msg)
AttributeError: Got AttributeError when attempting to get a value for field `email` on serializer `LoginSerializer`.
The serializer field might be named incorrectly and not match any attribute or key on the `Response` instance.
Original exception text was: 'Response' object has no attribute 'email'.
2020-12-27 00:32:08,732:ERROR:Internal Server Error: /login/
Traceback (most recent call last):
  File "C:\Users\TARUNVYDA\PycharmProjects\FundooNotes\venv\lib\site-packages\rest_framework\fields.py", line 457, in get_attribute
    return get_attribute(instance, self.source_attrs)
  File "C:\Users\TARUNVYDA\PycharmProjects\FundooNotes\venv\lib\site-packages\rest_framework\fields.py", line 97, in get_attribute
    instance = getattr(instance, attr)
AttributeError: 'Response' object has no attribute 'email'

During handling of the above exception, another exception occurred:

Traceback (most recent call last):
  File "C:\Users\TARUNVYDA\PycharmProjects\FundooNotes\venv\lib\site-packages\django\core\handlers\exception.py", line 47, in inner
    response = get_response(request)
  File "C:\Users\TARUNVYDA\PycharmProjects\FundooNotes\venv\lib\site-packages\django\core\handlers\base.py", line 179, in _get_response
    response = wrapped_callback(request, *callback_args, **callback_kwargs)
  File "C:\Users\TARUNVYDA\PycharmProjects\FundooNotes\venv\lib\site-packages\django\views\decorators\csrf.py", line 54, in wrapped_view
    return view_func(*args, **kwargs)
  File "C:\Users\TARUNVYDA\PycharmProjects\FundooNotes\venv\lib\site-packages\django\views\generic\base.py", line 70, in view
    return self.dispatch(request, *args, **kwargs)
  File "C:\Users\TARUNVYDA\PycharmProjects\FundooNotes\venv\lib\site-packages\rest_framework\views.py", line 509, in dispatch
    response = self.handle_exception(exc)
  File "C:\Users\TARUNVYDA\PycharmProjects\FundooNotes\venv\lib\site-packages\rest_framework\views.py", line 469, in handle_exception
    self.raise_uncaught_exception(exc)
  File "C:\Users\TARUNVYDA\PycharmProjects\FundooNotes\venv\lib\site-packages\rest_framework\views.py", line 480, in raise_uncaught_exception
    raise exc
  File "C:\Users\TARUNVYDA\PycharmProjects\FundooNotes\venv\lib\site-packages\rest_framework\views.py", line 506, in dispatch
    response = handler(request, *args, **kwargs)
  File "C:\Users\TARUNVYDA\CloneProjects\FundooNotes\fundoo\fundooapp\views.py", line 40, in post
    user = Account.objects.get(email=serializer.data['email'])
  File "C:\Users\TARUNVYDA\PycharmProjects\FundooNotes\venv\lib\site-packages\rest_framework\serializers.py", line 548, in data
    ret = super().data
  File "C:\Users\TARUNVYDA\PycharmProjects\FundooNotes\venv\lib\site-packages\rest_framework\serializers.py", line 248, in data
    self._data = self.to_representation(self.validated_data)
  File "C:\Users\TARUNVYDA\PycharmProjects\FundooNotes\venv\lib\site-packages\rest_framework\serializers.py", line 502, in to_representation
    attribute = field.get_attribute(instance)
  File "C:\Users\TARUNVYDA\PycharmProjects\FundooNotes\venv\lib\site-packages\rest_framework\fields.py", line 490, in get_attribute
    raise type(exc)(msg)
AttributeError: Got AttributeError when attempting to get a value for field `email` on serializer `LoginSerializer`.
The serializer field might be named incorrectly and not match any attribute or key on the `Response` instance.
Original exception text was: 'Response' object has no attribute 'email'.
2020-12-27 00:33:28,692:INFO:C:\Users\TARUNVYDA\CloneProjects\FundooNotes\fundoo\fundooapp\serializers.py changed, reloading.
2020-12-27 00:33:28,692:DEBUG:Using selector: SelectSelector
2020-12-27 00:33:33,867:ERROR:Internal Server Error: /login/
Traceback (most recent call last):
  File "C:\Users\TARUNVYDA\PycharmProjects\FundooNotes\venv\lib\site-packages\rest_framework\fields.py", line 457, in get_attribute
    return get_attribute(instance, self.source_attrs)
  File "C:\Users\TARUNVYDA\PycharmProjects\FundooNotes\venv\lib\site-packages\rest_framework\fields.py", line 97, in get_attribute
    instance = getattr(instance, attr)
AttributeError: 'set' object has no attribute 'email'

During handling of the above exception, another exception occurred:

Traceback (most recent call last):
  File "C:\Users\TARUNVYDA\PycharmProjects\FundooNotes\venv\lib\site-packages\django\core\handlers\exception.py", line 47, in inner
    response = get_response(request)
  File "C:\Users\TARUNVYDA\PycharmProjects\FundooNotes\venv\lib\site-packages\django\core\handlers\base.py", line 179, in _get_response
    response = wrapped_callback(request, *callback_args, **callback_kwargs)
  File "C:\Users\TARUNVYDA\PycharmProjects\FundooNotes\venv\lib\site-packages\django\views\decorators\csrf.py", line 54, in wrapped_view
    return view_func(*args, **kwargs)
  File "C:\Users\TARUNVYDA\PycharmProjects\FundooNotes\venv\lib\site-packages\django\views\generic\base.py", line 70, in view
    return self.dispatch(request, *args, **kwargs)
  File "C:\Users\TARUNVYDA\PycharmProjects\FundooNotes\venv\lib\site-packages\rest_framework\views.py", line 509, in dispatch
    response = self.handle_exception(exc)
  File "C:\Users\TARUNVYDA\PycharmProjects\FundooNotes\venv\lib\site-packages\rest_framework\views.py", line 469, in handle_exception
    self.raise_uncaught_exception(exc)
  File "C:\Users\TARUNVYDA\PycharmProjects\FundooNotes\venv\lib\site-packages\rest_framework\views.py", line 480, in raise_uncaught_exception
    raise exc
  File "C:\Users\TARUNVYDA\PycharmProjects\FundooNotes\venv\lib\site-packages\rest_framework\views.py", line 506, in dispatch
    response = handler(request, *args, **kwargs)
  File "C:\Users\TARUNVYDA\CloneProjects\FundooNotes\fundoo\fundooapp\views.py", line 40, in post
    user = Account.objects.get(email=serializer.data['email'])
  File "C:\Users\TARUNVYDA\PycharmProjects\FundooNotes\venv\lib\site-packages\rest_framework\serializers.py", line 548, in data
    ret = super().data
  File "C:\Users\TARUNVYDA\PycharmProjects\FundooNotes\venv\lib\site-packages\rest_framework\serializers.py", line 248, in data
    self._data = self.to_representation(self.validated_data)
  File "C:\Users\TARUNVYDA\PycharmProjects\FundooNotes\venv\lib\site-packages\rest_framework\serializers.py", line 502, in to_representation
    attribute = field.get_attribute(instance)
  File "C:\Users\TARUNVYDA\PycharmProjects\FundooNotes\venv\lib\site-packages\rest_framework\fields.py", line 490, in get_attribute
    raise type(exc)(msg)
AttributeError: Got AttributeError when attempting to get a value for field `email` on serializer `LoginSerializer`.
The serializer field might be named incorrectly and not match any attribute or key on the `set` instance.
Original exception text was: 'set' object has no attribute 'email'.
2020-12-27 00:35:07,467:INFO:C:\Users\TARUNVYDA\CloneProjects\FundooNotes\fundoo\fundooapp\serializers.py changed, reloading.
2020-12-27 00:35:07,467:DEBUG:Using selector: SelectSelector
2020-12-27 00:38:11,915:INFO:C:\Users\TARUNVYDA\CloneProjects\FundooNotes\fundoo\fundooapp\views.py changed, reloading.
2020-12-27 00:38:11,915:DEBUG:Using selector: SelectSelector
2020-12-27 00:38:18,153:DEBUG:{'status': False, 'message': 'some other issue please try after some time'}, status_code = 400
2020-12-27 00:38:18,156:WARNING:Bad Request: /login/
2020-12-27 00:39:29,742:INFO:C:\Users\TARUNVYDA\CloneProjects\FundooNotes\fundoo\notes\utils.py changed, reloading.
2020-12-27 00:39:29,742:DEBUG:Using selector: SelectSelector
2020-12-27 00:39:34,563:DEBUG:{'status': False, 'message': 'some other issue please try after some time'}, exception = Invalid credentials, try again, status_code = 400
2020-12-27 00:39:34,565:WARNING:Bad Request: /login/
2020-12-27 00:40:09,721:INFO:C:\Users\TARUNVYDA\CloneProjects\FundooNotes\fundoo\fundooapp\views.py changed, reloading.
2020-12-27 00:40:09,721:DEBUG:Using selector: SelectSelector
2020-12-27 00:40:14,970:ERROR:Internal Server Error: /login/
Traceback (most recent call last):
  File "C:\Users\TARUNVYDA\CloneProjects\FundooNotes\fundoo\fundooapp\views.py", line 42, in post
    serializer.is_valid(raise_exception=True)
  File "C:\Users\TARUNVYDA\PycharmProjects\FundooNotes\venv\lib\site-packages\rest_framework\serializers.py", line 220, in is_valid
    self._validated_data = self.run_validation(self.initial_data)
  File "C:\Users\TARUNVYDA\PycharmProjects\FundooNotes\venv\lib\site-packages\rest_framework\serializers.py", line 422, in run_validation
    value = self.validate(value)
  File "C:\Users\TARUNVYDA\CloneProjects\FundooNotes\fundoo\fundooapp\serializers.py", line 68, in validate
    raise AuthenticationFailed('Invalid credentials, try again')
rest_framework.exceptions.AuthenticationFailed: Invalid credentials, try again

During handling of the above exception, another exception occurred:

Traceback (most recent call last):
  File "C:\Users\TARUNVYDA\PycharmProjects\FundooNotes\venv\lib\site-packages\django\core\handlers\exception.py", line 47, in inner
    response = get_response(request)
  File "C:\Users\TARUNVYDA\PycharmProjects\FundooNotes\venv\lib\site-packages\django\core\handlers\base.py", line 179, in _get_response
    response = wrapped_callback(request, *callback_args, **callback_kwargs)
  File "C:\Users\TARUNVYDA\PycharmProjects\FundooNotes\venv\lib\site-packages\django\views\decorators\csrf.py", line 54, in wrapped_view
    return view_func(*args, **kwargs)
  File "C:\Users\TARUNVYDA\PycharmProjects\FundooNotes\venv\lib\site-packages\django\views\generic\base.py", line 70, in view
    return self.dispatch(request, *args, **kwargs)
  File "C:\Users\TARUNVYDA\PycharmProjects\FundooNotes\venv\lib\site-packages\rest_framework\views.py", line 509, in dispatch
    response = self.handle_exception(exc)
  File "C:\Users\TARUNVYDA\PycharmProjects\FundooNotes\venv\lib\site-packages\rest_framework\views.py", line 469, in handle_exception
    self.raise_uncaught_exception(exc)
  File "C:\Users\TARUNVYDA\PycharmProjects\FundooNotes\venv\lib\site-packages\rest_framework\views.py", line 480, in raise_uncaught_exception
    raise exc
  File "C:\Users\TARUNVYDA\PycharmProjects\FundooNotes\venv\lib\site-packages\rest_framework\views.py", line 506, in dispatch
    response = handler(request, *args, **kwargs)
  File "C:\Users\TARUNVYDA\CloneProjects\FundooNotes\fundoo\fundooapp\views.py", line 51, in post
    status_code=status.HTTP_400_BAD_REQUEST)
  File "C:\Users\TARUNVYDA\CloneProjects\FundooNotes\fundoo\notes\utils.py", line 67, in manage_response
    logging.debug('{}, exception = {}, status_code = {}'.format(result, kwargs['exception'], kwargs['status_code']))
KeyError: 'exception'
2020-12-27 00:40:25,630:INFO:C:\Users\TARUNVYDA\CloneProjects\FundooNotes\fundoo\fundooapp\views.py changed, reloading.
2020-12-27 00:40:25,630:DEBUG:Using selector: SelectSelector
2020-12-27 00:40:31,674:ERROR:Internal Server Error: /login/
Traceback (most recent call last):
  File "C:\Users\TARUNVYDA\CloneProjects\FundooNotes\fundoo\fundooapp\views.py", line 42, in post
    serializer.is_valid(raise_exception=True)
  File "C:\Users\TARUNVYDA\PycharmProjects\FundooNotes\venv\lib\site-packages\rest_framework\serializers.py", line 220, in is_valid
    self._validated_data = self.run_validation(self.initial_data)
  File "C:\Users\TARUNVYDA\PycharmProjects\FundooNotes\venv\lib\site-packages\rest_framework\serializers.py", line 422, in run_validation
    value = self.validate(value)
  File "C:\Users\TARUNVYDA\CloneProjects\FundooNotes\fundoo\fundooapp\serializers.py", line 68, in validate
    raise AuthenticationFailed('Invalid credentials, try again')
rest_framework.exceptions.AuthenticationFailed: Invalid credentials, try again

During handling of the above exception, another exception occurred:

Traceback (most recent call last):
  File "C:\Users\TARUNVYDA\PycharmProjects\FundooNotes\venv\lib\site-packages\django\core\handlers\exception.py", line 47, in inner
    response = get_response(request)
  File "C:\Users\TARUNVYDA\PycharmProjects\FundooNotes\venv\lib\site-packages\django\core\handlers\base.py", line 179, in _get_response
    response = wrapped_callback(request, *callback_args, **callback_kwargs)
  File "C:\Users\TARUNVYDA\PycharmProjects\FundooNotes\venv\lib\site-packages\django\views\decorators\csrf.py", line 54, in wrapped_view
    return view_func(*args, **kwargs)
  File "C:\Users\TARUNVYDA\PycharmProjects\FundooNotes\venv\lib\site-packages\django\views\generic\base.py", line 70, in view
    return self.dispatch(request, *args, **kwargs)
  File "C:\Users\TARUNVYDA\PycharmProjects\FundooNotes\venv\lib\site-packages\rest_framework\views.py", line 509, in dispatch
    response = self.handle_exception(exc)
  File "C:\Users\TARUNVYDA\PycharmProjects\FundooNotes\venv\lib\site-packages\rest_framework\views.py", line 469, in handle_exception
    self.raise_uncaught_exception(exc)
  File "C:\Users\TARUNVYDA\PycharmProjects\FundooNotes\venv\lib\site-packages\rest_framework\views.py", line 480, in raise_uncaught_exception
    raise exc
  File "C:\Users\TARUNVYDA\PycharmProjects\FundooNotes\venv\lib\site-packages\rest_framework\views.py", line 506, in dispatch
    response = handler(request, *args, **kwargs)
  File "C:\Users\TARUNVYDA\CloneProjects\FundooNotes\fundoo\fundooapp\views.py", line 51, in post
    status_code=status.HTTP_400_BAD_REQUEST)
  File "C:\Users\TARUNVYDA\CloneProjects\FundooNotes\fundoo\notes\utils.py", line 67, in manage_response
    logging.debug('{}, exception = {}, status_code = {}'.format(result, kwargs['exception'], kwargs['status_code']))
KeyError: 'exception'
2020-12-27 00:40:34,004:ERROR:Internal Server Error: /login/
Traceback (most recent call last):
  File "C:\Users\TARUNVYDA\CloneProjects\FundooNotes\fundoo\fundooapp\views.py", line 42, in post
    serializer.is_valid(raise_exception=True)
  File "C:\Users\TARUNVYDA\PycharmProjects\FundooNotes\venv\lib\site-packages\rest_framework\serializers.py", line 220, in is_valid
    self._validated_data = self.run_validation(self.initial_data)
  File "C:\Users\TARUNVYDA\PycharmProjects\FundooNotes\venv\lib\site-packages\rest_framework\serializers.py", line 422, in run_validation
    value = self.validate(value)
  File "C:\Users\TARUNVYDA\CloneProjects\FundooNotes\fundoo\fundooapp\serializers.py", line 68, in validate
    raise AuthenticationFailed('Invalid credentials, try again')
rest_framework.exceptions.AuthenticationFailed: Invalid credentials, try again

During handling of the above exception, another exception occurred:

Traceback (most recent call last):
  File "C:\Users\TARUNVYDA\PycharmProjects\FundooNotes\venv\lib\site-packages\django\core\handlers\exception.py", line 47, in inner
    response = get_response(request)
  File "C:\Users\TARUNVYDA\PycharmProjects\FundooNotes\venv\lib\site-packages\django\core\handlers\base.py", line 179, in _get_response
    response = wrapped_callback(request, *callback_args, **callback_kwargs)
  File "C:\Users\TARUNVYDA\PycharmProjects\FundooNotes\venv\lib\site-packages\django\views\decorators\csrf.py", line 54, in wrapped_view
    return view_func(*args, **kwargs)
  File "C:\Users\TARUNVYDA\PycharmProjects\FundooNotes\venv\lib\site-packages\django\views\generic\base.py", line 70, in view
    return self.dispatch(request, *args, **kwargs)
  File "C:\Users\TARUNVYDA\PycharmProjects\FundooNotes\venv\lib\site-packages\rest_framework\views.py", line 509, in dispatch
    response = self.handle_exception(exc)
  File "C:\Users\TARUNVYDA\PycharmProjects\FundooNotes\venv\lib\site-packages\rest_framework\views.py", line 469, in handle_exception
    self.raise_uncaught_exception(exc)
  File "C:\Users\TARUNVYDA\PycharmProjects\FundooNotes\venv\lib\site-packages\rest_framework\views.py", line 480, in raise_uncaught_exception
    raise exc
  File "C:\Users\TARUNVYDA\PycharmProjects\FundooNotes\venv\lib\site-packages\rest_framework\views.py", line 506, in dispatch
    response = handler(request, *args, **kwargs)
  File "C:\Users\TARUNVYDA\CloneProjects\FundooNotes\fundoo\fundooapp\views.py", line 51, in post
    status_code=status.HTTP_400_BAD_REQUEST)
  File "C:\Users\TARUNVYDA\CloneProjects\FundooNotes\fundoo\notes\utils.py", line 67, in manage_response
    logging.debug('{}, exception = {}, status_code = {}'.format(result, kwargs['exception'], kwargs['status_code']))
KeyError: 'exception'
2020-12-27 00:41:04,068:INFO:C:\Users\TARUNVYDA\CloneProjects\FundooNotes\fundoo\notes\utils.py changed, reloading.
2020-12-27 00:41:04,068:DEBUG:Using selector: SelectSelector
2020-12-27 00:41:08,584:DEBUG:{'status': False, 'message': 'Invalid credentials, try again'}, status_code = 400
2020-12-27 00:41:08,586:WARNING:Bad Request: /login/
2020-12-27 00:47:11,198:INFO:C:\Users\TARUNVYDA\CloneProjects\FundooNotes\fundoo\fundooapp\views.py changed, reloading.
2020-12-27 00:47:11,198:DEBUG:Using selector: SelectSelector
2020-12-27 00:47:16,547:DEBUG:{'status': False, 'message': 'Invalid credentials, try again'}, status_code = 400
2020-12-27 00:47:16,549:WARNING:Bad Request: /login/
2020-12-27 00:49:34,553:DEBUG:Using selector: SelectSelector
2020-12-27 00:54:50,761:ERROR:Internal Server Error: /login/
Traceback (most recent call last):
  File "C:\Users\TARUNVYDA\CloneProjects\FundooNotes\fundoo\fundooapp\views.py", line 42, in post
    serializer.is_valid(raise_exception=True)
  File "C:\Users\TARUNVYDA\PycharmProjects\FundooNotes\venv\lib\site-packages\rest_framework\serializers.py", line 220, in is_valid
    self._validated_data = self.run_validation(self.initial_data)
  File "C:\Users\TARUNVYDA\PycharmProjects\FundooNotes\venv\lib\site-packages\rest_framework\serializers.py", line 422, in run_validation
    value = self.validate(value)
  File "C:\Users\TARUNVYDA\CloneProjects\FundooNotes\fundoo\fundooapp\serializers.py", line 68, in validate
    raise AuthenticationFailed('Invalid credentials, try again')
rest_framework.exceptions.AuthenticationFailed: Invalid credentials, try again

During handling of the above exception, another exception occurred:

Traceback (most recent call last):
  File "C:\Users\TARUNVYDA\PycharmProjects\FundooNotes\venv\lib\site-packages\django\core\handlers\exception.py", line 47, in inner
    response = get_response(request)
  File "C:\Users\TARUNVYDA\PycharmProjects\FundooNotes\venv\lib\site-packages\django\core\handlers\base.py", line 179, in _get_response
    response = wrapped_callback(request, *callback_args, **callback_kwargs)
  File "C:\Users\TARUNVYDA\PycharmProjects\FundooNotes\venv\lib\site-packages\django\views\decorators\csrf.py", line 54, in wrapped_view
    return view_func(*args, **kwargs)
  File "C:\Users\TARUNVYDA\PycharmProjects\FundooNotes\venv\lib\site-packages\django\views\generic\base.py", line 70, in view
    return self.dispatch(request, *args, **kwargs)
  File "C:\Users\TARUNVYDA\PycharmProjects\FundooNotes\venv\lib\site-packages\rest_framework\views.py", line 509, in dispatch
    response = self.handle_exception(exc)
  File "C:\Users\TARUNVYDA\PycharmProjects\FundooNotes\venv\lib\site-packages\rest_framework\views.py", line 469, in handle_exception
    self.raise_uncaught_exception(exc)
  File "C:\Users\TARUNVYDA\PycharmProjects\FundooNotes\venv\lib\site-packages\rest_framework\views.py", line 480, in raise_uncaught_exception
    raise exc
  File "C:\Users\TARUNVYDA\PycharmProjects\FundooNotes\venv\lib\site-packages\rest_framework\views.py", line 506, in dispatch
    response = handler(request, *args, **kwargs)
  File "C:\Users\TARUNVYDA\CloneProjects\FundooNotes\fundoo\fundooapp\views.py", line 51, in post
    status_code=status.HTTP_400_BAD_REQUEST)
  File "C:\Users\TARUNVYDA\CloneProjects\FundooNotes\fundoo\notes\utils.py", line 67, in manage_response
    if kwargs['exception'] is None:
KeyError: 'exception'
2020-12-27 00:57:44,913:INFO:C:\Users\TARUNVYDA\CloneProjects\FundooNotes\fundoo\notes\utils.py changed, reloading.
2020-12-27 00:57:44,923:DEBUG:Using selector: SelectSelector
2020-12-27 00:57:49,873:ERROR:Internal Server Error: /login/
Traceback (most recent call last):
  File "C:\Users\TARUNVYDA\CloneProjects\FundooNotes\fundoo\fundooapp\views.py", line 42, in post
    serializer.is_valid(raise_exception=True)
  File "C:\Users\TARUNVYDA\PycharmProjects\FundooNotes\venv\lib\site-packages\rest_framework\serializers.py", line 220, in is_valid
    self._validated_data = self.run_validation(self.initial_data)
  File "C:\Users\TARUNVYDA\PycharmProjects\FundooNotes\venv\lib\site-packages\rest_framework\serializers.py", line 422, in run_validation
    value = self.validate(value)
  File "C:\Users\TARUNVYDA\CloneProjects\FundooNotes\fundoo\fundooapp\serializers.py", line 68, in validate
    raise AuthenticationFailed('Invalid credentials, try again')
rest_framework.exceptions.AuthenticationFailed: Invalid credentials, try again

During handling of the above exception, another exception occurred:

Traceback (most recent call last):
  File "C:\Users\TARUNVYDA\PycharmProjects\FundooNotes\venv\lib\site-packages\django\core\handlers\exception.py", line 47, in inner
    response = get_response(request)
  File "C:\Users\TARUNVYDA\PycharmProjects\FundooNotes\venv\lib\site-packages\django\core\handlers\base.py", line 179, in _get_response
    response = wrapped_callback(request, *callback_args, **callback_kwargs)
  File "C:\Users\TARUNVYDA\PycharmProjects\FundooNotes\venv\lib\site-packages\django\views\decorators\csrf.py", line 54, in wrapped_view
    return view_func(*args, **kwargs)
  File "C:\Users\TARUNVYDA\PycharmProjects\FundooNotes\venv\lib\site-packages\django\views\generic\base.py", line 70, in view
    return self.dispatch(request, *args, **kwargs)
  File "C:\Users\TARUNVYDA\PycharmProjects\FundooNotes\venv\lib\site-packages\rest_framework\views.py", line 509, in dispatch
    response = self.handle_exception(exc)
  File "C:\Users\TARUNVYDA\PycharmProjects\FundooNotes\venv\lib\site-packages\rest_framework\views.py", line 469, in handle_exception
    self.raise_uncaught_exception(exc)
  File "C:\Users\TARUNVYDA\PycharmProjects\FundooNotes\venv\lib\site-packages\rest_framework\views.py", line 480, in raise_uncaught_exception
    raise exc
  File "C:\Users\TARUNVYDA\PycharmProjects\FundooNotes\venv\lib\site-packages\rest_framework\views.py", line 506, in dispatch
    response = handler(request, *args, **kwargs)
  File "C:\Users\TARUNVYDA\CloneProjects\FundooNotes\fundoo\fundooapp\views.py", line 51, in post
    status_code=status.HTTP_400_BAD_REQUEST)
  File "C:\Users\TARUNVYDA\CloneProjects\FundooNotes\fundoo\notes\utils.py", line 67, in manage_response
    if kwargs['exception']:
KeyError: 'exception'
2020-12-27 00:58:14,002:INFO:C:\Users\TARUNVYDA\CloneProjects\FundooNotes\fundoo\notes\utils.py changed, reloading.
2020-12-27 00:58:14,002:DEBUG:Using selector: SelectSelector
2020-12-27 00:58:19,866:ERROR:Internal Server Error: /login/
Traceback (most recent call last):
  File "C:\Users\TARUNVYDA\CloneProjects\FundooNotes\fundoo\fundooapp\views.py", line 42, in post
    serializer.is_valid(raise_exception=True)
  File "C:\Users\TARUNVYDA\PycharmProjects\FundooNotes\venv\lib\site-packages\rest_framework\serializers.py", line 220, in is_valid
    self._validated_data = self.run_validation(self.initial_data)
  File "C:\Users\TARUNVYDA\PycharmProjects\FundooNotes\venv\lib\site-packages\rest_framework\serializers.py", line 422, in run_validation
    value = self.validate(value)
  File "C:\Users\TARUNVYDA\CloneProjects\FundooNotes\fundoo\fundooapp\serializers.py", line 68, in validate
    raise AuthenticationFailed('Invalid credentials, try again')
rest_framework.exceptions.AuthenticationFailed: Invalid credentials, try again

During handling of the above exception, another exception occurred:

Traceback (most recent call last):
  File "C:\Users\TARUNVYDA\PycharmProjects\FundooNotes\venv\lib\site-packages\django\core\handlers\exception.py", line 47, in inner
    response = get_response(request)
  File "C:\Users\TARUNVYDA\PycharmProjects\FundooNotes\venv\lib\site-packages\django\core\handlers\base.py", line 179, in _get_response
    response = wrapped_callback(request, *callback_args, **callback_kwargs)
  File "C:\Users\TARUNVYDA\PycharmProjects\FundooNotes\venv\lib\site-packages\django\views\decorators\csrf.py", line 54, in wrapped_view
    return view_func(*args, **kwargs)
  File "C:\Users\TARUNVYDA\PycharmProjects\FundooNotes\venv\lib\site-packages\django\views\generic\base.py", line 70, in view
    return self.dispatch(request, *args, **kwargs)
  File "C:\Users\TARUNVYDA\PycharmProjects\FundooNotes\venv\lib\site-packages\rest_framework\views.py", line 509, in dispatch
    response = self.handle_exception(exc)
  File "C:\Users\TARUNVYDA\PycharmProjects\FundooNotes\venv\lib\site-packages\rest_framework\views.py", line 469, in handle_exception
    self.raise_uncaught_exception(exc)
  File "C:\Users\TARUNVYDA\PycharmProjects\FundooNotes\venv\lib\site-packages\rest_framework\views.py", line 480, in raise_uncaught_exception
    raise exc
  File "C:\Users\TARUNVYDA\PycharmProjects\FundooNotes\venv\lib\site-packages\rest_framework\views.py", line 506, in dispatch
    response = handler(request, *args, **kwargs)
  File "C:\Users\TARUNVYDA\CloneProjects\FundooNotes\fundoo\fundooapp\views.py", line 51, in post
    status_code=status.HTTP_400_BAD_REQUEST)
  File "C:\Users\TARUNVYDA\CloneProjects\FundooNotes\fundoo\notes\utils.py", line 67, in manage_response
    if exception in kwargs:
NameError: name 'exception' is not defined
2020-12-27 00:59:07,291:INFO:C:\Users\TARUNVYDA\CloneProjects\FundooNotes\fundoo\notes\utils.py changed, reloading.
2020-12-27 00:59:07,291:DEBUG:Using selector: SelectSelector
2020-12-27 00:59:12,410:DEBUG:{'status': False, 'message': 'Invalid credentials, try again'}, status_code = 400
2020-12-27 00:59:12,412:WARNING:Bad Request: /login/
2020-12-27 01:03:54,996:INFO:C:\Users\TARUNVYDA\CloneProjects\FundooNotes\fundoo\notes\views.py changed, reloading.
2020-12-27 01:03:54,996:DEBUG:Using selector: SelectSelector
2020-12-27 01:04:09,668:DEBUG:{'status': False, 'message': 'Invalid credentials, try again'}, status_code = 400
2020-12-27 01:04:09,669:WARNING:Bad Request: /login/
2020-12-27 01:04:16,838:DEBUG:{'token': 'eyJ0eXAiOiJKV1QiLCJhbGciOiJIUzI1NiJ9.eyJpZCI6MX0.-xXA0iKB4mVNvWLYFtt2xNiYkFpObF54J9lj2RwduAI'}
2020-12-27 01:04:21,676:DEBUG:{'message': 'token verification successful', 'status': True} status_code = 200
2020-12-27 01:04:21,726:DEBUG:{'status': True, 'message': {'id': 1, 'title': 'my put note11', 'description': 'this is my testing note for put', 'created_time': '2020-12-21T07:12:08.603603Z', 'updated_time': '2020-12-22T05:45:47.772013Z', 'is_archived': False, 'is_deleted': False, 'color': '#00F0FF', 'image': None, 'trash': False, 'is_pinned': False, 'user': 1, 'label': [1], 'collaborate': [3]}}, status_code = 200
2020-12-27 01:04:26,423:DEBUG:{'message': 'token verification successful', 'status': True} status_code = 200
2020-12-27 01:04:26,428:DEBUG:{'status': False, 'message': 'Please enter valid Note id'}, status_code = 404
2020-12-27 01:04:26,428:WARNING:Not Found: /note/55
2020-12-27 01:04:32,806:DEBUG:Using selector: SelectSelector
2020-12-27 01:09:05,007:DEBUG:{'message': "logged in user's token is not provided", 'status': False} status_code = 400
2020-12-27 01:09:35,333:DEBUG:Using selector: SelectSelector
2020-12-27 01:21:35,137:DEBUG:{'token': 'eyJ0eXAiOiJKV1QiLCJhbGciOiJIUzI1NiJ9.eyJpZCI6MX0.-xXA0iKB4mVNvWLYFtt2xNiYkFpObF54J9lj2RwduAI'}
2020-12-27 01:21:35,140:DEBUG:{'status': True, 'message': {'token': 'eyJ0eXAiOiJKV1QiLCJhbGciOiJIUzI1NiJ9.eyJpZCI6MX0.-xXA0iKB4mVNvWLYFtt2xNiYkFpObF54J9lj2RwduAI'}}, status_code = 200
2020-12-27 01:22:11,542:DEBUG:Using selector: SelectSelector
2020-12-27 01:27:45,496:ERROR:{'message': 'Invalid Token', 'status': False}, exception = Not enough segments, status_code = 400
Traceback (most recent call last):
  File "C:\Users\TARUNVYDA\PycharmProjects\FundooNotes\venv\lib\site-packages\jwt\api_jws.py", line 180, in _load
    signing_input, crypto_segment = jwt.rsplit(b'.', 1)
ValueError: not enough values to unpack (expected 2, got 1)

During handling of the above exception, another exception occurred:

Traceback (most recent call last):
  File "C:\Users\TARUNVYDA\CloneProjects\FundooNotes\fundoo\fundooapp\decorator.py", line 16, in wrapper
    decoded_token = jwt.decode(token, config('ENCODE_SECRET_KEY'), algorithms=["HS256"])
  File "C:\Users\TARUNVYDA\PycharmProjects\FundooNotes\venv\lib\site-packages\jwt\api_jwt.py", line 84, in decode
    payload, _, _, _ = self._load(jwt)
  File "C:\Users\TARUNVYDA\PycharmProjects\FundooNotes\venv\lib\site-packages\jwt\api_jws.py", line 183, in _load
    raise DecodeError('Not enough segments')
jwt.exceptions.DecodeError: Not enough segments
2020-12-27 01:27:45,625:ERROR:Internal Server Error: /note/55
Traceback (most recent call last):
  File "C:\Users\TARUNVYDA\PycharmProjects\FundooNotes\venv\lib\site-packages\jwt\api_jws.py", line 180, in _load
    signing_input, crypto_segment = jwt.rsplit(b'.', 1)
ValueError: not enough values to unpack (expected 2, got 1)

During handling of the above exception, another exception occurred:

Traceback (most recent call last):
  File "C:\Users\TARUNVYDA\CloneProjects\FundooNotes\fundoo\fundooapp\decorator.py", line 16, in wrapper
    decoded_token = jwt.decode(token, config('ENCODE_SECRET_KEY'), algorithms=["HS256"])
  File "C:\Users\TARUNVYDA\PycharmProjects\FundooNotes\venv\lib\site-packages\jwt\api_jwt.py", line 84, in decode
    payload, _, _, _ = self._load(jwt)
  File "C:\Users\TARUNVYDA\PycharmProjects\FundooNotes\venv\lib\site-packages\jwt\api_jws.py", line 183, in _load
    raise DecodeError('Not enough segments')
jwt.exceptions.DecodeError: Not enough segments

During handling of the above exception, another exception occurred:

Traceback (most recent call last):
  File "C:\Users\TARUNVYDA\PycharmProjects\FundooNotes\venv\lib\site-packages\django\core\handlers\exception.py", line 47, in inner
    response = get_response(request)
  File "C:\Users\TARUNVYDA\PycharmProjects\FundooNotes\venv\lib\site-packages\django\core\handlers\base.py", line 179, in _get_response
    response = wrapped_callback(request, *callback_args, **callback_kwargs)
  File "C:\Users\TARUNVYDA\PycharmProjects\FundooNotes\venv\lib\site-packages\django\views\decorators\csrf.py", line 54, in wrapped_view
    return view_func(*args, **kwargs)
  File "C:\Users\TARUNVYDA\PycharmProjects\FundooNotes\venv\lib\site-packages\django\views\generic\base.py", line 70, in view
    return self.dispatch(request, *args, **kwargs)
  File "C:\Users\TARUNVYDA\PycharmProjects\FundooNotes\venv\lib\site-packages\django\utils\decorators.py", line 43, in _wrapper
    return bound_method(*args, **kwargs)
  File "C:\Users\TARUNVYDA\CloneProjects\FundooNotes\fundoo\fundooapp\decorator.py", line 34, in wrapper
    return HTTPResponse(json.dumps(result), status.HTTP_400_BAD_REQUEST)
NameError: name 'HTTPResponse' is not defined
2020-12-27 01:31:41,300:ERROR:{'message': 'Invalid Token', 'status': False}, exception = Not enough segments, status_code = 400
Traceback (most recent call last):
  File "C:\Users\TARUNVYDA\PycharmProjects\FundooNotes\venv\lib\site-packages\jwt\api_jws.py", line 180, in _load
    signing_input, crypto_segment = jwt.rsplit(b'.', 1)
ValueError: not enough values to unpack (expected 2, got 1)

During handling of the above exception, another exception occurred:

Traceback (most recent call last):
  File "C:\Users\TARUNVYDA\CloneProjects\FundooNotes\fundoo\fundooapp\decorator.py", line 16, in wrapper
    decoded_token = jwt.decode(token, config('ENCODE_SECRET_KEY'), algorithms=["HS256"])
  File "C:\Users\TARUNVYDA\PycharmProjects\FundooNotes\venv\lib\site-packages\jwt\api_jwt.py", line 84, in decode
    payload, _, _, _ = self._load(jwt)
  File "C:\Users\TARUNVYDA\PycharmProjects\FundooNotes\venv\lib\site-packages\jwt\api_jws.py", line 183, in _load
    raise DecodeError('Not enough segments')
jwt.exceptions.DecodeError: Not enough segments
2020-12-27 01:31:41,400:ERROR:Internal Server Error: /note/55
Traceback (most recent call last):
  File "C:\Users\TARUNVYDA\PycharmProjects\FundooNotes\venv\lib\site-packages\jwt\api_jws.py", line 180, in _load
    signing_input, crypto_segment = jwt.rsplit(b'.', 1)
ValueError: not enough values to unpack (expected 2, got 1)

During handling of the above exception, another exception occurred:

Traceback (most recent call last):
  File "C:\Users\TARUNVYDA\CloneProjects\FundooNotes\fundoo\fundooapp\decorator.py", line 16, in wrapper
    decoded_token = jwt.decode(token, config('ENCODE_SECRET_KEY'), algorithms=["HS256"])
  File "C:\Users\TARUNVYDA\PycharmProjects\FundooNotes\venv\lib\site-packages\jwt\api_jwt.py", line 84, in decode
    payload, _, _, _ = self._load(jwt)
  File "C:\Users\TARUNVYDA\PycharmProjects\FundooNotes\venv\lib\site-packages\jwt\api_jws.py", line 183, in _load
    raise DecodeError('Not enough segments')
jwt.exceptions.DecodeError: Not enough segments

During handling of the above exception, another exception occurred:

Traceback (most recent call last):
  File "C:\Users\TARUNVYDA\PycharmProjects\FundooNotes\venv\lib\site-packages\django\core\handlers\exception.py", line 47, in inner
    response = get_response(request)
  File "C:\Users\TARUNVYDA\PycharmProjects\FundooNotes\venv\lib\site-packages\django\core\handlers\base.py", line 179, in _get_response
    response = wrapped_callback(request, *callback_args, **callback_kwargs)
  File "C:\Users\TARUNVYDA\PycharmProjects\FundooNotes\venv\lib\site-packages\django\views\decorators\csrf.py", line 54, in wrapped_view
    return view_func(*args, **kwargs)
  File "C:\Users\TARUNVYDA\PycharmProjects\FundooNotes\venv\lib\site-packages\django\views\generic\base.py", line 70, in view
    return self.dispatch(request, *args, **kwargs)
  File "C:\Users\TARUNVYDA\PycharmProjects\FundooNotes\venv\lib\site-packages\django\utils\decorators.py", line 43, in _wrapper
    return bound_method(*args, **kwargs)
  File "C:\Users\TARUNVYDA\CloneProjects\FundooNotes\fundoo\fundooapp\decorator.py", line 34, in wrapper
    return HTTPResponse(json.dumps(result), status.HTTP_400_BAD_REQUEST)
NameError: name 'HTTPResponse' is not defined
2020-12-27 01:31:49,252:DEBUG:{'token': 'eyJ0eXAiOiJKV1QiLCJhbGciOiJIUzI1NiJ9.eyJpZCI6MX0.-xXA0iKB4mVNvWLYFtt2xNiYkFpObF54J9lj2RwduAI'}
2020-12-27 01:31:49,252:DEBUG:{'status': True, 'message': {'token': 'eyJ0eXAiOiJKV1QiLCJhbGciOiJIUzI1NiJ9.eyJpZCI6MX0.-xXA0iKB4mVNvWLYFtt2xNiYkFpObF54J9lj2RwduAI'}}, status_code = 200
2020-12-27 01:31:59,934:DEBUG:{'message': 'token verification successful', 'status': True} status_code = 200
2020-12-27 01:31:59,950:DEBUG:{'status': False, 'message': 'Please enter valid Note id'}, status_code = 404
2020-12-27 01:31:59,951:WARNING:Not Found: /note/55
2020-12-27 01:32:08,764:DEBUG:{'message': 'token verification successful', 'status': True} status_code = 200
2020-12-27 01:32:08,810:DEBUG:{'status': True, 'message': {'id': 2, 'title': 'my testing note', 'description': 'this is my second note', 'created_time': '2020-12-21T14:22:19.826517Z', 'updated_time': '2020-12-21T14:22:19.826517Z', 'is_archived': False, 'is_deleted': False, 'color': '#00F0FF', 'image': None, 'trash': False, 'is_pinned': False, 'user': 3, 'label': [1], 'collaborate': [1]}}, status_code = 200
2020-12-27 01:32:22,017:DEBUG:{'message': "logged in user's token is not provided", 'status': False} status_code = 400
2020-12-27 01:33:24,129:ERROR:{'message': 'Invalid Token', 'status': False}, exception = Not enough segments, status_code = 400
Traceback (most recent call last):
  File "C:\Users\TARUNVYDA\PycharmProjects\FundooNotes\venv\lib\site-packages\jwt\api_jws.py", line 180, in _load
    signing_input, crypto_segment = jwt.rsplit(b'.', 1)
ValueError: not enough values to unpack (expected 2, got 1)

During handling of the above exception, another exception occurred:

Traceback (most recent call last):
  File "C:\Users\TARUNVYDA\CloneProjects\FundooNotes\fundoo\fundooapp\decorator.py", line 16, in wrapper
    decoded_token = jwt.decode(token, config('ENCODE_SECRET_KEY'), algorithms=["HS256"])
  File "C:\Users\TARUNVYDA\PycharmProjects\FundooNotes\venv\lib\site-packages\jwt\api_jwt.py", line 84, in decode
    payload, _, _, _ = self._load(jwt)
  File "C:\Users\TARUNVYDA\PycharmProjects\FundooNotes\venv\lib\site-packages\jwt\api_jws.py", line 183, in _load
    raise DecodeError('Not enough segments')
jwt.exceptions.DecodeError: Not enough segments
2020-12-27 01:33:24,225:ERROR:Internal Server Error: /note/2
Traceback (most recent call last):
  File "C:\Users\TARUNVYDA\PycharmProjects\FundooNotes\venv\lib\site-packages\jwt\api_jws.py", line 180, in _load
    signing_input, crypto_segment = jwt.rsplit(b'.', 1)
ValueError: not enough values to unpack (expected 2, got 1)

During handling of the above exception, another exception occurred:

Traceback (most recent call last):
  File "C:\Users\TARUNVYDA\CloneProjects\FundooNotes\fundoo\fundooapp\decorator.py", line 16, in wrapper
    decoded_token = jwt.decode(token, config('ENCODE_SECRET_KEY'), algorithms=["HS256"])
  File "C:\Users\TARUNVYDA\PycharmProjects\FundooNotes\venv\lib\site-packages\jwt\api_jwt.py", line 84, in decode
    payload, _, _, _ = self._load(jwt)
  File "C:\Users\TARUNVYDA\PycharmProjects\FundooNotes\venv\lib\site-packages\jwt\api_jws.py", line 183, in _load
    raise DecodeError('Not enough segments')
jwt.exceptions.DecodeError: Not enough segments

During handling of the above exception, another exception occurred:

Traceback (most recent call last):
  File "C:\Users\TARUNVYDA\PycharmProjects\FundooNotes\venv\lib\site-packages\django\core\handlers\exception.py", line 47, in inner
    response = get_response(request)
  File "C:\Users\TARUNVYDA\PycharmProjects\FundooNotes\venv\lib\site-packages\django\core\handlers\base.py", line 179, in _get_response
    response = wrapped_callback(request, *callback_args, **callback_kwargs)
  File "C:\Users\TARUNVYDA\PycharmProjects\FundooNotes\venv\lib\site-packages\django\views\decorators\csrf.py", line 54, in wrapped_view
    return view_func(*args, **kwargs)
  File "C:\Users\TARUNVYDA\PycharmProjects\FundooNotes\venv\lib\site-packages\django\views\generic\base.py", line 70, in view
    return self.dispatch(request, *args, **kwargs)
  File "C:\Users\TARUNVYDA\PycharmProjects\FundooNotes\venv\lib\site-packages\django\utils\decorators.py", line 43, in _wrapper
    return bound_method(*args, **kwargs)
  File "C:\Users\TARUNVYDA\CloneProjects\FundooNotes\fundoo\fundooapp\decorator.py", line 34, in wrapper
    return HTTPResponse(json.dumps(result), status.HTTP_400_BAD_REQUEST)
NameError: name 'HTTPResponse' is not defined
2020-12-27 01:34:12,019:INFO:C:\Users\TARUNVYDA\CloneProjects\FundooNotes\fundoo\fundooapp\decorator.py changed, reloading.
2020-12-27 01:34:12,019:DEBUG:Using selector: SelectSelector
2020-12-27 01:34:21,396:ERROR:{'message': 'Invalid Token', 'status': False}, exception = Not enough segments, status_code = 400
Traceback (most recent call last):
  File "C:\Users\TARUNVYDA\PycharmProjects\FundooNotes\venv\lib\site-packages\jwt\api_jws.py", line 180, in _load
    signing_input, crypto_segment = jwt.rsplit(b'.', 1)
ValueError: not enough values to unpack (expected 2, got 1)

During handling of the above exception, another exception occurred:

Traceback (most recent call last):
  File "C:\Users\TARUNVYDA\CloneProjects\FundooNotes\fundoo\fundooapp\decorator.py", line 16, in wrapper
    decoded_token = jwt.decode(token, config('ENCODE_SECRET_KEY'), algorithms=["HS256"])
  File "C:\Users\TARUNVYDA\PycharmProjects\FundooNotes\venv\lib\site-packages\jwt\api_jwt.py", line 84, in decode
    payload, _, _, _ = self._load(jwt)
  File "C:\Users\TARUNVYDA\PycharmProjects\FundooNotes\venv\lib\site-packages\jwt\api_jws.py", line 183, in _load
    raise DecodeError('Not enough segments')
jwt.exceptions.DecodeError: Not enough segments
2020-12-27 01:35:36,010:DEBUG:{'message': "logged in user's token is not provided", 'status': False} status_code = 400
2020-12-27 01:37:15,175:ERROR:{'message': 'Invalid Token', 'status': False}, exception = Not enough segments, status_code = 400
Traceback (most recent call last):
  File "C:\Users\TARUNVYDA\PycharmProjects\FundooNotes\venv\lib\site-packages\jwt\api_jws.py", line 180, in _load
    signing_input, crypto_segment = jwt.rsplit(b'.', 1)
ValueError: not enough values to unpack (expected 2, got 1)

During handling of the above exception, another exception occurred:

Traceback (most recent call last):
  File "C:\Users\TARUNVYDA\CloneProjects\FundooNotes\fundoo\fundooapp\decorator.py", line 16, in wrapper
    decoded_token = jwt.decode(token, config('ENCODE_SECRET_KEY'), algorithms=["HS256"])
  File "C:\Users\TARUNVYDA\PycharmProjects\FundooNotes\venv\lib\site-packages\jwt\api_jwt.py", line 84, in decode
    payload, _, _, _ = self._load(jwt)
  File "C:\Users\TARUNVYDA\PycharmProjects\FundooNotes\venv\lib\site-packages\jwt\api_jws.py", line 183, in _load
    raise DecodeError('Not enough segments')
jwt.exceptions.DecodeError: Not enough segments
2020-12-27 01:38:09,812:DEBUG:Using selector: SelectSelector
2020-12-27 01:48:15,168:DEBUG:{'token': 'eyJ0eXAiOiJKV1QiLCJhbGciOiJIUzI1NiJ9.eyJpZCI6MX0.-xXA0iKB4mVNvWLYFtt2xNiYkFpObF54J9lj2RwduAI'}
2020-12-27 01:48:15,169:DEBUG:{'status': True, 'message': {'token': 'eyJ0eXAiOiJKV1QiLCJhbGciOiJIUzI1NiJ9.eyJpZCI6MX0.-xXA0iKB4mVNvWLYFtt2xNiYkFpObF54J9lj2RwduAI'}}, status_code = 200
2020-12-27 01:48:33,927:DEBUG:{'message': 'token verification successful', 'status': True} status_code = 200
2020-12-27 01:48:34,004:DEBUG:{'status': True, 'message': {'id': 2, 'title': 'my testing note', 'description': 'this is my second note', 'created_time': '2020-12-21T14:22:19.826517Z', 'updated_time': '2020-12-21T14:22:19.826517Z', 'is_archived': False, 'is_deleted': False, 'color': '#00F0FF', 'image': None, 'trash': False, 'is_pinned': False, 'user': 3, 'label': [1], 'collaborate': [1]}}, status_code = 200
2020-12-27 01:48:41,024:DEBUG:Using selector: SelectSelector
2020-12-27 01:52:29,487:DEBUG:{'status': False, 'message': 'some other issue please try after some time'}, exception = Invalid input of type: 'NoneType'. Convert to a bytes, string, int or float first., status_code = 400
2020-12-27 01:52:29,489:WARNING:Bad Request: /login/
2020-12-27 01:52:50,185:INFO:C:\Users\TARUNVYDA\CloneProjects\FundooNotes\fundoo\services\encrypt.py changed, reloading.
2020-12-27 01:52:50,195:DEBUG:Using selector: SelectSelector
2020-12-27 01:52:56,169:DEBUG:{'status': False, 'message': 'some other issue please try after some time'}, exception = Invalid input of type: 'NoneType'. Convert to a bytes, string, int or float first., status_code = 400
2020-12-27 01:52:56,173:WARNING:Bad Request: /login/
2020-12-27 01:52:58,216:DEBUG:{'status': False, 'message': 'some other issue please try after some time'}, exception = Invalid input of type: 'NoneType'. Convert to a bytes, string, int or float first., status_code = 400
2020-12-27 01:52:58,217:WARNING:Bad Request: /login/
2020-12-27 01:53:35,277:INFO:C:\Users\TARUNVYDA\CloneProjects\FundooNotes\fundoo\services\encrypt.py changed, reloading.
2020-12-27 01:53:35,277:DEBUG:Using selector: SelectSelector
2020-12-27 01:53:48,850:DEBUG:{'token': 'eyJ0eXAiOiJKV1QiLCJhbGciOiJIUzI1NiJ9.eyJpZCI6MX0.-xXA0iKB4mVNvWLYFtt2xNiYkFpObF54J9lj2RwduAI'}
2020-12-27 01:53:48,851:DEBUG:{'status': True, 'message': {'token': 'eyJ0eXAiOiJKV1QiLCJhbGciOiJIUzI1NiJ9.eyJpZCI6MX0.-xXA0iKB4mVNvWLYFtt2xNiYkFpObF54J9lj2RwduAI'}}, status_code = 200
2020-12-27 01:53:57,794:DEBUG:{'message': 'token verification successful', 'status': True} status_code = 200
2020-12-27 01:53:57,818:DEBUG:{'status': True, 'message': {'id': 2, 'title': 'my testing note', 'description': 'this is my second note', 'created_time': '2020-12-21T14:22:19.826517Z', 'updated_time': '2020-12-21T14:22:19.826517Z', 'is_archived': False, 'is_deleted': False, 'color': '#00F0FF', 'image': None, 'trash': False, 'is_pinned': False, 'user': 3, 'label': [1], 'collaborate': [1]}}, status_code = 200
2020-12-27 01:54:04,084:DEBUG:Using selector: SelectSelector
2020-12-27 02:00:06,004:DEBUG:{'message': "logged in user's token is not provided", 'status': False} status_code = 400
2020-12-27 02:00:09,098:DEBUG:{'token': 'eyJ0eXAiOiJKV1QiLCJhbGciOiJIUzI1NiJ9.eyJpZCI6MX0.-xXA0iKB4mVNvWLYFtt2xNiYkFpObF54J9lj2RwduAI'}
2020-12-27 02:00:09,098:DEBUG:{'status': True, 'message': {'token': 'eyJ0eXAiOiJKV1QiLCJhbGciOiJIUzI1NiJ9.eyJpZCI6MX0.-xXA0iKB4mVNvWLYFtt2xNiYkFpObF54J9lj2RwduAI'}}, status_code = 200
2020-12-27 02:00:12,058:DEBUG:{'message': 'token verification successful', 'status': True} status_code = 200
2020-12-27 02:00:12,084:DEBUG:{'status': True, 'message': {'id': 2, 'title': 'my testing note', 'description': 'this is my second note', 'created_time': '2020-12-21T14:22:19.826517Z', 'updated_time': '2020-12-21T14:22:19.826517Z', 'is_archived': False, 'is_deleted': False, 'color': '#00F0FF', 'image': None, 'trash': False, 'is_pinned': False, 'user': 3, 'label': [1], 'collaborate': [1]}}, status_code = 200
2020-12-27 02:00:15,971:DEBUG:Using selector: SelectSelector
2020-12-27 02:07:17,692:DEBUG:{'status': False, 'message': 'some other issue please try after some time'}, exception = can only concatenate str (not "int") to str, status_code = 400
2020-12-27 02:07:17,694:WARNING:Bad Request: /login/
2020-12-27 02:08:40,429:INFO:C:\Users\TARUNVYDA\CloneProjects\FundooNotes\fundoo\fundooapp\views.py changed, reloading.
2020-12-27 02:08:40,429:DEBUG:Using selector: SelectSelector
2020-12-27 02:08:47,372:DEBUG:{'token': 'eyJ0eXAiOiJKV1QiLCJhbGciOiJIUzI1NiJ9.eyJpZCI6MX0.-xXA0iKB4mVNvWLYFtt2xNiYkFpObF54J9lj2RwduAI'}
2020-12-27 02:08:47,373:DEBUG:{'status': True, 'message': {'token': 'eyJ0eXAiOiJKV1QiLCJhbGciOiJIUzI1NiJ9.eyJpZCI6MX0.-xXA0iKB4mVNvWLYFtt2xNiYkFpObF54J9lj2RwduAI'}}, status_code = 200
2020-12-27 02:10:09,582:INFO:C:\Users\TARUNVYDA\CloneProjects\FundooNotes\fundoo\fundooapp\decorator.py changed, reloading.
2020-12-27 02:10:09,582:DEBUG:Using selector: SelectSelector
2020-12-27 02:10:15,847:DEBUG:{'token': 'eyJ0eXAiOiJKV1QiLCJhbGciOiJIUzI1NiJ9.eyJpZCI6MX0.-xXA0iKB4mVNvWLYFtt2xNiYkFpObF54J9lj2RwduAI'}
2020-12-27 02:10:15,848:DEBUG:{'status': True, 'message': {'token': 'eyJ0eXAiOiJKV1QiLCJhbGciOiJIUzI1NiJ9.eyJpZCI6MX0.-xXA0iKB4mVNvWLYFtt2xNiYkFpObF54J9lj2RwduAI'}}, status_code = 200
2020-12-27 02:10:18,139:ERROR:{'message': 'some other issue please try after some time', 'status': False} exception = can only concatenate str (not "int") to str, status_code = 400
Traceback (most recent call last):
  File "C:\Users\TARUNVYDA\CloneProjects\FundooNotes\fundoo\fundooapp\decorator.py", line 17, in wrapper
    if Cache.get_cache("TOKEN_"+decoded_token['id']+"_AUTH") is not None:
TypeError: can only concatenate str (not "int") to str
2020-12-27 02:10:19,926:ERROR:{'message': 'some other issue please try after some time', 'status': False} exception = can only concatenate str (not "int") to str, status_code = 400
Traceback (most recent call last):
  File "C:\Users\TARUNVYDA\CloneProjects\FundooNotes\fundoo\fundooapp\decorator.py", line 17, in wrapper
    if Cache.get_cache("TOKEN_"+decoded_token['id']+"_AUTH") is not None:
TypeError: can only concatenate str (not "int") to str
2020-12-27 02:10:52,404:INFO:C:\Users\TARUNVYDA\CloneProjects\FundooNotes\fundoo\fundooapp\decorator.py changed, reloading.
2020-12-27 02:10:52,404:DEBUG:Using selector: SelectSelector
2020-12-27 02:10:58,512:DEBUG:{'message': 'token verification successful', 'status': True} status_code = 200
2020-12-27 02:10:58,538:DEBUG:{'status': True, 'message': {'id': 2, 'title': 'my testing note', 'description': 'this is my second note', 'created_time': '2020-12-21T14:22:19.826517Z', 'updated_time': '2020-12-21T14:22:19.826517Z', 'is_archived': False, 'is_deleted': False, 'color': '#00F0FF', 'image': None, 'trash': False, 'is_pinned': False, 'user': 3, 'label': [1], 'collaborate': [1]}}, status_code = 200
2020-12-27 02:12:10,232:DEBUG:Using selector: SelectSelector
