2020-12-21 19:55:04,273:DEBUG:{'message': 'Note Added Successfully', 'status': True}
2020-12-21 19:55:55,410:DEBUG:{'message': 'Note Deleted Successfully', 'status': True}
2020-12-21 20:13:11,437:INFO:C:\Users\TARUNVYDA\PycharmProjects\FundooNotes\fundoo\notes\views.py changed, reloading.
2020-12-21 20:13:11,437:DEBUG:Using selector: SelectSelector
2020-12-21 20:15:43,358:DEBUG:{'message': 'Note Deleted Successfully', 'status': True}
2020-12-21 20:15:59,656:DEBUG:{'message': 'Note matching query does not exist.', 'status': False}
2020-12-21 20:15:59,657:WARNING:Bad Request: /note/3
2020-12-21 20:16:08,028:DEBUG:{'message': {'id': 2, 'title': 'my testing note', 'description': 'this is my second note', 'created_time': '2020-12-21T14:22:19.826517Z', 'updated_time': '2020-12-21T14:22:19.826517Z', 'is_archived': False, 'is_deleted': False, 'color': '#00F0FF', 'image': None, 'trash': False, 'is_pinned': False, 'user': 3, 'label': [1], 'collaborate': [1]}, 'status': True}
2020-12-21 20:16:14,415:DEBUG:{'message': 'Note matching query does not exist.', 'status': False}
2020-12-21 20:16:14,416:WARNING:Bad Request: /note/3
2020-12-21 20:18:30,601:INFO:C:\Users\TARUNVYDA\PycharmProjects\FundooNotes\fundoo\notes\views.py changed, reloading.
2020-12-21 20:18:30,602:DEBUG:Using selector: SelectSelector
2020-12-21 20:18:40,731:DEBUG:{'message': 'Note matching query does not exist.', 'status': False}
2020-12-21 20:18:40,734:WARNING:Not Found: /note/3
2020-12-21 20:21:43,641:INFO:C:\Users\TARUNVYDA\PycharmProjects\FundooNotes\fundoo\labels\views.py changed, reloading.
2020-12-21 20:21:43,642:DEBUG:Using selector: SelectSelector
2020-12-21 20:21:54,758:INFO:C:\Users\TARUNVYDA\PycharmProjects\FundooNotes\fundoo\labels\views.py changed, reloading.
2020-12-21 20:21:54,758:DEBUG:Using selector: SelectSelector
2020-12-21 20:21:59,881:INFO:C:\Users\TARUNVYDA\PycharmProjects\FundooNotes\fundoo\labels\views.py changed, reloading.
2020-12-21 20:21:59,881:DEBUG:Using selector: SelectSelector
2020-12-21 20:23:00,677:INFO:C:\Users\TARUNVYDA\PycharmProjects\FundooNotes\fundoo\labels\views.py changed, reloading.
2020-12-21 20:23:00,677:DEBUG:Using selector: SelectSelector
2020-12-21 20:23:08,479:DEBUG:{'message': 'Note matching query does not exist.', 'status': False}
2020-12-21 20:23:08,481:WARNING:Not Found: /note/3
2020-12-21 20:23:11,057:DEBUG:{'message': 'Note matching query does not exist.', 'status': False}
2020-12-21 20:23:11,058:WARNING:Not Found: /note/3
2020-12-21 20:29:14,208:DEBUG:{'message': 'Note matching query does not exist.', 'status': False}
2020-12-21 20:29:14,208:WARNING:Not Found: /note/5
2020-12-21 20:29:16,153:DEBUG:{'message': 'Note matching query does not exist.', 'status': False}
2020-12-21 20:29:16,154:WARNING:Not Found: /note/5
2020-12-21 20:29:20,203:DEBUG:{'message': 'Note matching query does not exist.', 'status': False}
2020-12-21 20:29:20,204:WARNING:Not Found: /note/3
2020-12-21 20:38:40,832:INFO:C:\Users\TARUNVYDA\PycharmProjects\FundooNotes\fundoo\labels\views.py changed, reloading.
2020-12-21 20:38:40,834:DEBUG:Using selector: SelectSelector
2020-12-21 20:38:46,788:DEBUG:{'message': 'Note matching query does not exist.', 'status': False}
2020-12-21 20:38:46,789:WARNING:Not Found: /note/3
2020-12-21 20:38:58,888:DEBUG:{'message': 'Note matching query does not exist.', 'status': False}
2020-12-21 20:38:58,889:WARNING:Not Found: /note/3
2020-12-21 20:39:03,387:DEBUG:{'message': 'Note matching query does not exist.', 'status': False}
2020-12-21 20:39:03,388:WARNING:Not Found: /note/3
2020-12-21 20:41:47,065:INFO:C:\Users\TARUNVYDA\PycharmProjects\FundooNotes\fundoo\labels\views.py changed, reloading.
2020-12-21 20:41:47,065:DEBUG:Using selector: SelectSelector
2020-12-21 20:41:59,821:DEBUG:{'message': 'Note matching query does not exist.', 'status': False}
2020-12-21 20:41:59,823:WARNING:Bad Request: /note/8
2020-12-21 20:42:29,843:INFO:C:\Users\TARUNVYDA\PycharmProjects\FundooNotes\fundoo\labels\views.py changed, reloading.
2020-12-21 20:42:29,843:DEBUG:Using selector: SelectSelector
2020-12-21 20:42:34,024:DEBUG:{'message': 'Note matching query does not exist.', 'status': False}
2020-12-21 20:42:34,026:WARNING:Bad Request: /note/8
2020-12-21 20:42:56,681:INFO:C:\Users\TARUNVYDA\PycharmProjects\FundooNotes\fundoo\labels\views.py changed, reloading.
2020-12-21 20:42:56,681:DEBUG:Using selector: SelectSelector
2020-12-21 20:43:26,613:WARNING:Not Found: /label/15
2020-12-21 20:47:44,027:INFO:C:\Users\TARUNVYDA\PycharmProjects\FundooNotes\fundoo\labels\views.py changed, reloading.
2020-12-21 20:47:44,027:DEBUG:Using selector: SelectSelector
2020-12-21 20:48:48,498:INFO:C:\Users\TARUNVYDA\PycharmProjects\FundooNotes\fundoo\labels\views.py changed, reloading.
2020-12-21 20:48:48,502:DEBUG:Using selector: SelectSelector
2020-12-21 20:51:18,803:DEBUG:{'message': 'please enter valid data', 'status': False}
2020-12-21 20:51:18,805:WARNING:Bad Request: /label/
2020-12-21 20:54:03,572:WARNING:Not Found: /label/
2020-12-21 20:54:04,169:WARNING:Not Found: /favicon.ico
2020-12-21 20:54:11,245:DEBUG:{'message': 'please enter valid data', 'status': False}
2020-12-21 20:54:11,299:WARNING:Bad Request: /label/
2020-12-21 20:55:08,401:INFO:C:\Users\TARUNVYDA\PycharmProjects\FundooNotes\fundoo\labels\views.py changed, reloading.
2020-12-21 20:55:08,401:DEBUG:Using selector: SelectSelector
2020-12-21 20:56:11,898:INFO:C:\Users\TARUNVYDA\PycharmProjects\FundooNotes\fundoo\labels\views.py changed, reloading.
2020-12-21 20:56:11,898:DEBUG:Using selector: SelectSelector
2020-12-21 20:56:20,955:DEBUG:{'message': 'please enter valid data', 'status': False}
2020-12-21 20:56:21,041:WARNING:Bad Request: /label/
2020-12-21 20:57:38,842:INFO:C:\Users\TARUNVYDA\PycharmProjects\FundooNotes\fundoo\labels\views.py changed, reloading.
2020-12-21 20:57:38,842:DEBUG:Using selector: SelectSelector
2020-12-21 20:57:45,501:DEBUG:{'message': 'please enter valid data', 'status': False}
2020-12-21 20:57:45,586:WARNING:Bad Request: /label/
2020-12-21 20:57:49,788:DEBUG:{'message': 'please enter valid data', 'status': False}
2020-12-21 20:57:49,915:WARNING:Bad Request: /label/
2020-12-21 20:58:46,070:INFO:C:\Users\TARUNVYDA\PycharmProjects\FundooNotes\fundoo\labels\views.py changed, reloading.
2020-12-21 20:58:46,070:DEBUG:Using selector: SelectSelector
2020-12-21 20:58:52,808:DEBUG:{'message': 'You cannot call `.save()` on a serializer with invalid data.', 'status': False}
2020-12-21 20:58:52,890:WARNING:Bad Request: /label/
2020-12-21 20:59:22,230:INFO:C:\Users\TARUNVYDA\PycharmProjects\FundooNotes\fundoo\labels\views.py changed, reloading.
2020-12-21 20:59:22,245:DEBUG:Using selector: SelectSelector
2020-12-21 20:59:29,090:DEBUG:{'message': 'Label Added Successfully', 'status': True}
2020-12-21 20:59:51,564:INFO:C:\Users\TARUNVYDA\PycharmProjects\FundooNotes\fundoo\labels\views.py changed, reloading.
2020-12-21 20:59:51,566:DEBUG:Using selector: SelectSelector
2020-12-21 21:03:38,051:INFO:C:\Users\TARUNVYDA\PycharmProjects\FundooNotes\fundoo\labels\views.py changed, reloading.
2020-12-21 21:03:38,053:DEBUG:Using selector: SelectSelector
2020-12-21 21:03:56,793:DEBUG:{'message': 'maximum length of label name should be 50 characters', 'status': False}
2020-12-21 21:03:56,881:WARNING:Bad Request: /label/
2020-12-21 21:04:21,792:INFO:C:\Users\TARUNVYDA\PycharmProjects\FundooNotes\fundoo\labels\views.py changed, reloading.
2020-12-21 21:04:21,792:DEBUG:Using selector: SelectSelector
2020-12-21 21:04:28,765:DEBUG:{'message': 'maximum length of label name should be 50 characters', 'status': False}
2020-12-21 21:04:28,850:WARNING:Bad Request: /label/
2020-12-21 21:05:12,461:INFO:C:\Users\TARUNVYDA\PycharmProjects\FundooNotes\fundoo\labels\views.py changed, reloading.
2020-12-21 21:05:12,462:DEBUG:Using selector: SelectSelector
2020-12-21 21:08:05,206:INFO:C:\Users\TARUNVYDA\PycharmProjects\FundooNotes\fundoo\labels\views.py changed, reloading.
2020-12-21 21:08:05,209:DEBUG:Using selector: SelectSelector
2020-12-21 21:13:36,790:INFO:C:\Users\TARUNVYDA\PycharmProjects\FundooNotes\fundoo\labels\views.py changed, reloading.
2020-12-21 21:13:36,792:DEBUG:Using selector: SelectSelector
2020-12-21 21:16:51,871:INFO:C:\Users\TARUNVYDA\PycharmProjects\FundooNotes\fundoo\labels\views.py changed, reloading.
2020-12-21 21:16:51,873:DEBUG:Using selector: SelectSelector
2020-12-21 21:21:18,431:INFO:C:\Users\TARUNVYDA\PycharmProjects\FundooNotes\fundoo\notes\views.py changed, reloading.
2020-12-21 21:21:18,432:DEBUG:Using selector: SelectSelector
2020-12-21 21:32:31,999:INFO:C:\Users\TARUNVYDA\PycharmProjects\FundooNotes\fundoo\notes\views.py changed, reloading.
2020-12-21 21:32:32,001:DEBUG:Using selector: SelectSelector
2020-12-21 21:33:04,838:ERROR:Internal Server Error: /note/3
Traceback (most recent call last):
  File "C:\Users\TARUNVYDA\PycharmProjects\FundooNotes\venv\lib\site-packages\django\core\handlers\exception.py", line 47, in inner
    response = get_response(request)
  File "C:\Users\TARUNVYDA\PycharmProjects\FundooNotes\venv\lib\site-packages\django\core\handlers\base.py", line 179, in _get_response
    response = wrapped_callback(request, *callback_args, **callback_kwargs)
  File "C:\Users\TARUNVYDA\PycharmProjects\FundooNotes\venv\lib\site-packages\django\views\decorators\csrf.py", line 54, in wrapped_view
    return view_func(*args, **kwargs)
  File "C:\Users\TARUNVYDA\PycharmProjects\FundooNotes\venv\lib\site-packages\django\views\generic\base.py", line 70, in view
    return self.dispatch(request, *args, **kwargs)
  File "C:\Users\TARUNVYDA\PycharmProjects\FundooNotes\venv\lib\site-packages\rest_framework\views.py", line 511, in dispatch
    self.response = self.finalize_response(request, response, *args, **kwargs)
  File "C:\Users\TARUNVYDA\PycharmProjects\FundooNotes\venv\lib\site-packages\rest_framework\views.py", line 426, in finalize_response
    % type(response)
AssertionError: Expected a `Response`, `HttpResponse` or `HttpStreamingResponse` to be returned from the view, but received a `<class 'NoneType'>`
2020-12-21 21:33:58,435:INFO:C:\Users\TARUNVYDA\PycharmProjects\FundooNotes\fundoo\notes\views.py changed, reloading.
2020-12-21 21:33:58,437:DEBUG:Using selector: SelectSelector
2020-12-21 21:34:04,138:WARNING:Bad Request: /note/3
2020-12-21 21:34:30,590:DEBUG:{'message': {'id': 1, 'title': 'my testing note', 'description': 'this is my second note', 'created_time': '2020-12-21T07:12:08.603603Z', 'updated_time': '2020-12-21T07:12:08.603603Z', 'is_archived': False, 'is_deleted': False, 'color': '#00F0FF', 'image': None, 'trash': False, 'is_pinned': False, 'user': 1, 'label': [1], 'collaborate': [3]}, 'status': True}
2020-12-21 21:35:19,506:DEBUG:{'message': 'Note Update Successfully', 'status': True}
2020-12-21 21:35:27,117:DEBUG:{'message': 'Note Update Successfully', 'status': True}
2020-12-21 21:36:18,336:DEBUG:{'message': 'Note Update Successfully', 'status': True}
2020-12-21 21:37:16,900:DEBUG:{'message': 'Note Update Successfully', 'status': True}
2020-12-21 21:38:08,096:INFO:C:\Users\TARUNVYDA\PycharmProjects\FundooNotes\fundoo\notes\views.py changed, reloading.
2020-12-21 21:38:08,098:DEBUG:Using selector: SelectSelector
2020-12-21 21:38:37,610:INFO:C:\Users\TARUNVYDA\PycharmProjects\FundooNotes\fundoo\notes\views.py changed, reloading.
2020-12-21 21:38:37,612:DEBUG:Using selector: SelectSelector
2020-12-21 21:41:54,701:INFO:C:\Users\TARUNVYDA\PycharmProjects\FundooNotes\fundoo\labels\views.py changed, reloading.
2020-12-21 21:41:54,704:DEBUG:Using selector: SelectSelector
2020-12-21 21:42:01,568:DEBUG:Using selector: SelectSelector
2020-12-21 22:09:29,176:DEBUG:{'message': {'id': 1, 'title': 'my put note11', 'description': 'this is my testing note for put', 'created_time': '2020-12-21T07:12:08.603603Z', 'updated_time': '2020-12-21T16:07:16.895819Z', 'is_archived': False, 'is_deleted': False, 'color': '#00F0FF', 'image': None, 'trash': False, 'is_pinned': False, 'user': 1, 'label': [1], 'collaborate': [3]}, 'status': True}
2020-12-21 22:11:07,885:DEBUG:{'message': 'please enter valid data', 'status': False}
2020-12-21 22:11:07,886:WARNING:Bad Request: /note/
2020-12-21 22:13:21,190:INFO:C:\Users\TARUNVYDA\PycharmProjects\FundooNotes\fundoo\notes\views.py changed, reloading.
2020-12-21 22:13:21,192:DEBUG:Using selector: SelectSelector
2020-12-21 22:13:27,448:DEBUG:{'message': 'title should be less than 150 characters', 'status': False}
2020-12-21 22:13:27,450:WARNING:Bad Request: /note/
2020-12-21 22:15:38,828:INFO:C:\Users\TARUNVYDA\PycharmProjects\FundooNotes\fundoo\notes\utils.py changed, reloading.
2020-12-21 22:15:38,829:DEBUG:Using selector: SelectSelector
2020-12-21 22:15:42,372:DEBUG:{'message': "'Account' object has no attribute 'exists'", 'status': False}
2020-12-21 22:15:42,374:WARNING:Bad Request: /note/
2020-12-21 22:16:35,172:INFO:C:\Users\TARUNVYDA\PycharmProjects\FundooNotes\fundoo\notes\utils.py changed, reloading.
2020-12-21 22:16:35,174:DEBUG:Using selector: SelectSelector
2020-12-21 22:16:40,083:DEBUG:{'message': 'Note Added Successfully', 'status': True}
2020-12-21 22:17:02,237:INFO:C:\Users\TARUNVYDA\PycharmProjects\FundooNotes\fundoo\notes\utils.py changed, reloading.
2020-12-21 22:17:02,238:DEBUG:Using selector: SelectSelector
2020-12-21 22:17:08,325:INFO:C:\Users\TARUNVYDA\PycharmProjects\FundooNotes\fundoo\notes\utils.py changed, reloading.
2020-12-21 22:17:08,326:DEBUG:Using selector: SelectSelector
2020-12-21 22:17:14,941:DEBUG:{'message': 'Note Added Successfully', 'status': True}
2020-12-21 22:18:39,930:INFO:C:\Users\TARUNVYDA\PycharmProjects\FundooNotes\fundoo\notes\utils.py changed, reloading.
2020-12-21 22:18:39,931:DEBUG:Using selector: SelectSelector
2020-12-21 22:20:56,048:DEBUG:{'message': 'Note Added Successfully', 'status': True}
2020-12-21 22:22:30,043:DEBUG:{'message': {'user': 1, 'label_name': 'adsf'}, 'status': True}
2020-12-21 22:23:02,997:DEBUG:Using selector: SelectSelector
2020-12-24 11:47:18,942:INFO:C:\Users\TARUNVYDA\CloneProjects\FundooNotes\fundoo\notes\views.py changed, reloading.
2020-12-24 11:47:18,962:DEBUG:Using selector: SelectSelector
2020-12-24 11:47:25,440:WARNING:Unauthorized: /note/2
2020-12-24 11:47:38,414:DEBUG:Using selector: SelectSelector
2020-12-24 12:40:10,152:DEBUG:Using selector: SelectSelector
2020-12-24 13:39:23,003:DEBUG:{'message': {'id': 2, 'title': 'my testing note', 'description': 'this is my second note', 'created_time': '2020-12-21T14:22:19.826517Z', 'updated_time': '2020-12-21T14:22:19.826517Z', 'is_archived': False, 'is_deleted': False, 'color': '#00F0FF', 'image': None, 'trash': False, 'is_pinned': False, 'user': 3, 'label': [1], 'collaborate': [1]}, 'status': True}
2020-12-24 13:43:47,088:INFO:C:\Users\TARUNVYDA\CloneProjects\FundooNotes\fundoo\fundooapp\decorator.py changed, reloading.
2020-12-24 13:43:47,089:DEBUG:Using selector: SelectSelector
2020-12-24 13:47:40,370:INFO:C:\Users\TARUNVYDA\CloneProjects\FundooNotes\fundoo\fundooapp\decorator.py changed, reloading.
2020-12-24 13:47:40,370:DEBUG:Using selector: SelectSelector
2020-12-24 13:47:45,144:DEBUG:{'message': {'id': 2, 'title': 'my testing note', 'description': 'this is my second note', 'created_time': '2020-12-21T14:22:19.826517Z', 'updated_time': '2020-12-21T14:22:19.826517Z', 'is_archived': False, 'is_deleted': False, 'color': '#00F0FF', 'image': None, 'trash': False, 'is_pinned': False, 'user': 3, 'label': [1], 'collaborate': [1]}, 'status': True}
2020-12-24 13:47:49,703:DEBUG:Using selector: SelectSelector
2020-12-24 15:10:49,412:DEBUG:Using selector: SelectSelector
2020-12-24 15:11:43,165:DEBUG:{'message': {'id': 2, 'title': 'my testing note', 'description': 'this is my second note', 'created_time': '2020-12-21T14:22:19.826517Z', 'updated_time': '2020-12-21T14:22:19.826517Z', 'is_archived': False, 'is_deleted': False, 'color': '#00F0FF', 'image': None, 'trash': False, 'is_pinned': False, 'user': 3, 'label': [1], 'collaborate': [1]}, 'status': True}
2020-12-24 15:11:53,114:WARNING:Bad Request: /note/
2020-12-24 15:12:04,931:DEBUG:{'message': {'id': 2, 'title': 'my testing note', 'description': 'this is my second note', 'created_time': '2020-12-21T14:22:19.826517Z', 'updated_time': '2020-12-21T14:22:19.826517Z', 'is_archived': False, 'is_deleted': False, 'color': '#00F0FF', 'image': None, 'trash': False, 'is_pinned': False, 'user': 3, 'label': [1], 'collaborate': [1]}, 'status': True}
2020-12-24 15:12:15,642:DEBUG:{'message': {'user': 1, 'label_name': 'mmm'}, 'status': True}
2020-12-24 15:12:28,086:DEBUG:{'message': {'user': 1, 'label_name': 'mmm'}, 'status': True}
2020-12-24 15:13:01,586:DEBUG:Using selector: SelectSelector
2020-12-24 15:13:22,809:DEBUG:{'message': {'id': 2, 'title': 'my testing note', 'description': 'this is my second note', 'created_time': '2020-12-21T14:22:19.826517Z', 'updated_time': '2020-12-21T14:22:19.826517Z', 'is_archived': False, 'is_deleted': False, 'color': '#00F0FF', 'image': None, 'trash': False, 'is_pinned': False, 'user': 3, 'label': [1], 'collaborate': [1]}, 'status': True}
2020-12-24 15:13:27,810:ERROR:Internal Server Error: /note/2
Traceback (most recent call last):
  File "C:\Users\TARUNVYDA\PycharmProjects\FundooNotes\venv\lib\site-packages\jwt\api_jws.py", line 180, in _load
    signing_input, crypto_segment = jwt.rsplit(b'.', 1)
ValueError: not enough values to unpack (expected 2, got 1)

During handling of the above exception, another exception occurred:

Traceback (most recent call last):
  File "C:\Users\TARUNVYDA\PycharmProjects\FundooNotes\venv\lib\site-packages\django\core\handlers\exception.py", line 47, in inner
    response = get_response(request)
  File "C:\Users\TARUNVYDA\PycharmProjects\FundooNotes\venv\lib\site-packages\django\core\handlers\base.py", line 179, in _get_response
    response = wrapped_callback(request, *callback_args, **callback_kwargs)
  File "C:\Users\TARUNVYDA\PycharmProjects\FundooNotes\venv\lib\site-packages\django\views\decorators\csrf.py", line 54, in wrapped_view
    return view_func(*args, **kwargs)
  File "C:\Users\TARUNVYDA\PycharmProjects\FundooNotes\venv\lib\site-packages\django\views\generic\base.py", line 70, in view
    return self.dispatch(request, *args, **kwargs)
  File "C:\Users\TARUNVYDA\PycharmProjects\FundooNotes\venv\lib\site-packages\django\utils\decorators.py", line 43, in _wrapper
    return bound_method(*args, **kwargs)
  File "C:\Users\TARUNVYDA\CloneProjects\FundooNotes\fundoo\fundooapp\decorator.py", line 14, in wrapper
    decoded_token = jwt.decode(token, "secret", algorithms=["HS256"])
  File "C:\Users\TARUNVYDA\PycharmProjects\FundooNotes\venv\lib\site-packages\jwt\api_jwt.py", line 84, in decode
    payload, _, _, _ = self._load(jwt)
  File "C:\Users\TARUNVYDA\PycharmProjects\FundooNotes\venv\lib\site-packages\jwt\api_jws.py", line 183, in _load
    raise DecodeError('Not enough segments')
jwt.exceptions.DecodeError: Not enough segments
2020-12-24 15:13:32,076:DEBUG:{'message': {'id': 2, 'title': 'my testing note', 'description': 'this is my second note', 'created_time': '2020-12-21T14:22:19.826517Z', 'updated_time': '2020-12-21T14:22:19.826517Z', 'is_archived': False, 'is_deleted': False, 'color': '#00F0FF', 'image': None, 'trash': False, 'is_pinned': False, 'user': 3, 'label': [1], 'collaborate': [1]}, 'status': True}
2020-12-24 15:13:36,137:DEBUG:Using selector: SelectSelector
2020-12-24 15:16:52,239:ERROR:Internal Server Error: /note/2
Traceback (most recent call last):
  File "C:\Users\TARUNVYDA\CloneProjects\FundooNotes\fundoo\notes\views.py", line 76, in get
    result = utils.manage_response(status=True, message=serializer.data)
AttributeError: module 'notes.utils' has no attribute 'manage_response'

During handling of the above exception, another exception occurred:

Traceback (most recent call last):
  File "C:\Users\TARUNVYDA\PycharmProjects\FundooNotes\venv\lib\site-packages\django\core\handlers\exception.py", line 47, in inner
    response = get_response(request)
  File "C:\Users\TARUNVYDA\PycharmProjects\FundooNotes\venv\lib\site-packages\django\core\handlers\base.py", line 179, in _get_response
    response = wrapped_callback(request, *callback_args, **callback_kwargs)
  File "C:\Users\TARUNVYDA\PycharmProjects\FundooNotes\venv\lib\site-packages\django\views\decorators\csrf.py", line 54, in wrapped_view
    return view_func(*args, **kwargs)
  File "C:\Users\TARUNVYDA\PycharmProjects\FundooNotes\venv\lib\site-packages\django\views\generic\base.py", line 70, in view
    return self.dispatch(request, *args, **kwargs)
  File "C:\Users\TARUNVYDA\PycharmProjects\FundooNotes\venv\lib\site-packages\django\utils\decorators.py", line 43, in _wrapper
    return bound_method(*args, **kwargs)
  File "C:\Users\TARUNVYDA\CloneProjects\FundooNotes\fundoo\fundooapp\decorator.py", line 21, in wrapper
    return view_func(request, *args, **kwargs)
  File "C:\Users\TARUNVYDA\PycharmProjects\FundooNotes\venv\lib\site-packages\rest_framework\views.py", line 509, in dispatch
    response = self.handle_exception(exc)
  File "C:\Users\TARUNVYDA\PycharmProjects\FundooNotes\venv\lib\site-packages\rest_framework\views.py", line 469, in handle_exception
    self.raise_uncaught_exception(exc)
  File "C:\Users\TARUNVYDA\PycharmProjects\FundooNotes\venv\lib\site-packages\rest_framework\views.py", line 480, in raise_uncaught_exception
    raise exc
  File "C:\Users\TARUNVYDA\PycharmProjects\FundooNotes\venv\lib\site-packages\rest_framework\views.py", line 506, in dispatch
    response = handler(request, *args, **kwargs)
  File "C:\Users\TARUNVYDA\CloneProjects\FundooNotes\fundoo\notes\views.py", line 84, in get
    result = utils.manage_response(status=False, message='some other issue please try after some time')
AttributeError: module 'notes.utils' has no attribute 'manage_response'
2020-12-24 15:16:54,630:ERROR:Internal Server Error: /note/2
Traceback (most recent call last):
  File "C:\Users\TARUNVYDA\CloneProjects\FundooNotes\fundoo\notes\views.py", line 76, in get
    result = utils.manage_response(status=True, message=serializer.data)
AttributeError: module 'notes.utils' has no attribute 'manage_response'

During handling of the above exception, another exception occurred:

Traceback (most recent call last):
  File "C:\Users\TARUNVYDA\PycharmProjects\FundooNotes\venv\lib\site-packages\django\core\handlers\exception.py", line 47, in inner
    response = get_response(request)
  File "C:\Users\TARUNVYDA\PycharmProjects\FundooNotes\venv\lib\site-packages\django\core\handlers\base.py", line 179, in _get_response
    response = wrapped_callback(request, *callback_args, **callback_kwargs)
  File "C:\Users\TARUNVYDA\PycharmProjects\FundooNotes\venv\lib\site-packages\django\views\decorators\csrf.py", line 54, in wrapped_view
    return view_func(*args, **kwargs)
  File "C:\Users\TARUNVYDA\PycharmProjects\FundooNotes\venv\lib\site-packages\django\views\generic\base.py", line 70, in view
    return self.dispatch(request, *args, **kwargs)
  File "C:\Users\TARUNVYDA\PycharmProjects\FundooNotes\venv\lib\site-packages\django\utils\decorators.py", line 43, in _wrapper
    return bound_method(*args, **kwargs)
  File "C:\Users\TARUNVYDA\CloneProjects\FundooNotes\fundoo\fundooapp\decorator.py", line 21, in wrapper
    return view_func(request, *args, **kwargs)
  File "C:\Users\TARUNVYDA\PycharmProjects\FundooNotes\venv\lib\site-packages\rest_framework\views.py", line 509, in dispatch
    response = self.handle_exception(exc)
  File "C:\Users\TARUNVYDA\PycharmProjects\FundooNotes\venv\lib\site-packages\rest_framework\views.py", line 469, in handle_exception
    self.raise_uncaught_exception(exc)
  File "C:\Users\TARUNVYDA\PycharmProjects\FundooNotes\venv\lib\site-packages\rest_framework\views.py", line 480, in raise_uncaught_exception
    raise exc
  File "C:\Users\TARUNVYDA\PycharmProjects\FundooNotes\venv\lib\site-packages\rest_framework\views.py", line 506, in dispatch
    response = handler(request, *args, **kwargs)
  File "C:\Users\TARUNVYDA\CloneProjects\FundooNotes\fundoo\notes\views.py", line 84, in get
    result = utils.manage_response(status=False, message='some other issue please try after some time')
AttributeError: module 'notes.utils' has no attribute 'manage_response'
2020-12-24 15:17:00,400:ERROR:Internal Server Error: /note/2
Traceback (most recent call last):
  File "C:\Users\TARUNVYDA\CloneProjects\FundooNotes\fundoo\notes\views.py", line 76, in get
    result = utils.manage_response(status=True, message=serializer.data)
AttributeError: module 'notes.utils' has no attribute 'manage_response'

During handling of the above exception, another exception occurred:

Traceback (most recent call last):
  File "C:\Users\TARUNVYDA\PycharmProjects\FundooNotes\venv\lib\site-packages\django\core\handlers\exception.py", line 47, in inner
    response = get_response(request)
  File "C:\Users\TARUNVYDA\PycharmProjects\FundooNotes\venv\lib\site-packages\django\core\handlers\base.py", line 179, in _get_response
    response = wrapped_callback(request, *callback_args, **callback_kwargs)
  File "C:\Users\TARUNVYDA\PycharmProjects\FundooNotes\venv\lib\site-packages\django\views\decorators\csrf.py", line 54, in wrapped_view
    return view_func(*args, **kwargs)
  File "C:\Users\TARUNVYDA\PycharmProjects\FundooNotes\venv\lib\site-packages\django\views\generic\base.py", line 70, in view
    return self.dispatch(request, *args, **kwargs)
  File "C:\Users\TARUNVYDA\PycharmProjects\FundooNotes\venv\lib\site-packages\django\utils\decorators.py", line 43, in _wrapper
    return bound_method(*args, **kwargs)
  File "C:\Users\TARUNVYDA\CloneProjects\FundooNotes\fundoo\fundooapp\decorator.py", line 21, in wrapper
    return view_func(request, *args, **kwargs)
  File "C:\Users\TARUNVYDA\PycharmProjects\FundooNotes\venv\lib\site-packages\rest_framework\views.py", line 509, in dispatch
    response = self.handle_exception(exc)
  File "C:\Users\TARUNVYDA\PycharmProjects\FundooNotes\venv\lib\site-packages\rest_framework\views.py", line 469, in handle_exception
    self.raise_uncaught_exception(exc)
  File "C:\Users\TARUNVYDA\PycharmProjects\FundooNotes\venv\lib\site-packages\rest_framework\views.py", line 480, in raise_uncaught_exception
    raise exc
  File "C:\Users\TARUNVYDA\PycharmProjects\FundooNotes\venv\lib\site-packages\rest_framework\views.py", line 506, in dispatch
    response = handler(request, *args, **kwargs)
  File "C:\Users\TARUNVYDA\CloneProjects\FundooNotes\fundoo\notes\views.py", line 84, in get
    result = utils.manage_response(status=False, message='some other issue please try after some time')
AttributeError: module 'notes.utils' has no attribute 'manage_response'
2020-12-24 15:17:38,660:INFO:C:\Users\TARUNVYDA\CloneProjects\FundooNotes\fundoo\notes\utils.py changed, reloading.
2020-12-24 15:17:38,660:DEBUG:Using selector: SelectSelector
2020-12-24 15:17:43,755:DEBUG:{'status': True, 'message': {'id': 2, 'title': 'my testing note', 'description': 'this is my second note', 'created_time': '2020-12-21T14:22:19.826517Z', 'updated_time': '2020-12-21T14:22:19.826517Z', 'is_archived': False, 'is_deleted': False, 'color': '#00F0FF', 'image': None, 'trash': False, 'is_pinned': False, 'user': 3, 'label': [1], 'collaborate': [1]}}
2020-12-24 15:17:49,755:DEBUG:Using selector: SelectSelector
2020-12-24 15:19:11,866:DEBUG:{'status': True, 'message': {'user': 1, 'label_name': 'mmm'}}
2020-12-24 15:19:16,577:ERROR:Internal Server Error: /label/2
Traceback (most recent call last):
  File "C:\Users\TARUNVYDA\PycharmProjects\FundooNotes\venv\lib\site-packages\jwt\api_jws.py", line 180, in _load
    signing_input, crypto_segment = jwt.rsplit(b'.', 1)
ValueError: not enough values to unpack (expected 2, got 1)

During handling of the above exception, another exception occurred:

Traceback (most recent call last):
  File "C:\Users\TARUNVYDA\PycharmProjects\FundooNotes\venv\lib\site-packages\django\core\handlers\exception.py", line 47, in inner
    response = get_response(request)
  File "C:\Users\TARUNVYDA\PycharmProjects\FundooNotes\venv\lib\site-packages\django\core\handlers\base.py", line 179, in _get_response
    response = wrapped_callback(request, *callback_args, **callback_kwargs)
  File "C:\Users\TARUNVYDA\PycharmProjects\FundooNotes\venv\lib\site-packages\django\views\decorators\csrf.py", line 54, in wrapped_view
    return view_func(*args, **kwargs)
  File "C:\Users\TARUNVYDA\PycharmProjects\FundooNotes\venv\lib\site-packages\django\views\generic\base.py", line 70, in view
    return self.dispatch(request, *args, **kwargs)
  File "C:\Users\TARUNVYDA\PycharmProjects\FundooNotes\venv\lib\site-packages\django\utils\decorators.py", line 43, in _wrapper
    return bound_method(*args, **kwargs)
  File "C:\Users\TARUNVYDA\CloneProjects\FundooNotes\fundoo\fundooapp\decorator.py", line 14, in wrapper
    decoded_token = jwt.decode(token, "secret", algorithms=["HS256"])
  File "C:\Users\TARUNVYDA\PycharmProjects\FundooNotes\venv\lib\site-packages\jwt\api_jwt.py", line 84, in decode
    payload, _, _, _ = self._load(jwt)
  File "C:\Users\TARUNVYDA\PycharmProjects\FundooNotes\venv\lib\site-packages\jwt\api_jws.py", line 183, in _load
    raise DecodeError('Not enough segments')
jwt.exceptions.DecodeError: Not enough segments
2020-12-24 15:19:18,763:ERROR:Internal Server Error: /label/2
Traceback (most recent call last):
  File "C:\Users\TARUNVYDA\PycharmProjects\FundooNotes\venv\lib\site-packages\jwt\api_jws.py", line 180, in _load
    signing_input, crypto_segment = jwt.rsplit(b'.', 1)
ValueError: not enough values to unpack (expected 2, got 1)

During handling of the above exception, another exception occurred:

Traceback (most recent call last):
  File "C:\Users\TARUNVYDA\PycharmProjects\FundooNotes\venv\lib\site-packages\django\core\handlers\exception.py", line 47, in inner
    response = get_response(request)
  File "C:\Users\TARUNVYDA\PycharmProjects\FundooNotes\venv\lib\site-packages\django\core\handlers\base.py", line 179, in _get_response
    response = wrapped_callback(request, *callback_args, **callback_kwargs)
  File "C:\Users\TARUNVYDA\PycharmProjects\FundooNotes\venv\lib\site-packages\django\views\decorators\csrf.py", line 54, in wrapped_view
    return view_func(*args, **kwargs)
  File "C:\Users\TARUNVYDA\PycharmProjects\FundooNotes\venv\lib\site-packages\django\views\generic\base.py", line 70, in view
    return self.dispatch(request, *args, **kwargs)
  File "C:\Users\TARUNVYDA\PycharmProjects\FundooNotes\venv\lib\site-packages\django\utils\decorators.py", line 43, in _wrapper
    return bound_method(*args, **kwargs)
  File "C:\Users\TARUNVYDA\CloneProjects\FundooNotes\fundoo\fundooapp\decorator.py", line 14, in wrapper
    decoded_token = jwt.decode(token, "secret", algorithms=["HS256"])
  File "C:\Users\TARUNVYDA\PycharmProjects\FundooNotes\venv\lib\site-packages\jwt\api_jwt.py", line 84, in decode
    payload, _, _, _ = self._load(jwt)
  File "C:\Users\TARUNVYDA\PycharmProjects\FundooNotes\venv\lib\site-packages\jwt\api_jws.py", line 183, in _load
    raise DecodeError('Not enough segments')
jwt.exceptions.DecodeError: Not enough segments
2020-12-24 15:19:34,154:DEBUG:{'status': True, 'message': {'user': 1, 'label_name': 'mmm'}}
2020-12-24 15:19:45,432:DEBUG:Using selector: SelectSelector
2020-12-24 15:23:01,404:WARNING:Not Found: /notes/2
2020-12-24 15:23:08,651:DEBUG:{'status': True, 'message': {'id': 2, 'title': 'my testing note', 'description': 'this is my second note', 'created_time': '2020-12-21T14:22:19.826517Z', 'updated_time': '2020-12-21T14:22:19.826517Z', 'is_archived': False, 'is_deleted': False, 'color': '#00F0FF', 'image': None, 'trash': False, 'is_pinned': False, 'user': 3, 'label': [1], 'collaborate': [1]}}
2020-12-24 15:23:18,918:DEBUG:Using selector: SelectSelector
2020-12-24 15:33:07,624:WARNING:Method Not Allowed: /login/
2020-12-24 15:34:02,156:DEBUG:{'email': 'viratkohli123@gmail.com', 'user_name': 'viratkohli'}
2020-12-24 15:34:06,065:DEBUG:Using selector: SelectSelector
2020-12-24 15:42:35,319:DEBUG:{'email': 'viratkohli123@gmail.com'}
2020-12-24 15:43:07,874:DEBUG:Using selector: SelectSelector
2020-12-24 15:46:31,890:ERROR:Internal Server Error: /login/
Traceback (most recent call last):
  File "C:\Users\TARUNVYDA\PycharmProjects\FundooNotes\venv\lib\site-packages\django\core\handlers\exception.py", line 47, in inner
    response = get_response(request)
  File "C:\Users\TARUNVYDA\PycharmProjects\FundooNotes\venv\lib\site-packages\django\core\handlers\base.py", line 179, in _get_response
    response = wrapped_callback(request, *callback_args, **callback_kwargs)
  File "C:\Users\TARUNVYDA\PycharmProjects\FundooNotes\venv\lib\site-packages\django\views\decorators\csrf.py", line 54, in wrapped_view
    return view_func(*args, **kwargs)
  File "C:\Users\TARUNVYDA\PycharmProjects\FundooNotes\venv\lib\site-packages\django\views\generic\base.py", line 70, in view
    return self.dispatch(request, *args, **kwargs)
  File "C:\Users\TARUNVYDA\PycharmProjects\FundooNotes\venv\lib\site-packages\rest_framework\views.py", line 509, in dispatch
    response = self.handle_exception(exc)
  File "C:\Users\TARUNVYDA\PycharmProjects\FundooNotes\venv\lib\site-packages\rest_framework\views.py", line 469, in handle_exception
    self.raise_uncaught_exception(exc)
  File "C:\Users\TARUNVYDA\PycharmProjects\FundooNotes\venv\lib\site-packages\rest_framework\views.py", line 480, in raise_uncaught_exception
    raise exc
  File "C:\Users\TARUNVYDA\PycharmProjects\FundooNotes\venv\lib\site-packages\rest_framework\views.py", line 506, in dispatch
    response = handler(request, *args, **kwargs)
  File "C:\Users\TARUNVYDA\CloneProjects\FundooNotes\fundoo\fundooapp\views.py", line 37, in post
    serializer.is_valid(raise_exception=True)
  File "C:\Users\TARUNVYDA\PycharmProjects\FundooNotes\venv\lib\site-packages\rest_framework\serializers.py", line 220, in is_valid
    self._validated_data = self.run_validation(self.initial_data)
  File "C:\Users\TARUNVYDA\PycharmProjects\FundooNotes\venv\lib\site-packages\rest_framework\serializers.py", line 419, in run_validation
    value = self.to_internal_value(data)
  File "C:\Users\TARUNVYDA\PycharmProjects\FundooNotes\venv\lib\site-packages\rest_framework\serializers.py", line 472, in to_internal_value
    for field in fields:
  File "C:\Users\TARUNVYDA\PycharmProjects\FundooNotes\venv\lib\site-packages\rest_framework\serializers.py", line 355, in _writable_fields
    for field in self.fields.values():
  File "C:\Users\TARUNVYDA\PycharmProjects\FundooNotes\venv\lib\site-packages\django\utils\functional.py", line 48, in __get__
    res = instance.__dict__[self.name] = self.func(instance)
  File "C:\Users\TARUNVYDA\PycharmProjects\FundooNotes\venv\lib\site-packages\rest_framework\serializers.py", line 349, in fields
    for key, value in self.get_fields().items():
  File "C:\Users\TARUNVYDA\PycharmProjects\FundooNotes\venv\lib\site-packages\rest_framework\serializers.py", line 1029, in get_fields
    field_names = self.get_field_names(declared_fields, info)
  File "C:\Users\TARUNVYDA\PycharmProjects\FundooNotes\venv\lib\site-packages\rest_framework\serializers.py", line 1130, in get_field_names
    serializer_class=self.__class__.__name__
AssertionError: The field 'token' was declared on serializer LoginSerializer, but has not been included in the 'fields' option.
2020-12-24 15:47:50,451:ERROR:Internal Server Error: /login/
Traceback (most recent call last):
  File "C:\Users\TARUNVYDA\PycharmProjects\FundooNotes\venv\lib\site-packages\django\core\handlers\exception.py", line 47, in inner
    response = get_response(request)
  File "C:\Users\TARUNVYDA\PycharmProjects\FundooNotes\venv\lib\site-packages\django\core\handlers\base.py", line 179, in _get_response
    response = wrapped_callback(request, *callback_args, **callback_kwargs)
  File "C:\Users\TARUNVYDA\PycharmProjects\FundooNotes\venv\lib\site-packages\django\views\decorators\csrf.py", line 54, in wrapped_view
    return view_func(*args, **kwargs)
  File "C:\Users\TARUNVYDA\PycharmProjects\FundooNotes\venv\lib\site-packages\django\views\generic\base.py", line 70, in view
    return self.dispatch(request, *args, **kwargs)
  File "C:\Users\TARUNVYDA\PycharmProjects\FundooNotes\venv\lib\site-packages\rest_framework\views.py", line 509, in dispatch
    response = self.handle_exception(exc)
  File "C:\Users\TARUNVYDA\PycharmProjects\FundooNotes\venv\lib\site-packages\rest_framework\views.py", line 469, in handle_exception
    self.raise_uncaught_exception(exc)
  File "C:\Users\TARUNVYDA\PycharmProjects\FundooNotes\venv\lib\site-packages\rest_framework\views.py", line 480, in raise_uncaught_exception
    raise exc
  File "C:\Users\TARUNVYDA\PycharmProjects\FundooNotes\venv\lib\site-packages\rest_framework\views.py", line 506, in dispatch
    response = handler(request, *args, **kwargs)
  File "C:\Users\TARUNVYDA\CloneProjects\FundooNotes\fundoo\fundooapp\views.py", line 37, in post
    serializer.is_valid(raise_exception=True)
  File "C:\Users\TARUNVYDA\PycharmProjects\FundooNotes\venv\lib\site-packages\rest_framework\serializers.py", line 220, in is_valid
    self._validated_data = self.run_validation(self.initial_data)
  File "C:\Users\TARUNVYDA\PycharmProjects\FundooNotes\venv\lib\site-packages\rest_framework\serializers.py", line 419, in run_validation
    value = self.to_internal_value(data)
  File "C:\Users\TARUNVYDA\PycharmProjects\FundooNotes\venv\lib\site-packages\rest_framework\serializers.py", line 472, in to_internal_value
    for field in fields:
  File "C:\Users\TARUNVYDA\PycharmProjects\FundooNotes\venv\lib\site-packages\rest_framework\serializers.py", line 355, in _writable_fields
    for field in self.fields.values():
  File "C:\Users\TARUNVYDA\PycharmProjects\FundooNotes\venv\lib\site-packages\django\utils\functional.py", line 48, in __get__
    res = instance.__dict__[self.name] = self.func(instance)
  File "C:\Users\TARUNVYDA\PycharmProjects\FundooNotes\venv\lib\site-packages\rest_framework\serializers.py", line 349, in fields
    for key, value in self.get_fields().items():
  File "C:\Users\TARUNVYDA\PycharmProjects\FundooNotes\venv\lib\site-packages\rest_framework\serializers.py", line 1029, in get_fields
    field_names = self.get_field_names(declared_fields, info)
  File "C:\Users\TARUNVYDA\PycharmProjects\FundooNotes\venv\lib\site-packages\rest_framework\serializers.py", line 1130, in get_field_names
    serializer_class=self.__class__.__name__
AssertionError: The field 'token' was declared on serializer LoginSerializer, but has not been included in the 'fields' option.
2020-12-24 15:48:50,895:ERROR:Internal Server Error: /login/
Traceback (most recent call last):
  File "C:\Users\TARUNVYDA\PycharmProjects\FundooNotes\venv\lib\site-packages\django\core\handlers\exception.py", line 47, in inner
    response = get_response(request)
  File "C:\Users\TARUNVYDA\PycharmProjects\FundooNotes\venv\lib\site-packages\django\core\handlers\base.py", line 179, in _get_response
    response = wrapped_callback(request, *callback_args, **callback_kwargs)
  File "C:\Users\TARUNVYDA\PycharmProjects\FundooNotes\venv\lib\site-packages\django\views\decorators\csrf.py", line 54, in wrapped_view
    return view_func(*args, **kwargs)
  File "C:\Users\TARUNVYDA\PycharmProjects\FundooNotes\venv\lib\site-packages\django\views\generic\base.py", line 70, in view
    return self.dispatch(request, *args, **kwargs)
  File "C:\Users\TARUNVYDA\PycharmProjects\FundooNotes\venv\lib\site-packages\rest_framework\views.py", line 509, in dispatch
    response = self.handle_exception(exc)
  File "C:\Users\TARUNVYDA\PycharmProjects\FundooNotes\venv\lib\site-packages\rest_framework\views.py", line 469, in handle_exception
    self.raise_uncaught_exception(exc)
  File "C:\Users\TARUNVYDA\PycharmProjects\FundooNotes\venv\lib\site-packages\rest_framework\views.py", line 480, in raise_uncaught_exception
    raise exc
  File "C:\Users\TARUNVYDA\PycharmProjects\FundooNotes\venv\lib\site-packages\rest_framework\views.py", line 506, in dispatch
    response = handler(request, *args, **kwargs)
  File "C:\Users\TARUNVYDA\CloneProjects\FundooNotes\fundoo\fundooapp\views.py", line 37, in post
    serializer.is_valid(raise_exception=True)
  File "C:\Users\TARUNVYDA\PycharmProjects\FundooNotes\venv\lib\site-packages\rest_framework\serializers.py", line 220, in is_valid
    self._validated_data = self.run_validation(self.initial_data)
  File "C:\Users\TARUNVYDA\PycharmProjects\FundooNotes\venv\lib\site-packages\rest_framework\serializers.py", line 419, in run_validation
    value = self.to_internal_value(data)
  File "C:\Users\TARUNVYDA\PycharmProjects\FundooNotes\venv\lib\site-packages\rest_framework\serializers.py", line 472, in to_internal_value
    for field in fields:
  File "C:\Users\TARUNVYDA\PycharmProjects\FundooNotes\venv\lib\site-packages\rest_framework\serializers.py", line 355, in _writable_fields
    for field in self.fields.values():
  File "C:\Users\TARUNVYDA\PycharmProjects\FundooNotes\venv\lib\site-packages\django\utils\functional.py", line 48, in __get__
    res = instance.__dict__[self.name] = self.func(instance)
  File "C:\Users\TARUNVYDA\PycharmProjects\FundooNotes\venv\lib\site-packages\rest_framework\serializers.py", line 349, in fields
    for key, value in self.get_fields().items():
  File "C:\Users\TARUNVYDA\PycharmProjects\FundooNotes\venv\lib\site-packages\rest_framework\serializers.py", line 1029, in get_fields
    field_names = self.get_field_names(declared_fields, info)
  File "C:\Users\TARUNVYDA\PycharmProjects\FundooNotes\venv\lib\site-packages\rest_framework\serializers.py", line 1130, in get_field_names
    serializer_class=self.__class__.__name__
AssertionError: The field 'token' was declared on serializer LoginSerializer, but has not been included in the 'fields' option.
2020-12-24 15:53:01,145:DEBUG:{'email': 'viratkohli123@gmail.com'}
2020-12-24 15:53:04,616:DEBUG:Using selector: SelectSelector
2020-12-24 15:53:44,908:DEBUG:Using selector: SelectSelector
2020-12-24 15:53:53,946:DEBUG:Using selector: SelectSelector
2020-12-24 15:55:41,836:DEBUG:Using selector: SelectSelector
2020-12-24 15:55:50,096:DEBUG:{'email': 'viratkohli123@gmail.com', 'user_name': 'viratkohli'}
2020-12-24 15:55:53,743:DEBUG:Using selector: SelectSelector
2020-12-24 15:59:16,516:DEBUG:{'email': 'viratkohli123@gmail.com', 'user_name': 'viratkohli'}
2020-12-24 15:59:30,312:INFO:C:\Users\TARUNVYDA\CloneProjects\FundooNotes\fundoo\fundooapp\views.py changed, reloading.
2020-12-24 15:59:30,328:DEBUG:Using selector: SelectSelector
2020-12-24 15:59:35,112:DEBUG:{'email': 'viratkohli123@gmail.com', 'user_name': 'viratkohli'}eyJ0eXAiOiJKV1QiLCJhbGciOiJIUzI1NiJ9.eyJpZCI6MX0.-xXA0iKB4mVNvWLYFtt2xNiYkFpObF54J9lj2RwduAI
2020-12-24 15:59:52,615:INFO:C:\Users\TARUNVYDA\CloneProjects\FundooNotes\fundoo\fundooapp\views.py changed, reloading.
2020-12-24 15:59:52,615:DEBUG:Using selector: SelectSelector
2020-12-24 16:00:41,466:INFO:C:\Users\TARUNVYDA\CloneProjects\FundooNotes\fundoo\fundooapp\views.py changed, reloading.
2020-12-24 16:00:41,466:DEBUG:Using selector: SelectSelector
2020-12-24 16:00:46,505:DEBUG:{'email': 'viratkohli123@gmail.com', 'user_name': 'viratkohli'}
2020-12-24 16:00:46,593:ERROR:Internal Server Error: /login/
Traceback (most recent call last):
  File "C:\Users\TARUNVYDA\PycharmProjects\FundooNotes\venv\lib\site-packages\django\core\handlers\exception.py", line 47, in inner
    response = get_response(request)
  File "C:\Users\TARUNVYDA\PycharmProjects\FundooNotes\venv\lib\site-packages\django\core\handlers\base.py", line 179, in _get_response
    response = wrapped_callback(request, *callback_args, **callback_kwargs)
  File "C:\Users\TARUNVYDA\PycharmProjects\FundooNotes\venv\lib\site-packages\django\views\decorators\csrf.py", line 54, in wrapped_view
    return view_func(*args, **kwargs)
  File "C:\Users\TARUNVYDA\PycharmProjects\FundooNotes\venv\lib\site-packages\django\views\generic\base.py", line 70, in view
    return self.dispatch(request, *args, **kwargs)
  File "C:\Users\TARUNVYDA\PycharmProjects\FundooNotes\venv\lib\site-packages\rest_framework\views.py", line 509, in dispatch
    response = self.handle_exception(exc)
  File "C:\Users\TARUNVYDA\PycharmProjects\FundooNotes\venv\lib\site-packages\rest_framework\views.py", line 469, in handle_exception
    self.raise_uncaught_exception(exc)
  File "C:\Users\TARUNVYDA\PycharmProjects\FundooNotes\venv\lib\site-packages\rest_framework\views.py", line 480, in raise_uncaught_exception
    raise exc
  File "C:\Users\TARUNVYDA\PycharmProjects\FundooNotes\venv\lib\site-packages\rest_framework\views.py", line 506, in dispatch
    response = handler(request, *args, **kwargs)
  File "C:\Users\TARUNVYDA\CloneProjects\FundooNotes\fundoo\fundooapp\views.py", line 41, in post
    return Response(serializer.data, token, status=status.HTTP_200_OK)
TypeError: __init__() got multiple values for argument 'status'
2020-12-24 16:00:48,967:DEBUG:{'email': 'viratkohli123@gmail.com', 'user_name': 'viratkohli'}
2020-12-24 16:00:49,040:ERROR:Internal Server Error: /login/
Traceback (most recent call last):
  File "C:\Users\TARUNVYDA\PycharmProjects\FundooNotes\venv\lib\site-packages\django\core\handlers\exception.py", line 47, in inner
    response = get_response(request)
  File "C:\Users\TARUNVYDA\PycharmProjects\FundooNotes\venv\lib\site-packages\django\core\handlers\base.py", line 179, in _get_response
    response = wrapped_callback(request, *callback_args, **callback_kwargs)
  File "C:\Users\TARUNVYDA\PycharmProjects\FundooNotes\venv\lib\site-packages\django\views\decorators\csrf.py", line 54, in wrapped_view
    return view_func(*args, **kwargs)
  File "C:\Users\TARUNVYDA\PycharmProjects\FundooNotes\venv\lib\site-packages\django\views\generic\base.py", line 70, in view
    return self.dispatch(request, *args, **kwargs)
  File "C:\Users\TARUNVYDA\PycharmProjects\FundooNotes\venv\lib\site-packages\rest_framework\views.py", line 509, in dispatch
    response = self.handle_exception(exc)
  File "C:\Users\TARUNVYDA\PycharmProjects\FundooNotes\venv\lib\site-packages\rest_framework\views.py", line 469, in handle_exception
    self.raise_uncaught_exception(exc)
  File "C:\Users\TARUNVYDA\PycharmProjects\FundooNotes\venv\lib\site-packages\rest_framework\views.py", line 480, in raise_uncaught_exception
    raise exc
  File "C:\Users\TARUNVYDA\PycharmProjects\FundooNotes\venv\lib\site-packages\rest_framework\views.py", line 506, in dispatch
    response = handler(request, *args, **kwargs)
  File "C:\Users\TARUNVYDA\CloneProjects\FundooNotes\fundoo\fundooapp\views.py", line 41, in post
    return Response(serializer.data, token, status=status.HTTP_200_OK)
TypeError: __init__() got multiple values for argument 'status'
2020-12-24 16:01:22,838:DEBUG:Using selector: SelectSelector
2020-12-24 16:02:20,458:DEBUG:{'data': {'email': 'viratkohli123@gmail.com', 'user_name': 'viratkohli'}, 'token': 'eyJ0eXAiOiJKV1QiLCJhbGciOiJIUzI1NiJ9.eyJpZCI6MX0.-xXA0iKB4mVNvWLYFtt2xNiYkFpObF54J9lj2RwduAI'}
2020-12-24 16:03:04,243:DEBUG:Using selector: SelectSelector
2020-12-24 16:04:51,349:DEBUG:{'email': 'viratkohli123@gmail.com', 'token': 'eyJ0eXAiOiJKV1QiLCJhbGciOiJIUzI1NiJ9.eyJpZCI6MX0.-xXA0iKB4mVNvWLYFtt2xNiYkFpObF54J9lj2RwduAI'}
2020-12-24 16:07:22,792:DEBUG:Using selector: SelectSelector
2020-12-24 16:11:34,363:ERROR:Internal Server Error: /note/2
Traceback (most recent call last):
  File "C:\Users\TARUNVYDA\PycharmProjects\FundooNotes\venv\lib\site-packages\django\core\handlers\exception.py", line 47, in inner
    response = get_response(request)
  File "C:\Users\TARUNVYDA\PycharmProjects\FundooNotes\venv\lib\site-packages\django\core\handlers\base.py", line 179, in _get_response
    response = wrapped_callback(request, *callback_args, **callback_kwargs)
  File "C:\Users\TARUNVYDA\PycharmProjects\FundooNotes\venv\lib\site-packages\django\views\decorators\csrf.py", line 54, in wrapped_view
    return view_func(*args, **kwargs)
  File "C:\Users\TARUNVYDA\PycharmProjects\FundooNotes\venv\lib\site-packages\django\views\generic\base.py", line 70, in view
    return self.dispatch(request, *args, **kwargs)
  File "C:\Users\TARUNVYDA\PycharmProjects\FundooNotes\venv\lib\site-packages\django\utils\decorators.py", line 43, in _wrapper
    return bound_method(*args, **kwargs)
  File "C:\Users\TARUNVYDA\CloneProjects\FundooNotes\fundoo\fundooapp\decorator.py", line 13, in wrapper
    id = decoded_token['id']
KeyError: 'id'
2020-12-24 16:11:37,100:ERROR:Internal Server Error: /note/2
Traceback (most recent call last):
  File "C:\Users\TARUNVYDA\PycharmProjects\FundooNotes\venv\lib\site-packages\django\core\handlers\exception.py", line 47, in inner
    response = get_response(request)
  File "C:\Users\TARUNVYDA\PycharmProjects\FundooNotes\venv\lib\site-packages\django\core\handlers\base.py", line 179, in _get_response
    response = wrapped_callback(request, *callback_args, **callback_kwargs)
  File "C:\Users\TARUNVYDA\PycharmProjects\FundooNotes\venv\lib\site-packages\django\views\decorators\csrf.py", line 54, in wrapped_view
    return view_func(*args, **kwargs)
  File "C:\Users\TARUNVYDA\PycharmProjects\FundooNotes\venv\lib\site-packages\django\views\generic\base.py", line 70, in view
    return self.dispatch(request, *args, **kwargs)
  File "C:\Users\TARUNVYDA\PycharmProjects\FundooNotes\venv\lib\site-packages\django\utils\decorators.py", line 43, in _wrapper
    return bound_method(*args, **kwargs)
  File "C:\Users\TARUNVYDA\CloneProjects\FundooNotes\fundoo\fundooapp\decorator.py", line 13, in wrapper
    id = decoded_token['id']
KeyError: 'id'
2020-12-24 16:11:55,809:INFO:C:\Users\TARUNVYDA\CloneProjects\FundooNotes\fundoo\fundooapp\decorator.py changed, reloading.
2020-12-24 16:11:55,809:DEBUG:Using selector: SelectSelector
2020-12-24 16:12:00,467:ERROR:Internal Server Error: /note/2
Traceback (most recent call last):
  File "C:\Users\TARUNVYDA\PycharmProjects\FundooNotes\venv\lib\site-packages\django\core\handlers\exception.py", line 47, in inner
    response = get_response(request)
  File "C:\Users\TARUNVYDA\PycharmProjects\FundooNotes\venv\lib\site-packages\django\core\handlers\base.py", line 179, in _get_response
    response = wrapped_callback(request, *callback_args, **callback_kwargs)
  File "C:\Users\TARUNVYDA\PycharmProjects\FundooNotes\venv\lib\site-packages\django\views\decorators\csrf.py", line 54, in wrapped_view
    return view_func(*args, **kwargs)
  File "C:\Users\TARUNVYDA\PycharmProjects\FundooNotes\venv\lib\site-packages\django\views\generic\base.py", line 70, in view
    return self.dispatch(request, *args, **kwargs)
  File "C:\Users\TARUNVYDA\PycharmProjects\FundooNotes\venv\lib\site-packages\django\utils\decorators.py", line 43, in _wrapper
    return bound_method(*args, **kwargs)
  File "C:\Users\TARUNVYDA\CloneProjects\FundooNotes\fundoo\fundooapp\decorator.py", line 13, in wrapper
    id = decoded_token['token']
KeyError: 'token'
2020-12-24 16:12:27,098:INFO:C:\Users\TARUNVYDA\CloneProjects\FundooNotes\fundoo\fundooapp\decorator.py changed, reloading.
2020-12-24 16:12:27,098:DEBUG:Using selector: SelectSelector
2020-12-24 16:12:31,636:DEBUG:{'status': True, 'message': {'id': 2, 'title': 'my testing note', 'description': 'this is my second note', 'created_time': '2020-12-21T14:22:19.826517Z', 'updated_time': '2020-12-21T14:22:19.826517Z', 'is_archived': False, 'is_deleted': False, 'color': '#00F0FF', 'image': None, 'trash': False, 'is_pinned': False, 'user': 3, 'label': [1], 'collaborate': [1]}}
2020-12-24 16:13:08,866:DEBUG:Using selector: SelectSelector
2020-12-24 21:06:42,464:DEBUG:{'email': 'viratkohli123@gmail.com', 'token': 'eyJ0eXAiOiJKV1QiLCJhbGciOiJIUzI1NiJ9.eyJpZCI6MX0.-xXA0iKB4mVNvWLYFtt2xNiYkFpObF54J9lj2RwduAI'}
2020-12-24 21:07:11,806:ERROR:Internal Server Error: /note/2
Traceback (most recent call last):
  File "C:\Users\TARUNVYDA\PycharmProjects\FundooNotes\venv\lib\site-packages\django\core\handlers\exception.py", line 47, in inner
    response = get_response(request)
  File "C:\Users\TARUNVYDA\PycharmProjects\FundooNotes\venv\lib\site-packages\django\core\handlers\base.py", line 179, in _get_response
    response = wrapped_callback(request, *callback_args, **callback_kwargs)
  File "C:\Users\TARUNVYDA\PycharmProjects\FundooNotes\venv\lib\site-packages\django\views\decorators\csrf.py", line 54, in wrapped_view
    return view_func(*args, **kwargs)
  File "C:\Users\TARUNVYDA\PycharmProjects\FundooNotes\venv\lib\site-packages\django\views\generic\base.py", line 70, in view
    return self.dispatch(request, *args, **kwargs)
  File "C:\Users\TARUNVYDA\PycharmProjects\FundooNotes\venv\lib\site-packages\django\utils\decorators.py", line 43, in _wrapper
    return bound_method(*args, **kwargs)
  File "C:\Users\TARUNVYDA\CloneProjects\FundooNotes\fundoo\fundooapp\decorator.py", line 13, in wrapper
    email = decoded_token['email']
KeyError: 'email'
2020-12-24 21:07:16,768:ERROR:Internal Server Error: /note/2
Traceback (most recent call last):
  File "C:\Users\TARUNVYDA\PycharmProjects\FundooNotes\venv\lib\site-packages\django\core\handlers\exception.py", line 47, in inner
    response = get_response(request)
  File "C:\Users\TARUNVYDA\PycharmProjects\FundooNotes\venv\lib\site-packages\django\core\handlers\base.py", line 179, in _get_response
    response = wrapped_callback(request, *callback_args, **callback_kwargs)
  File "C:\Users\TARUNVYDA\PycharmProjects\FundooNotes\venv\lib\site-packages\django\views\decorators\csrf.py", line 54, in wrapped_view
    return view_func(*args, **kwargs)
  File "C:\Users\TARUNVYDA\PycharmProjects\FundooNotes\venv\lib\site-packages\django\views\generic\base.py", line 70, in view
    return self.dispatch(request, *args, **kwargs)
  File "C:\Users\TARUNVYDA\PycharmProjects\FundooNotes\venv\lib\site-packages\django\utils\decorators.py", line 43, in _wrapper
    return bound_method(*args, **kwargs)
  File "C:\Users\TARUNVYDA\CloneProjects\FundooNotes\fundoo\fundooapp\decorator.py", line 13, in wrapper
    email = decoded_token['email']
KeyError: 'email'
2020-12-24 21:07:53,258:INFO:C:\Users\TARUNVYDA\CloneProjects\FundooNotes\fundoo\fundooapp\decorator.py changed, reloading.
2020-12-24 21:07:53,259:DEBUG:Using selector: SelectSelector
2020-12-24 21:08:01,360:ERROR:Internal Server Error: /note/2
Traceback (most recent call last):
  File "C:\Users\TARUNVYDA\PycharmProjects\FundooNotes\venv\lib\site-packages\django\core\handlers\exception.py", line 47, in inner
    response = get_response(request)
  File "C:\Users\TARUNVYDA\PycharmProjects\FundooNotes\venv\lib\site-packages\django\core\handlers\base.py", line 179, in _get_response
    response = wrapped_callback(request, *callback_args, **callback_kwargs)
  File "C:\Users\TARUNVYDA\PycharmProjects\FundooNotes\venv\lib\site-packages\django\views\decorators\csrf.py", line 54, in wrapped_view
    return view_func(*args, **kwargs)
  File "C:\Users\TARUNVYDA\PycharmProjects\FundooNotes\venv\lib\site-packages\django\views\generic\base.py", line 70, in view
    return self.dispatch(request, *args, **kwargs)
  File "C:\Users\TARUNVYDA\PycharmProjects\FundooNotes\venv\lib\site-packages\django\utils\decorators.py", line 43, in _wrapper
    return bound_method(*args, **kwargs)
  File "C:\Users\TARUNVYDA\CloneProjects\FundooNotes\fundoo\fundooapp\decorator.py", line 13, in wrapper
    email = decoded_token['token']
KeyError: 'token'
2020-12-24 21:08:12,398:INFO:C:\Users\TARUNVYDA\CloneProjects\FundooNotes\fundoo\fundooapp\decorator.py changed, reloading.
2020-12-24 21:08:12,399:DEBUG:Using selector: SelectSelector
2020-12-24 21:08:47,676:INFO:C:\Users\TARUNVYDA\CloneProjects\FundooNotes\fundoo\fundooapp\views.py changed, reloading.
2020-12-24 21:08:47,678:DEBUG:Using selector: SelectSelector
2020-12-24 21:08:53,293:ERROR:Internal Server Error: /note/2
Traceback (most recent call last):
  File "C:\Users\TARUNVYDA\PycharmProjects\FundooNotes\venv\lib\site-packages\django\core\handlers\exception.py", line 47, in inner
    response = get_response(request)
  File "C:\Users\TARUNVYDA\PycharmProjects\FundooNotes\venv\lib\site-packages\django\core\handlers\base.py", line 179, in _get_response
    response = wrapped_callback(request, *callback_args, **callback_kwargs)
  File "C:\Users\TARUNVYDA\PycharmProjects\FundooNotes\venv\lib\site-packages\django\views\decorators\csrf.py", line 54, in wrapped_view
    return view_func(*args, **kwargs)
  File "C:\Users\TARUNVYDA\PycharmProjects\FundooNotes\venv\lib\site-packages\django\views\generic\base.py", line 70, in view
    return self.dispatch(request, *args, **kwargs)
  File "C:\Users\TARUNVYDA\PycharmProjects\FundooNotes\venv\lib\site-packages\django\utils\decorators.py", line 43, in _wrapper
    return bound_method(*args, **kwargs)
  File "C:\Users\TARUNVYDA\CloneProjects\FundooNotes\fundoo\fundooapp\decorator.py", line 13, in wrapper
    email = decoded_token['email']
KeyError: 'email'
2020-12-24 21:08:55,631:ERROR:Internal Server Error: /note/2
Traceback (most recent call last):
  File "C:\Users\TARUNVYDA\PycharmProjects\FundooNotes\venv\lib\site-packages\django\core\handlers\exception.py", line 47, in inner
    response = get_response(request)
  File "C:\Users\TARUNVYDA\PycharmProjects\FundooNotes\venv\lib\site-packages\django\core\handlers\base.py", line 179, in _get_response
    response = wrapped_callback(request, *callback_args, **callback_kwargs)
  File "C:\Users\TARUNVYDA\PycharmProjects\FundooNotes\venv\lib\site-packages\django\views\decorators\csrf.py", line 54, in wrapped_view
    return view_func(*args, **kwargs)
  File "C:\Users\TARUNVYDA\PycharmProjects\FundooNotes\venv\lib\site-packages\django\views\generic\base.py", line 70, in view
    return self.dispatch(request, *args, **kwargs)
  File "C:\Users\TARUNVYDA\PycharmProjects\FundooNotes\venv\lib\site-packages\django\utils\decorators.py", line 43, in _wrapper
    return bound_method(*args, **kwargs)
  File "C:\Users\TARUNVYDA\CloneProjects\FundooNotes\fundoo\fundooapp\decorator.py", line 13, in wrapper
    email = decoded_token['email']
KeyError: 'email'
2020-12-24 21:09:06,132:INFO:C:\Users\TARUNVYDA\CloneProjects\FundooNotes\fundoo\fundooapp\views.py changed, reloading.
2020-12-24 21:09:06,134:DEBUG:Using selector: SelectSelector
2020-12-24 21:09:23,470:INFO:C:\Users\TARUNVYDA\CloneProjects\FundooNotes\fundoo\fundooapp\views.py changed, reloading.
2020-12-24 21:09:23,607:DEBUG:Using selector: SelectSelector
2020-12-24 21:09:32,762:DEBUG:{'email': 'viratkohli123@gmail.com', 'token': 'eyJ0eXAiOiJKV1QiLCJhbGciOiJIUzI1NiJ9.eyJpZCI6MX0.-xXA0iKB4mVNvWLYFtt2xNiYkFpObF54J9lj2RwduAI'}
2020-12-24 21:09:37,770:DEBUG:{'email': 'viratkohli123@gmail.com', 'token': 'eyJ0eXAiOiJKV1QiLCJhbGciOiJIUzI1NiJ9.eyJpZCI6MX0.-xXA0iKB4mVNvWLYFtt2xNiYkFpObF54J9lj2RwduAI'}
2020-12-24 21:09:50,064:ERROR:Internal Server Error: /note/2
Traceback (most recent call last):
  File "C:\Users\TARUNVYDA\PycharmProjects\FundooNotes\venv\lib\site-packages\django\core\handlers\exception.py", line 47, in inner
    response = get_response(request)
  File "C:\Users\TARUNVYDA\PycharmProjects\FundooNotes\venv\lib\site-packages\django\core\handlers\base.py", line 179, in _get_response
    response = wrapped_callback(request, *callback_args, **callback_kwargs)
  File "C:\Users\TARUNVYDA\PycharmProjects\FundooNotes\venv\lib\site-packages\django\views\decorators\csrf.py", line 54, in wrapped_view
    return view_func(*args, **kwargs)
  File "C:\Users\TARUNVYDA\PycharmProjects\FundooNotes\venv\lib\site-packages\django\views\generic\base.py", line 70, in view
    return self.dispatch(request, *args, **kwargs)
  File "C:\Users\TARUNVYDA\PycharmProjects\FundooNotes\venv\lib\site-packages\django\utils\decorators.py", line 43, in _wrapper
    return bound_method(*args, **kwargs)
  File "C:\Users\TARUNVYDA\CloneProjects\FundooNotes\fundoo\fundooapp\decorator.py", line 13, in wrapper
    email = decoded_token['email']
KeyError: 'email'
2020-12-24 21:10:31,227:DEBUG:Using selector: SelectSelector
2020-12-24 21:11:21,114:ERROR:Internal Server Error: /note/2
Traceback (most recent call last):
  File "C:\Users\TARUNVYDA\PycharmProjects\FundooNotes\venv\lib\site-packages\django\core\handlers\exception.py", line 47, in inner
    response = get_response(request)
  File "C:\Users\TARUNVYDA\PycharmProjects\FundooNotes\venv\lib\site-packages\django\core\handlers\base.py", line 179, in _get_response
    response = wrapped_callback(request, *callback_args, **callback_kwargs)
  File "C:\Users\TARUNVYDA\PycharmProjects\FundooNotes\venv\lib\site-packages\django\views\decorators\csrf.py", line 54, in wrapped_view
    return view_func(*args, **kwargs)
  File "C:\Users\TARUNVYDA\PycharmProjects\FundooNotes\venv\lib\site-packages\django\views\generic\base.py", line 70, in view
    return self.dispatch(request, *args, **kwargs)
  File "C:\Users\TARUNVYDA\PycharmProjects\FundooNotes\venv\lib\site-packages\django\utils\decorators.py", line 43, in _wrapper
    return bound_method(*args, **kwargs)
  File "C:\Users\TARUNVYDA\CloneProjects\FundooNotes\fundoo\fundooapp\decorator.py", line 14, in wrapper
    user = Account.objects.get(email=email)
  File "C:\Users\TARUNVYDA\PycharmProjects\FundooNotes\venv\lib\site-packages\django\db\models\manager.py", line 85, in manager_method
    return getattr(self.get_queryset(), name)(*args, **kwargs)
  File "C:\Users\TARUNVYDA\PycharmProjects\FundooNotes\venv\lib\site-packages\django\db\models\query.py", line 431, in get
    self.model._meta.object_name
fundooapp.models.Account.DoesNotExist: Account matching query does not exist.
2020-12-24 21:11:25,665:ERROR:Internal Server Error: /note/2
Traceback (most recent call last):
  File "C:\Users\TARUNVYDA\PycharmProjects\FundooNotes\venv\lib\site-packages\django\core\handlers\exception.py", line 47, in inner
    response = get_response(request)
  File "C:\Users\TARUNVYDA\PycharmProjects\FundooNotes\venv\lib\site-packages\django\core\handlers\base.py", line 179, in _get_response
    response = wrapped_callback(request, *callback_args, **callback_kwargs)
  File "C:\Users\TARUNVYDA\PycharmProjects\FundooNotes\venv\lib\site-packages\django\views\decorators\csrf.py", line 54, in wrapped_view
    return view_func(*args, **kwargs)
  File "C:\Users\TARUNVYDA\PycharmProjects\FundooNotes\venv\lib\site-packages\django\views\generic\base.py", line 70, in view
    return self.dispatch(request, *args, **kwargs)
  File "C:\Users\TARUNVYDA\PycharmProjects\FundooNotes\venv\lib\site-packages\django\utils\decorators.py", line 43, in _wrapper
    return bound_method(*args, **kwargs)
  File "C:\Users\TARUNVYDA\CloneProjects\FundooNotes\fundoo\fundooapp\decorator.py", line 14, in wrapper
    user = Account.objects.get(email=email)
  File "C:\Users\TARUNVYDA\PycharmProjects\FundooNotes\venv\lib\site-packages\django\db\models\manager.py", line 85, in manager_method
    return getattr(self.get_queryset(), name)(*args, **kwargs)
  File "C:\Users\TARUNVYDA\PycharmProjects\FundooNotes\venv\lib\site-packages\django\db\models\query.py", line 431, in get
    self.model._meta.object_name
fundooapp.models.Account.DoesNotExist: Account matching query does not exist.
2020-12-24 21:11:31,400:DEBUG:{'email': 'viratkohli123@gmail.com', 'token': 'eyJ0eXAiOiJKV1QiLCJhbGciOiJIUzI1NiJ9.eyJpZCI6MX0.-xXA0iKB4mVNvWLYFtt2xNiYkFpObF54J9lj2RwduAI'}
2020-12-24 21:11:42,950:ERROR:Internal Server Error: /note/2
Traceback (most recent call last):
  File "C:\Users\TARUNVYDA\PycharmProjects\FundooNotes\venv\lib\site-packages\django\core\handlers\exception.py", line 47, in inner
    response = get_response(request)
  File "C:\Users\TARUNVYDA\PycharmProjects\FundooNotes\venv\lib\site-packages\django\core\handlers\base.py", line 179, in _get_response
    response = wrapped_callback(request, *callback_args, **callback_kwargs)
  File "C:\Users\TARUNVYDA\PycharmProjects\FundooNotes\venv\lib\site-packages\django\views\decorators\csrf.py", line 54, in wrapped_view
    return view_func(*args, **kwargs)
  File "C:\Users\TARUNVYDA\PycharmProjects\FundooNotes\venv\lib\site-packages\django\views\generic\base.py", line 70, in view
    return self.dispatch(request, *args, **kwargs)
  File "C:\Users\TARUNVYDA\PycharmProjects\FundooNotes\venv\lib\site-packages\django\utils\decorators.py", line 43, in _wrapper
    return bound_method(*args, **kwargs)
  File "C:\Users\TARUNVYDA\CloneProjects\FundooNotes\fundoo\fundooapp\decorator.py", line 14, in wrapper
    user = Account.objects.get(email=email)
  File "C:\Users\TARUNVYDA\PycharmProjects\FundooNotes\venv\lib\site-packages\django\db\models\manager.py", line 85, in manager_method
    return getattr(self.get_queryset(), name)(*args, **kwargs)
  File "C:\Users\TARUNVYDA\PycharmProjects\FundooNotes\venv\lib\site-packages\django\db\models\query.py", line 431, in get
    self.model._meta.object_name
fundooapp.models.Account.DoesNotExist: Account matching query does not exist.
2020-12-24 21:12:09,721:INFO:C:\Users\TARUNVYDA\CloneProjects\FundooNotes\fundoo\fundooapp\decorator.py changed, reloading.
2020-12-24 21:12:09,722:DEBUG:Using selector: SelectSelector
2020-12-24 21:12:16,846:DEBUG:{'status': True, 'message': {'id': 2, 'title': 'my testing note', 'description': 'this is my second note', 'created_time': '2020-12-21T14:22:19.826517Z', 'updated_time': '2020-12-21T14:22:19.826517Z', 'is_archived': False, 'is_deleted': False, 'color': '#00F0FF', 'image': None, 'trash': False, 'is_pinned': False, 'user': 3, 'label': [1], 'collaborate': [1]}}
2020-12-24 21:12:34,072:DEBUG:Using selector: SelectSelector
2020-12-24 21:13:31,594:DEBUG:{'token': 'eyJ0eXAiOiJKV1QiLCJhbGciOiJIUzI1NiJ9.eyJpZCI6MX0.-xXA0iKB4mVNvWLYFtt2xNiYkFpObF54J9lj2RwduAI'}
2020-12-24 21:13:46,242:DEBUG:{'status': True, 'message': {'id': 2, 'title': 'my testing note', 'description': 'this is my second note', 'created_time': '2020-12-21T14:22:19.826517Z', 'updated_time': '2020-12-21T14:22:19.826517Z', 'is_archived': False, 'is_deleted': False, 'color': '#00F0FF', 'image': None, 'trash': False, 'is_pinned': False, 'user': 3, 'label': [1], 'collaborate': [1]}}
2020-12-24 21:13:58,582:DEBUG:Using selector: SelectSelector
2020-12-24 21:17:06,956:DEBUG:{'status': True, 'message': {'id': 2, 'title': 'my testing note', 'description': 'this is my second note', 'created_time': '2020-12-21T14:22:19.826517Z', 'updated_time': '2020-12-21T14:22:19.826517Z', 'is_archived': False, 'is_deleted': False, 'color': '#00F0FF', 'image': None, 'trash': False, 'is_pinned': False, 'user': 3, 'label': [1], 'collaborate': [1]}}
2020-12-24 21:28:14,480:DEBUG:Using selector: SelectSelector
2020-12-24 21:36:18,114:DEBUG:{'token': 'eyJ0eXAiOiJKV1QiLCJhbGciOiJIUzI1NiJ9.eyJpZCI6MX0.-xXA0iKB4mVNvWLYFtt2xNiYkFpObF54J9lj2RwduAI'}
2020-12-24 21:36:43,652:INFO:C:\Users\TARUNVYDA\CloneProjects\FundooNotes\fundoo\fundooapp\decorator.py changed, reloading.
2020-12-24 21:36:43,654:DEBUG:Using selector: SelectSelector
2020-12-24 21:36:49,827:DEBUG:{'token': 'eyJ0eXAiOiJKV1QiLCJhbGciOiJIUzI1NiJ9.eyJpZCI6MX0.-xXA0iKB4mVNvWLYFtt2xNiYkFpObF54J9lj2RwduAI'}
2020-12-24 21:36:53,057:DEBUG:{'token': 'eyJ0eXAiOiJKV1QiLCJhbGciOiJIUzI1NiJ9.eyJpZCI6MX0.-xXA0iKB4mVNvWLYFtt2xNiYkFpObF54J9lj2RwduAI'}
2020-12-24 21:37:26,480:ERROR:Internal Server Error: /note/2
Traceback (most recent call last):
  File "C:\Users\TARUNVYDA\PycharmProjects\FundooNotes\venv\lib\site-packages\django\core\handlers\exception.py", line 47, in inner
    response = get_response(request)
  File "C:\Users\TARUNVYDA\PycharmProjects\FundooNotes\venv\lib\site-packages\django\core\handlers\base.py", line 179, in _get_response
    response = wrapped_callback(request, *callback_args, **callback_kwargs)
  File "C:\Users\TARUNVYDA\PycharmProjects\FundooNotes\venv\lib\site-packages\django\views\decorators\csrf.py", line 54, in wrapped_view
    return view_func(*args, **kwargs)
  File "C:\Users\TARUNVYDA\PycharmProjects\FundooNotes\venv\lib\site-packages\django\views\generic\base.py", line 70, in view
    return self.dispatch(request, *args, **kwargs)
  File "C:\Users\TARUNVYDA\PycharmProjects\FundooNotes\venv\lib\site-packages\django\utils\decorators.py", line 43, in _wrapper
    return bound_method(*args, **kwargs)
  File "C:\Users\TARUNVYDA\CloneProjects\FundooNotes\fundoo\fundooapp\decorator.py", line 12, in wrapper
    decoded_token = jwt.decode(token, settings.SECRET_KEY)
NameError: name 'settings' is not defined
2020-12-24 21:37:32,108:ERROR:Internal Server Error: /note/2
Traceback (most recent call last):
  File "C:\Users\TARUNVYDA\PycharmProjects\FundooNotes\venv\lib\site-packages\django\core\handlers\exception.py", line 47, in inner
    response = get_response(request)
  File "C:\Users\TARUNVYDA\PycharmProjects\FundooNotes\venv\lib\site-packages\django\core\handlers\base.py", line 179, in _get_response
    response = wrapped_callback(request, *callback_args, **callback_kwargs)
  File "C:\Users\TARUNVYDA\PycharmProjects\FundooNotes\venv\lib\site-packages\django\views\decorators\csrf.py", line 54, in wrapped_view
    return view_func(*args, **kwargs)
  File "C:\Users\TARUNVYDA\PycharmProjects\FundooNotes\venv\lib\site-packages\django\views\generic\base.py", line 70, in view
    return self.dispatch(request, *args, **kwargs)
  File "C:\Users\TARUNVYDA\PycharmProjects\FundooNotes\venv\lib\site-packages\django\utils\decorators.py", line 43, in _wrapper
    return bound_method(*args, **kwargs)
  File "C:\Users\TARUNVYDA\CloneProjects\FundooNotes\fundoo\fundooapp\decorator.py", line 12, in wrapper
    decoded_token = jwt.decode(token, settings.SECRET_KEY)
NameError: name 'settings' is not defined
2020-12-24 21:37:46,506:ERROR:Internal Server Error: /note/2
Traceback (most recent call last):
  File "C:\Users\TARUNVYDA\PycharmProjects\FundooNotes\venv\lib\site-packages\django\core\handlers\exception.py", line 47, in inner
    response = get_response(request)
  File "C:\Users\TARUNVYDA\PycharmProjects\FundooNotes\venv\lib\site-packages\django\core\handlers\base.py", line 179, in _get_response
    response = wrapped_callback(request, *callback_args, **callback_kwargs)
  File "C:\Users\TARUNVYDA\PycharmProjects\FundooNotes\venv\lib\site-packages\django\views\decorators\csrf.py", line 54, in wrapped_view
    return view_func(*args, **kwargs)
  File "C:\Users\TARUNVYDA\PycharmProjects\FundooNotes\venv\lib\site-packages\django\views\generic\base.py", line 70, in view
    return self.dispatch(request, *args, **kwargs)
  File "C:\Users\TARUNVYDA\PycharmProjects\FundooNotes\venv\lib\site-packages\django\utils\decorators.py", line 43, in _wrapper
    return bound_method(*args, **kwargs)
  File "C:\Users\TARUNVYDA\CloneProjects\FundooNotes\fundoo\fundooapp\decorator.py", line 12, in wrapper
    decoded_token = jwt.decode(token, settings.SECRET_KEY)
NameError: name 'settings' is not defined
2020-12-24 21:37:56,396:ERROR:Internal Server Error: /note/2
Traceback (most recent call last):
  File "C:\Users\TARUNVYDA\PycharmProjects\FundooNotes\venv\lib\site-packages\django\core\handlers\exception.py", line 47, in inner
    response = get_response(request)
  File "C:\Users\TARUNVYDA\PycharmProjects\FundooNotes\venv\lib\site-packages\django\core\handlers\base.py", line 179, in _get_response
    response = wrapped_callback(request, *callback_args, **callback_kwargs)
  File "C:\Users\TARUNVYDA\PycharmProjects\FundooNotes\venv\lib\site-packages\django\views\decorators\csrf.py", line 54, in wrapped_view
    return view_func(*args, **kwargs)
  File "C:\Users\TARUNVYDA\PycharmProjects\FundooNotes\venv\lib\site-packages\django\views\generic\base.py", line 70, in view
    return self.dispatch(request, *args, **kwargs)
  File "C:\Users\TARUNVYDA\PycharmProjects\FundooNotes\venv\lib\site-packages\django\utils\decorators.py", line 43, in _wrapper
    return bound_method(*args, **kwargs)
  File "C:\Users\TARUNVYDA\CloneProjects\FundooNotes\fundoo\fundooapp\decorator.py", line 12, in wrapper
    decoded_token = jwt.decode(token, settings.SECRET_KEY)
NameError: name 'settings' is not defined
2020-12-24 21:37:59,436:ERROR:Internal Server Error: /note/2
Traceback (most recent call last):
  File "C:\Users\TARUNVYDA\PycharmProjects\FundooNotes\venv\lib\site-packages\django\core\handlers\exception.py", line 47, in inner
    response = get_response(request)
  File "C:\Users\TARUNVYDA\PycharmProjects\FundooNotes\venv\lib\site-packages\django\core\handlers\base.py", line 179, in _get_response
    response = wrapped_callback(request, *callback_args, **callback_kwargs)
  File "C:\Users\TARUNVYDA\PycharmProjects\FundooNotes\venv\lib\site-packages\django\views\decorators\csrf.py", line 54, in wrapped_view
    return view_func(*args, **kwargs)
  File "C:\Users\TARUNVYDA\PycharmProjects\FundooNotes\venv\lib\site-packages\django\views\generic\base.py", line 70, in view
    return self.dispatch(request, *args, **kwargs)
  File "C:\Users\TARUNVYDA\PycharmProjects\FundooNotes\venv\lib\site-packages\django\utils\decorators.py", line 43, in _wrapper
    return bound_method(*args, **kwargs)
  File "C:\Users\TARUNVYDA\CloneProjects\FundooNotes\fundoo\fundooapp\decorator.py", line 12, in wrapper
    decoded_token = jwt.decode(token, settings.SECRET_KEY)
NameError: name 'settings' is not defined
2020-12-24 21:38:00,917:ERROR:Internal Server Error: /note/2
Traceback (most recent call last):
  File "C:\Users\TARUNVYDA\PycharmProjects\FundooNotes\venv\lib\site-packages\django\core\handlers\exception.py", line 47, in inner
    response = get_response(request)
  File "C:\Users\TARUNVYDA\PycharmProjects\FundooNotes\venv\lib\site-packages\django\core\handlers\base.py", line 179, in _get_response
    response = wrapped_callback(request, *callback_args, **callback_kwargs)
  File "C:\Users\TARUNVYDA\PycharmProjects\FundooNotes\venv\lib\site-packages\django\views\decorators\csrf.py", line 54, in wrapped_view
    return view_func(*args, **kwargs)
  File "C:\Users\TARUNVYDA\PycharmProjects\FundooNotes\venv\lib\site-packages\django\views\generic\base.py", line 70, in view
    return self.dispatch(request, *args, **kwargs)
  File "C:\Users\TARUNVYDA\PycharmProjects\FundooNotes\venv\lib\site-packages\django\utils\decorators.py", line 43, in _wrapper
    return bound_method(*args, **kwargs)
  File "C:\Users\TARUNVYDA\CloneProjects\FundooNotes\fundoo\fundooapp\decorator.py", line 12, in wrapper
    decoded_token = jwt.decode(token, settings.SECRET_KEY)
NameError: name 'settings' is not defined
2020-12-24 21:38:02,487:ERROR:Internal Server Error: /note/2
Traceback (most recent call last):
  File "C:\Users\TARUNVYDA\PycharmProjects\FundooNotes\venv\lib\site-packages\django\core\handlers\exception.py", line 47, in inner
    response = get_response(request)
  File "C:\Users\TARUNVYDA\PycharmProjects\FundooNotes\venv\lib\site-packages\django\core\handlers\base.py", line 179, in _get_response
    response = wrapped_callback(request, *callback_args, **callback_kwargs)
  File "C:\Users\TARUNVYDA\PycharmProjects\FundooNotes\venv\lib\site-packages\django\views\decorators\csrf.py", line 54, in wrapped_view
    return view_func(*args, **kwargs)
  File "C:\Users\TARUNVYDA\PycharmProjects\FundooNotes\venv\lib\site-packages\django\views\generic\base.py", line 70, in view
    return self.dispatch(request, *args, **kwargs)
  File "C:\Users\TARUNVYDA\PycharmProjects\FundooNotes\venv\lib\site-packages\django\utils\decorators.py", line 43, in _wrapper
    return bound_method(*args, **kwargs)
  File "C:\Users\TARUNVYDA\CloneProjects\FundooNotes\fundoo\fundooapp\decorator.py", line 12, in wrapper
    decoded_token = jwt.decode(token, settings.SECRET_KEY)
NameError: name 'settings' is not defined
2020-12-24 21:38:04,220:ERROR:Internal Server Error: /note/2
Traceback (most recent call last):
  File "C:\Users\TARUNVYDA\PycharmProjects\FundooNotes\venv\lib\site-packages\django\core\handlers\exception.py", line 47, in inner
    response = get_response(request)
  File "C:\Users\TARUNVYDA\PycharmProjects\FundooNotes\venv\lib\site-packages\django\core\handlers\base.py", line 179, in _get_response
    response = wrapped_callback(request, *callback_args, **callback_kwargs)
  File "C:\Users\TARUNVYDA\PycharmProjects\FundooNotes\venv\lib\site-packages\django\views\decorators\csrf.py", line 54, in wrapped_view
    return view_func(*args, **kwargs)
  File "C:\Users\TARUNVYDA\PycharmProjects\FundooNotes\venv\lib\site-packages\django\views\generic\base.py", line 70, in view
    return self.dispatch(request, *args, **kwargs)
  File "C:\Users\TARUNVYDA\PycharmProjects\FundooNotes\venv\lib\site-packages\django\utils\decorators.py", line 43, in _wrapper
    return bound_method(*args, **kwargs)
  File "C:\Users\TARUNVYDA\CloneProjects\FundooNotes\fundoo\fundooapp\decorator.py", line 12, in wrapper
    decoded_token = jwt.decode(token, settings.SECRET_KEY)
NameError: name 'settings' is not defined
2020-12-24 21:38:23,131:INFO:C:\Users\TARUNVYDA\CloneProjects\FundooNotes\fundoo\fundooapp\decorator.py changed, reloading.
2020-12-24 21:38:23,132:DEBUG:Using selector: SelectSelector
2020-12-24 21:38:29,656:ERROR:Internal Server Error: /note/2
Traceback (most recent call last):
  File "C:\Users\TARUNVYDA\PycharmProjects\FundooNotes\venv\lib\site-packages\django\core\handlers\exception.py", line 47, in inner
    response = get_response(request)
  File "C:\Users\TARUNVYDA\PycharmProjects\FundooNotes\venv\lib\site-packages\django\core\handlers\base.py", line 179, in _get_response
    response = wrapped_callback(request, *callback_args, **callback_kwargs)
  File "C:\Users\TARUNVYDA\PycharmProjects\FundooNotes\venv\lib\site-packages\django\views\decorators\csrf.py", line 54, in wrapped_view
    return view_func(*args, **kwargs)
  File "C:\Users\TARUNVYDA\PycharmProjects\FundooNotes\venv\lib\site-packages\django\views\generic\base.py", line 70, in view
    return self.dispatch(request, *args, **kwargs)
  File "C:\Users\TARUNVYDA\PycharmProjects\FundooNotes\venv\lib\site-packages\django\utils\decorators.py", line 43, in _wrapper
    return bound_method(*args, **kwargs)
  File "C:\Users\TARUNVYDA\CloneProjects\FundooNotes\fundoo\fundooapp\decorator.py", line 12, in wrapper
    decoded_token = jwt.decode(token, settings.SECRET_KEY, algorithms=["HS256"])
NameError: name 'settings' is not defined
2020-12-24 21:38:31,423:ERROR:Internal Server Error: /note/2
Traceback (most recent call last):
  File "C:\Users\TARUNVYDA\PycharmProjects\FundooNotes\venv\lib\site-packages\django\core\handlers\exception.py", line 47, in inner
    response = get_response(request)
  File "C:\Users\TARUNVYDA\PycharmProjects\FundooNotes\venv\lib\site-packages\django\core\handlers\base.py", line 179, in _get_response
    response = wrapped_callback(request, *callback_args, **callback_kwargs)
  File "C:\Users\TARUNVYDA\PycharmProjects\FundooNotes\venv\lib\site-packages\django\views\decorators\csrf.py", line 54, in wrapped_view
    return view_func(*args, **kwargs)
  File "C:\Users\TARUNVYDA\PycharmProjects\FundooNotes\venv\lib\site-packages\django\views\generic\base.py", line 70, in view
    return self.dispatch(request, *args, **kwargs)
  File "C:\Users\TARUNVYDA\PycharmProjects\FundooNotes\venv\lib\site-packages\django\utils\decorators.py", line 43, in _wrapper
    return bound_method(*args, **kwargs)
  File "C:\Users\TARUNVYDA\CloneProjects\FundooNotes\fundoo\fundooapp\decorator.py", line 12, in wrapper
    decoded_token = jwt.decode(token, settings.SECRET_KEY, algorithms=["HS256"])
NameError: name 'settings' is not defined
2020-12-24 21:38:37,310:INFO:C:\Users\TARUNVYDA\CloneProjects\FundooNotes\fundoo\fundooapp\decorator.py changed, reloading.
2020-12-24 21:38:37,311:DEBUG:Using selector: SelectSelector
2020-12-24 21:38:43,177:DEBUG:{'status': True, 'message': {'id': 2, 'title': 'my testing note', 'description': 'this is my second note', 'created_time': '2020-12-21T14:22:19.826517Z', 'updated_time': '2020-12-21T14:22:19.826517Z', 'is_archived': False, 'is_deleted': False, 'color': '#00F0FF', 'image': None, 'trash': False, 'is_pinned': False, 'user': 3, 'label': [1], 'collaborate': [1]}}
2020-12-24 21:38:53,903:DEBUG:Using selector: SelectSelector
2020-12-24 21:39:57,193:ERROR:Internal Server Error: /note/2
Traceback (most recent call last):
  File "C:\Users\TARUNVYDA\PycharmProjects\FundooNotes\venv\lib\site-packages\jwt\api_jws.py", line 180, in _load
    signing_input, crypto_segment = jwt.rsplit(b'.', 1)
ValueError: not enough values to unpack (expected 2, got 1)

During handling of the above exception, another exception occurred:

Traceback (most recent call last):
  File "C:\Users\TARUNVYDA\PycharmProjects\FundooNotes\venv\lib\site-packages\django\core\handlers\exception.py", line 47, in inner
    response = get_response(request)
  File "C:\Users\TARUNVYDA\PycharmProjects\FundooNotes\venv\lib\site-packages\django\core\handlers\base.py", line 179, in _get_response
    response = wrapped_callback(request, *callback_args, **callback_kwargs)
  File "C:\Users\TARUNVYDA\PycharmProjects\FundooNotes\venv\lib\site-packages\django\views\decorators\csrf.py", line 54, in wrapped_view
    return view_func(*args, **kwargs)
  File "C:\Users\TARUNVYDA\PycharmProjects\FundooNotes\venv\lib\site-packages\django\views\generic\base.py", line 70, in view
    return self.dispatch(request, *args, **kwargs)
  File "C:\Users\TARUNVYDA\PycharmProjects\FundooNotes\venv\lib\site-packages\django\utils\decorators.py", line 43, in _wrapper
    return bound_method(*args, **kwargs)
  File "C:\Users\TARUNVYDA\CloneProjects\FundooNotes\fundoo\fundooapp\decorator.py", line 12, in wrapper
    decoded_token = jwt.decode(token, "secret", algorithms=["HS256"])
  File "C:\Users\TARUNVYDA\PycharmProjects\FundooNotes\venv\lib\site-packages\jwt\api_jwt.py", line 84, in decode
    payload, _, _, _ = self._load(jwt)
  File "C:\Users\TARUNVYDA\PycharmProjects\FundooNotes\venv\lib\site-packages\jwt\api_jws.py", line 183, in _load
    raise DecodeError('Not enough segments')
jwt.exceptions.DecodeError: Not enough segments
2020-12-24 21:39:59,582:ERROR:Internal Server Error: /note/2
Traceback (most recent call last):
  File "C:\Users\TARUNVYDA\PycharmProjects\FundooNotes\venv\lib\site-packages\jwt\api_jws.py", line 180, in _load
    signing_input, crypto_segment = jwt.rsplit(b'.', 1)
ValueError: not enough values to unpack (expected 2, got 1)

During handling of the above exception, another exception occurred:

Traceback (most recent call last):
  File "C:\Users\TARUNVYDA\PycharmProjects\FundooNotes\venv\lib\site-packages\django\core\handlers\exception.py", line 47, in inner
    response = get_response(request)
  File "C:\Users\TARUNVYDA\PycharmProjects\FundooNotes\venv\lib\site-packages\django\core\handlers\base.py", line 179, in _get_response
    response = wrapped_callback(request, *callback_args, **callback_kwargs)
  File "C:\Users\TARUNVYDA\PycharmProjects\FundooNotes\venv\lib\site-packages\django\views\decorators\csrf.py", line 54, in wrapped_view
    return view_func(*args, **kwargs)
  File "C:\Users\TARUNVYDA\PycharmProjects\FundooNotes\venv\lib\site-packages\django\views\generic\base.py", line 70, in view
    return self.dispatch(request, *args, **kwargs)
  File "C:\Users\TARUNVYDA\PycharmProjects\FundooNotes\venv\lib\site-packages\django\utils\decorators.py", line 43, in _wrapper
    return bound_method(*args, **kwargs)
  File "C:\Users\TARUNVYDA\CloneProjects\FundooNotes\fundoo\fundooapp\decorator.py", line 12, in wrapper
    decoded_token = jwt.decode(token, "secret", algorithms=["HS256"])
  File "C:\Users\TARUNVYDA\PycharmProjects\FundooNotes\venv\lib\site-packages\jwt\api_jwt.py", line 84, in decode
    payload, _, _, _ = self._load(jwt)
  File "C:\Users\TARUNVYDA\PycharmProjects\FundooNotes\venv\lib\site-packages\jwt\api_jws.py", line 183, in _load
    raise DecodeError('Not enough segments')
jwt.exceptions.DecodeError: Not enough segments
2020-12-24 21:40:47,374:INFO:C:\Users\TARUNVYDA\CloneProjects\FundooNotes\fundoo\fundooapp\decorator.py changed, reloading.
2020-12-24 21:40:47,375:DEBUG:Using selector: SelectSelector
2020-12-24 21:41:35,239:INFO:C:\Users\TARUNVYDA\CloneProjects\FundooNotes\fundoo\fundooapp\decorator.py changed, reloading.
2020-12-24 21:41:35,241:DEBUG:Using selector: SelectSelector
2020-12-24 21:41:50,273:INFO:C:\Users\TARUNVYDA\CloneProjects\FundooNotes\fundoo\fundooapp\decorator.py changed, reloading.
2020-12-24 21:41:50,274:DEBUG:Using selector: SelectSelector
2020-12-24 21:42:15,335:INFO:C:\Users\TARUNVYDA\CloneProjects\FundooNotes\fundoo\fundooapp\decorator.py changed, reloading.
2020-12-24 21:42:15,337:DEBUG:Using selector: SelectSelector
2020-12-24 21:44:25,475:INFO:C:\Users\TARUNVYDA\CloneProjects\FundooNotes\fundoo\fundooapp\decorator.py changed, reloading.
2020-12-24 21:44:25,476:DEBUG:Using selector: SelectSelector
2020-12-24 21:44:56,507:WARNING:Unauthorized: /login/
2020-12-24 21:45:02,066:WARNING:Unauthorized: /login/
2020-12-24 21:45:24,083:DEBUG:{'token': 'eyJ0eXAiOiJKV1QiLCJhbGciOiJIUzI1NiJ9.eyJpZCI6MX0.-xXA0iKB4mVNvWLYFtt2xNiYkFpObF54J9lj2RwduAI'}
2020-12-24 21:46:14,101:INFO:C:\Users\TARUNVYDA\CloneProjects\FundooNotes\fundoo\fundooapp\decorator.py changed, reloading.
2020-12-24 21:46:14,101:DEBUG:Using selector: SelectSelector
2020-12-24 21:46:18,307:DEBUG:Using selector: SelectSelector
